Workbook
Name abortion: 'Données pop de l''année de ref'!$C$38
Name abortion: 'Données pop de l''année de ref'!$C$41
Name comm_deliv: 'Traitement de la MAS'!$D$3
Name diarrhoea_1_5mo: 'Données pop de l''année de ref'!$C$52
Name diarrhoea_12_23mo: 'Données pop de l''année de ref'!$C$54
Name diarrhoea_1mo: 'Données pop de l''année de ref'!$C$51
Name diarrhoea_24_59mo: 'Données pop de l''année de ref'!$C$55
Name diarrhoea_6_11mo: 'Données pop de l''année de ref'!$C$53
Name end_year: 'Données pop de l''année de ref'!$C$4
Name famplan_unmet_need: 'Données pop de l''année de ref'!$C$13
Name food_insecure: 'Données pop de l''année de ref'!$C$8
Name frac_children_health_facility: 'Données pop de l''année de ref'!$C$12
Name frac_diarrhea_severe: 'Données pop de l''année de ref'!$C$58
Name frac_maize: 'Données pop de l''année de ref'!$C$19
Name frac_malaria_risk: 'Données pop de l''année de ref'!$C$9
Name frac_mam_1_5months: 'Dist. de l''état nutritionnel'!$D$10
Name frac_mam_12_23months: 'Dist. de l''état nutritionnel'!$F$10
Name frac_mam_1month: 'Dist. de l''état nutritionnel'!$C$10
Name frac_mam_24_59months: 'Dist. de l''état nutritionnel'!$G$10
Name frac_mam_6_11months: 'Dist. de l''état nutritionnel'!$E$10
Name frac_MAMtoSAM: 'Données pop de l''année de ref'!#REF!
Name frac_other_staples: 'Données pop de l''année de ref'!$C$20
Name frac_PW_health_facility: 'Données pop de l''année de ref'!$C$11
Name frac_rice: 'Données pop de l''année de ref'!$C$17
Name frac_sam_1_5months: 'Dist. de l''état nutritionnel'!$D$11
Name frac_sam_12_23months: 'Dist. de l''état nutritionnel'!$F$11
Name frac_sam_1month: 'Dist. de l''état nutritionnel'!$C$11
Name frac_sam_24_59months: 'Dist. de l''état nutritionnel'!$G$11
Name frac_sam_6_11months: 'Dist. de l''état nutritionnel'!$E$11
Name frac_SAMtoMAM: 'Données pop de l''année de ref'!#REF!
Name frac_subsistence_farming: 'Données pop de l''année de ref'!$C$16
Name frac_wheat: 'Données pop de l''année de ref'!$C$18
Name infant_mortality: 'Données pop de l''année de ref'!$C$38
Name iron_deficiency_anaemia: 'Données pop de l''année de ref'!$C$59
Name manage_mam: 'Traitement de la MAS'!$D$2
Name maternal_mortality: 'Données pop de l''année de ref'!$C$40
Name neonatal_mortality: 'Données pop de l''année de ref'!$C$37
Name Percentage_of_pregnant_women_attending_health_facility: 'Données pop de l''année de ref'!$C$11
Name preterm_AGA: 'Données pop de l''année de ref'!$C$46
Name preterm_SGA: 'Données pop de l''année de ref'!$C$45
Name school_attendance: 'Données pop de l''année de ref'!$C$10
Name start_year: 'Données pop de l''année de ref'!$C$3
Name stillbirth: 'Données pop de l''année de ref'!$C$39
Name stillbirth: 'Données pop de l''année de ref'!$C$42
Name term_AGA: 'Données pop de l''année de ref'!$C$48
Name term_SGA: 'Données pop de l''année de ref'!$C$47
Name U5_mortality: 'Données pop de l''année de ref'!$C$39

Sheet Données pop de l'année de ref
A1: Données de l'année de référence | B1: Field | C1: Données
A2: Années de projection
B3: Année de référence (première année de la projection) | C3: 2024
B4: Année finale | C4: 2035
A6: Données démographiques
B7: Population des enfants de moins de 5 ans | C7: 674530.52
B8: Pourcentage de la population en situation d'insécurité alimentaire (pauvre par défaut) | C8: 0.016
B9: Pourcentage de la population exposé au risque de paludisme | C9: 0.01
B10: Fréquentation scolaire (pourcentage des femmes de 15 à 19 ans) | C10: 0.66318047
B11: Pourcentage des femmes enceintes fréquentant un établissement de santé | C11: 1
B12: Pourcentage des enfants fréquentant un établissement de santé | C12: 1
B13: Besoin non satisfait pour la planification familiale | C13: 0.174
A15: Alimentation
B16: Fraction de l'agriculture de subsistance | C16: 0.1
B17: Fraction qui mange du riz comme denrée de base principale | C17: 0.01
B18: Fraction qui mange du blé comme denrée de base principale | C18: 0.98
B19: Fraction qui mange du maïs comme denrée de base principale | C19: 0.01
B20: Fraction qui consomme d'autres denrées de base comme denrée de base principale | C20: =1-frac_rice-frac_wheat-frac_maize -> 0
A22: Répartition par âge des femmes enceintes
B23: Pourcentage des femmes enceintes âgées de 15 à 19 ans | C23: 0.1144
B24: Pourcentage des femmes enceintes âgées de 20 à 29 ans | C24: 0.5066
B25: Pourcentage des femmes enceintes âgées de 30 à 39 ans | C25: 0.3217
B26: Pourcentage des femmes enceintes âgées de 40 à 49 ans | C26: 0.0573
A28: Espacement des naissances
B29: Première naissance | C29: 0.24713422
B30: moins de 18 mois | C30: 0.12625974
B31: 18 à 23 mois | C31: 0.15756467
B32: 24 mois ou plus | C32: 0.46904137
B33: Total (doit être 100%) | C33: =SUM(C29:C32) -> 1
A35: Mortalité et facteurs de risque de l'année de référence
A36: Mortalité
B37: Mortalité néonatale (pour 1 000 naissances vivantes) | C37: 9.65179
B38: Mortalité infantile (pour 1 000 naissances vivantes) | C38: 15.57174
B39: Mortalité des moins de 5 ans (pour 1 000 naissances vivantes) | C39: 18.15749
B40: Mortalité maternelle (pour 1 000 naissances vivantes) | C40: 0.71
B41: Fraction des grossesses se terminant par un avortement spontané | C41: 0.12
B42: Mortinatalité (pour 1 000 naissances totales) | C42: 10.01533
A44: Distribution des résultats des naissances
B45: SGA prématuré | C45: 0.0066462
B46: AGA prématuré | C46: 0.0714129
...

Sheet Projections démographiques
A1: année | B1: Nombre de naissances | C1: FAP: 15-19 ans | D1: FAP: 20-29 ans | E1: FAP: 30-39 ans | F1: FAP: 40-49 ans | G1: Total FAP | H1: Estimation des femmes enceintes | I1: FAP non enceintes
A2: =start_year -> 2024 | B2: 136586 | C2: 355057.5 | D2: 585919 | E2: 545690 | F2: 350057 | G2: =C2+D2+E2+F2 -> 1836723.5 | H2: =(B2 + stillbirth*B2/(1000-stillbirth))/(1-abortion) -> 156781.58 | I2: =G2-H2 -> 1679941.9
A3: =IF($A$2+ROW(A3)-2<=end_year,A2+1,"") -> 2025 | B3: 135746 | C3: 356596.5 | D3: 582284.5 | E3: 553058.5 | F3: 362878 | G3: =C3+D3+E3+F3 -> 1854817.5 | H3: =(B3 + stillbirth*B3/(1000-stillbirth))/(1-abortion) -> 155817.38 | I3: =G3-H3 -> 1699000.1
A4: =IF($A$2+ROW(A4)-2<=end_year,A3+1,"") -> 2026 | B4: 135253 | C4: 358223.5 | D4: 578843 | E4: 559152.5 | F4: 376414.5 | G4: =C4+D4+E4+F4 -> 1872633.5 | H4: =(B4 + stillbirth*B4/(1000-stillbirth))/(1-abortion) -> 155251.49 | I4: =G4-H4 -> 1717382
A5: =IF($A$2+ROW(A5)-2<=end_year,A4+1,"") -> 2027 | B5: 134015 | C5: 360497.5 | D5: 575855.5 | E5: 563972.5 | F5: 390259 | G5: =C5+D5+E5+F5 -> 1890584.5 | H5: =(B5 + stillbirth*B5/(1000-stillbirth))/(1-abortion) -> 153830.44 | I5: =G5-H5 -> 1736754.1
A6: =IF($A$2+ROW(A6)-2<=end_year,A5+1,"") -> 2028 | B6: 133242 | C6: 363985.5 | D6: 573514.5 | E6: 567361 | F6: 404181.5 | G6: =C6+D6+E6+F6 -> 1909042.5 | H6: =(B6 + stillbirth*B6/(1000-stillbirth))/(1-abortion) -> 152943.14 | I6: =G6-H6 -> 1756099.4
A7: =IF($A$2+ROW(A7)-2<=end_year,A6+1,"") -> 2029 | B7: 131980 | C7: 368489.5 | D7: 571956.5 | E7: 569416.5 | F7: 417897.5 | G7: =C7+D7+E7+F7 -> 1927760 | H7: =(B7 + stillbirth*B7/(1000-stillbirth))/(1-abortion) -> 151494.54 | I7: =G7-H7 -> 1776265.5
A8: =IF($A$2+ROW(A8)-2<=end_year,A7+1,"") -> 2030 | B8: 131206 | C8: 373690 | D8: 571146 | E8: 570176.5 | F8: 430736 | G8: =C8+D8+E8+F8 -> 1945748.5 | H8: =(B8 + stillbirth*B8/(1000-stillbirth))/(1-abortion) -> 150606.1 | I8: =G8-H8 -> 1795142.4
A9: =IF($A$2+ROW(A9)-2<=end_year,A8+1,"") -> 2031 | B9: 129929 | C9: 379121.5 | D9: 571213.5 | E9: 569516.5 | F9: 442324 | G9: =C9+D9+E9+F9 -> 1962175.5 | H9: =(B9 + stillbirth*B9/(1000-stillbirth))/(1-abortion) -> 149140.28 | I9: =G9-H9 -> 1813035.2
A10: =IF($A$2+ROW(A10)-2<=end_year,A9+1,"") -> 2032 | B10: 129556 | C10: 384437.5 | D10: 572328 | E10: 567573 | F10: 452811 | G10: =C10+D10+E10+F10 -> 1977149.5 | H10: =(B10 + stillbirth*B10/(1000-stillbirth))/(1-abortion) -> 148712.13 | I10: =G10-H10 -> 1828437.4
A11: =IF($A$2+ROW(A11)-2<=end_year,A10+1,"") -> 2033 | B11: 128809 | C11: 388779.5 | D11: 574894.5 | E11: 564747.5 | F11: 462279 | G11: =C11+D11+E11+F11 -> 1990700.5 | H11: =(B11 + stillbirth*B11/(1000-stillbirth))/(1-abortion) -> 147854.68 | I11: =G11-H11 -> 1842845.8
A12: =IF($A$2+ROW(A12)-2<=end_year,A11+1,"") -> 2034 | B12: 128412 | C12: 391398 | D12: 579219 | E12: 561399.5 | F12: 470573.5 | G12: =C12+D12+E12+F12 -> 2002590 | H12: =(B12 + stillbirth*B12/(1000-stillbirth))/(1-abortion) -> 147398.98 | I12: =G12-H12 -> 1855191
A13: =IF($A$2+ROW(A13)-2<=end_year,A12+1,"") -> 2035 | B13: 127620 | C13: 392517.5 | D13: 584908.5 | E13: 557852.5 | F13: 477711.5 | G13: =C13+D13+E13+F13 -> 2012990 | H13: =(B13 + stillbirth*B13/(1000-stillbirth))/(1-abortion) -> 146489.87 | I13: =G13-H13 -> 1866500.1
A14: =IF($A$2+ROW(A14)-2<=end_year,A13+1,"")
A15: =IF($A$2+ROW(A15)-2<=end_year,A14+1,"")
A16: =IF($A$2+ROW(A16)-2<=end_year,A15+1,"")
A17: =IF($A$2+ROW(A17)-2<=end_year,A16+1,"")
A18: =IF($A$2+ROW(A18)-2<=end_year,A17+1,"")
A19: =IF($A$2+ROW(A19)-2<=end_year,A18+1,"")
A20: =IF($A$2+ROW(A20)-2<=end_year,A19+1,"")
A21: =IF($A$2+ROW(A21)-2<=end_year,A20+1,"")
A22: =IF($A$2+ROW(A22)-2<=end_year,A21+1,"")
A23: =IF($A$2+ROW(A23)-2<=end_year,A22+1,"")
A24: =IF($A$2+ROW(A24)-2<=end_year,A23+1,"")
A25: =IF($A$2+ROW(A25)-2<=end_year,A24+1,"")
... A37: =IF($A$2+ROW(A37)-2<=end_year,A36+1,"")
A38: =IF($A$2+ROW(A38)-2<=end_year,A37+1,"") | G38: =C38+D38+E38+F38 -> 0 | H38: =(B38 + stillbirth*B38/(1000-stillbirth))/(1-abortion) -> 0 | I38: =G38-H38 -> 0
A39: =IF($A$2+ROW(A39)-2<=end_year,A38+1,"") | G39: =C39+D39+E39+F39 -> 0 | H39: =(B39 + stillbirth*B39/(1000-stillbirth))/(1-abortion) -> 0 | I39: =G39-H39 -> 0
A40: =IF($A$2+ROW(A40)-2<=end_year,A39+1,"") | G40: =C40+D40+E40+F40 -> 0 | H40: =(B40 + stillbirth*B40/(1000-stillbirth))/(1-abortion) -> 0 | I40: =G40-H40 -> 0

Sheet Causes du décès
A1: ="Pourcentage des morts de l'année de référence ("&start_year&") imputable à chaque cause" -> Pourcentage des morts de l'année de référence (2024) imputable à chaque cause
A2: Néonatal | B2: Causes | C2: <1 mois
B3: Diarrhée néonatale | C3: 0.00076678956
B4: Sepsis néonatal | C4: 0.064427525
B5: Pneumonie néonatale | C5: 0.031018023
B6: Asphyxie néonatale | C6: 0.18516063
B7: Prématurité néonatale | C7: 0.44250568
B8: Tétanos néonatal | C8: 0.00010751256
B9: Anomalies congénitales néonatales | C9: 0.17925164
B10: Autres pathologies néonatales | C10: 0.096762202
B11: Total (doit être 100%) | C11: =SUM(C3:C10) -> 1
A13: Enfants | B13: Causes | C13: 1-5 mois | D13: 6-11 mois | E13: 12-23 mois | F13: 24-59 mois
B14: Diarrhée | C14: 0.17328306 | D14: 0.17328306 | E14: 0.17328306 | F14: 0.17328306
B15: Pneumonie | C15: 0.36070214 | D15: 0.36070214 | E15: 0.36070214 | F15: 0.36070214
B16: Méningite | C16: 0.037287091 | D16: 0.037287091 | E16: 0.037287091 | F16: 0.037287091
B17: Rougeole | C17: 0 | D17: 0 | E17: 0 | F17: 0
B18: Paludisme | C18: 0 | D18: 0 | E18: 0 | F18: 0
B19: Coqueluche | C19: 0.10448947 | D19: 0.10448947 | E19: 0.10448947 | F19: 0.10448947
B20: SIDA | C20: 0.030766079 | D20: 0.030766079 | E20: 0.030766079 | F20: 0.030766079
B21: Blessure | C21: 0.28076528 | D21: 0.28076528 | E21: 0.28076528 | F21: 0.28076528
B22: Autre | C22: 0.012706881 | D22: 0.012706881 | E22: 0.012706881 | F22: 0.012706881
B23: Total (doit être 100%) | C23: =SUM(C14:C22) -> 1 | D23: =SUM(D14:D22) -> 1 | E23: =SUM(E14:E22) -> 1 | F23: =SUM(F14:F22) -> 1
A25: Femmes enceintes | B25: Causes | C25: Femmes enceintes
B26: Hémorragie antepartum | C26: 0.028053888
B27: Hémorragie intra-partum | C27: 0.022885193
B28: Hémorragie du post-partum | C28: 0.17241262
B29: Troubles hypertensifs | C29: 0.18535888
B30: Sepsis | C30: 0.10644221
B31: Avortement | C31: 0.22565471
B32: Embolie | C32: 0.025746143
B33: Autres causes directes | C33: 0.099438821
B34: Causes indirectes | C34: 0.13400752
B35: Total (doit être 100%) | C35: =SUM(C26:C34) -> 1

Sheet Dist. de l'état nutritionnel
A1: ="Pourcentage de la population dans chaque catégorie pendant l'année de référence ("&start_year&")" -> Pourcentage de la population dans chaque catégorie pendant l'année de référence (2024) | B1: État | C1: <1 mois | D1: 1-5 mois | E1: 6-11 mois | F1: 12-23 mois | G1: 24-59 mois
A2: Retard de croissance (taille-pour-âge) | B2: Normal (score HAZ > -1) | C2: =IFERROR(1-_xlfn.NORM.DIST(_xlfn.NORM.INV(SUM(C4:C5), 0, 1) + 1, 0, 1, TRUE), "") -> 0.67504211 | D2: =IFERROR(1-_xlfn.NORM.DIST(_xlfn.NORM.INV(SUM(D4:D5), 0, 1) + 1, 0, 1, TRUE), "") -> 0.67504211 | E2: =IFERROR(1-_xlfn.NORM.DIST(_xlfn.NORM.INV(SUM(E4:E5), 0, 1) + 1, 0, 1, TRUE), "") -> 0.75043818 | F2: =IFERROR(1-_xlfn.NORM.DIST(_xlfn.NORM.INV(SUM(F4:F5), 0, 1) + 1, 0, 1, TRUE), "") -> 0.66568741 | G2: =IFERROR(1-_xlfn.NORM.DIST(_xlfn.NORM.INV(SUM(G4:G5), 0, 1) + 1, 0, 1, TRUE), "") -> 0.74912991
B3: Léger (score HAZ entre -2 et -1) | C3: =IFERROR(_xlfn.NORM.DIST(_xlfn.NORM.INV(SUM(C4:C5), 0, 1) + 1, 0, 1, TRUE) - SUM(C4:C5), "") -> 0.25196799 | D3: =IFERROR(_xlfn.NORM.DIST(_xlfn.NORM.INV(SUM(D4:D5), 0, 1) + 1, 0, 1, TRUE) - SUM(D4:D5), "") -> 0.25196799 | E3: =IFERROR(_xlfn.NORM.DIST(_xlfn.NORM.INV(SUM(E4:E5), 0, 1) + 1, 0, 1, TRUE) - SUM(E4:E5), "") -> 0.20267992 | F3: =IFERROR(_xlfn.NORM.DIST(_xlfn.NORM.INV(SUM(F4:F5), 0, 1) + 1, 0, 1, TRUE) - SUM(F4:F5), "") -> 0.25767179 | G3: =IFERROR(_xlfn.NORM.DIST(_xlfn.NORM.INV(SUM(G4:G5), 0, 1) + 1, 0, 1, TRUE) - SUM(G4:G5), "") -> 0.20358369
B4: Modéré (score HAZ entre -3 et -2) | C4: 0.034071 | D4: 0.034071 | E4: 0.0360883 | F4: 0.0636949 | G4: 0.0383731
B5: Élevé (score HAZ < -3) | C5: 0.0389189 | D5: 0.0389189 | E5: 0.0107936 | F5: 0.0129459 | G5: 0.0089133
A8: Émaciation (poids-pour-taille) | B8: Normal (score WHZ > -1) | C8: =IFERROR(1-_xlfn.NORM.DIST(_xlfn.NORM.INV(SUM(C10:C11), 0, 1) + 1, 0, 1, TRUE), "") -> 0.74089077 | D8: =IFERROR(1-_xlfn.NORM.DIST(_xlfn.NORM.INV(SUM(D10:D11), 0, 1) + 1, 0, 1, TRUE), "") -> 0.74089077 | E8: =IFERROR(1-_xlfn.NORM.DIST(_xlfn.NORM.INV(SUM(E10:E11), 0, 1) + 1, 0, 1, TRUE), "") -> 0.96677592 | F8: =IFERROR(1-_xlfn.NORM.DIST(_xlfn.NORM.INV(SUM(F10:F11), 0, 1) + 1, 0, 1, TRUE), "") -> 0.92383805 | G8: =IFERROR(1-_xlfn.NORM.DIST(_xlfn.NORM.INV(SUM(G10:G11), 0, 1) + 1, 0, 1, TRUE), "") -> 0.94012842
B9: Léger (score WHZ entre -2 et -1) | C9: =IFERROR(_xlfn.NORM.DIST(_xlfn.NORM.INV(SUM(C10:C11), 0, 1) + 1, 0, 1, TRUE) - SUM(C10:C11), "") -> 0.20923703 | D9: =IFERROR(_xlfn.NORM.DIST(_xlfn.NORM.INV(SUM(D10:D11), 0, 1) + 1, 0, 1, TRUE) - SUM(D10:D11), "") -> 0.20923703 | E9: =IFERROR(_xlfn.NORM.DIST(_xlfn.NORM.INV(SUM(E10:E11), 0, 1) + 1, 0, 1, TRUE) - SUM(E10:E11), "") -> 0.030935579 | F9: =IFERROR(_xlfn.NORM.DIST(_xlfn.NORM.INV(SUM(F10:F11), 0, 1) + 1, 0, 1, TRUE) - SUM(F10:F11), "") -> 0.068641045 | G9: =IFERROR(_xlfn.NORM.DIST(_xlfn.NORM.INV(SUM(G10:G11), 0, 1) + 1, 0, 1, TRUE) - SUM(G10:G11), "") -> 0.054575181
B10: MM (score WHZ entre -3 et -2) | C10: 0.0265208 | D10: 0.0265208 | E10: 0.0022885 | F10: 0.0050772 | G10: 0.0037767
B11: MAS (score WHZ < -3) | C11: 0.0233514 | D11: 0.0233514 | E11: 0 | F11: 0.0024437 | G11: 0.0015197
A13: Anémie | C13: <1 mois | D13: 1-5 mois | E13: 6-11 mois | F13: 12-23 mois | G13: 24-59 mois | H13: FE: 15-19 ans | I13: FE: 20-29 ans | J13: FE: 30-39 ans | K13: FE: 40-49 ans | L13: FAP: 15-19 ans | M13: FAP: 20-29 ans | N13: FAP: 30-39 ans | O13: FAP: 40-49 ans
B14: Prévalence de l'anémie | C14: 0.33770808 | D14: 0.33097332 | E14: 0.33097332 | F14: 0.25412178 | G14: 0.25412178 | H14: 0.327 | I14: 0.327 | J14: 0.327 | K14: 0.327 | L14: 0.223 | M14: 0.223 | N14: 0.223 | O14: 0.223
B15: Prévalence de l'anémie ferriprive | C15: =iron_deficiency_anaemia*C14 -> 0.19242708 | D15: =iron_deficiency_anaemia*D14 -> 0.18858959 | E15: =iron_deficiency_anaemia*E14 -> 0.18858959 | F15: =iron_deficiency_anaemia*F14 -> 0.14479935 | G15: =iron_deficiency_anaemia*G14 -> 0.14479935 | H15: =iron_deficiency_anaemia*H14 -> 0.18632558 | I15: =iron_deficiency_anaemia*I14 -> 0.18632558 | J15: =iron_deficiency_anaemia*J14 -> 0.18632558 | ... O15: =iron_deficiency_anaemia*O14 -> 0.12706607

Sheet Dist. l'allaitement maternel
A1: ="Pourcentage des enfants dans chaque catégorie pendant l'année de référence ("&start_year&")" -> Pourcentage des enfants dans chaque catégorie pendant l'année de référence (2024) | B1: État | C1: <1 mois | D1: 1-5 mois | E1: 6-11 mois | F1: 12-23 mois | G1: 24-59 mois
A2: Allaitement maternel | B2: Exclusif | C2: 0.6431855 | D2: 0.3008649 | E2: 0 | F2: 0 | G2: 0
B3: Prédominant | C3: 0.1938405 | D3: 0.2158948 | E3: 0 | F3: 0 | G3: 0
B4: Partiel | C4: 0.1472349 | D4: 0.3919264 | E4: 0.7774008 | F4: 0.3283283 | G4: 0
B5: Aucun | C5: 0.0157391 | D5: 0.0913139 | E5: =1-SUM(E2:E4) -> 0.2225992 | F5: =1-SUM(F2:F4) -> 0.6716717 | G5: =1-SUM(G2:G4) -> 1

Sheet Tendances temporelles
A1: Risque | B1: Population | C1: 2010 | D1: 2011 | E1: 2012 | F1: 2013 | G1: 2014 | H1: 2015 | I1: 2016 | J1: 2017 | K1: 2018
A2: Prévalence du retard de croissance (%) | B2: Enfants âgés de 0 à 59 mois
A4: Prévalence de l'émaciation (%) | B4: Enfants âgés de 0 à 59 mois
A6: Prévalence de l'anémie (%) | B6: Enfants âgés de 0 à 59 mois
B7: Femmes enceintes
B8: Femmes en âge de procréer
A10: Prévalence de l'allaitement maternel adapté à l'âge des enfants | B10: Enfants âgés de 0 à 5 mois
B11: Enfants âgés de 6 à 23 mois
A13: Mortalité | B13: Moins de cinq ans (décès pour 1 000 naissances)
B14: Maternelle (décès pour 1 000 naissances)

Sheet Perte économique
A1: Type | B1: Coût
A2: Épisode d'émaciation d'un enfant | B2: 10
A3: Enfant souffrant d'un retard de croissance qui aura 5 ans (au cours de sa vie) | B3: 10
A4: Décès d'enfant | B4: 10
A5: Décès maternel | B5: 10
A6: Enfant anémique (par an) | B6: 10
A7: Femme enceinte anémique (par grossesse) | B7: 10

Sheet Paquets ANJE
A1: Paquet ANJE | B1: Population cible | C1: Établissement de santé | D1: Communautaire | E1: Médias de masse
A2: ANJE 1 | B2: Femmes enceintes | E2: =IF(E$7="","",E$7)
B3: <1 mois | D3: x | E3: =IF(E$7="","",E$7)
B4: 1-5 mois | D4: x | E4: =IF(E$7="","",E$7)
B5: 6-11 mois | D5: x | E5: =IF(E$7="","",E$7)
B6: 12-23 mois | D6: x | E6: =IF(E$7="","",E$7)
B7: Tous
A9: ANJE 2 | B9: Femmes enceintes | E9: =IF(E$7="","",E$7)
B10: <1 mois | E10: =IF(E$7="","",E$7)
B11: 1-5 mois | E11: =IF(E$7="","",E$7)
B12: 6-11 mois | D12: x | E12: =IF(E$7="","",E$7)
B13: 12-23 mois | D13: x | E13: =IF(E$7="","",E$7)
B14: Tous
A16: ANJE 3 | B16: Femmes enceintes | D16: x | E16: =IF(E$7="","",E$7)
B17: <1 mois | D17: x | E17: =IF(E$7="","",E$7)
B18: 1-5 mois | D18: x | E18: =IF(E$7="","",E$7)
B19: 6-11 mois | D19: x | E19: =IF(E$7="","",E$7)
B20: 12-23 mois | D20: x | E20: =IF(E$7="","",E$7)
B21: Tous

Sheet Traitement de la MAS
A1: Field | B1: Défaut | C1: Extension | D1: Ajouter une extension
A2: Programme | B2: Traitement de la MAS | C2: Gestion de la MAM
A3: Mode de livraison | B3: Établissement de santé | C3: Communautaire

Sheet Coûts et couvertures des prgms
A1: Programme | B1: ="Couverture de l'année de référence ("&start_year&")" -> Couverture de l'année de référence (2024) | C1: Couverture à saturation de la population cible | D1: Coût à l'unité (US$) | E1: Relation coût-couverture | F1: Augmentation maximale par an | G1: Réduction maximale par an
A2: Supplémentation équilibrée en énergie et en protéines | B2: 0 | C2: 0.95 | D2: 57.606668 | E2: Linéaire (coût marginal constant) [par défaut]. | F2: 1 | G2: 1
A3: Supplémentation en calcium | B3: 0.24393369 | C3: 0.95 | D3: 39.870655 | E3: Linéaire (coût marginal constant) [par défaut]. | F3: 1 | G3: 1
A4: Transferts monétaires | B4: 0 | C4: 0.95 | D4: 407.77421 | E4: Linéaire (coût marginal constant) [par défaut]. | F4: 1 | G4: 1
A5: Clampage tardif du cordon | B5: 0 | C5: 0.95 | D5: 1.0211921 | E5: Linéaire (coût marginal constant) [par défaut]. | F5: 1 | G5: 1
A6: Planification familiale | B6: 0 | C6: 0.95 | D6: 99.99 | E6: Linéaire (coût marginal constant) [par défaut]. | F6: 1 | G6: 1
A7: Enrichissement du maïs en FAF | B7: 0 | C7: 0.95 | D7: 99.99 | E7: Linéaire (coût marginal constant) [par défaut]. | F7: 1 | G7: 1
A8: Enrichissement du riz en FAF | B8: 0 | C8: 0.95 | D8: 99.99 | E8: Linéaire (coût marginal constant) [par défaut]. | F8: 1 | G8: 1
A9: Enrichissement en FAF de la farine de blé | B9: 0 | C9: 0.95 | D9: 99.99 | E9: Linéaire (coût marginal constant) [par défaut]. | F9: 1 | G9: 1
A10: SFAF (communautaire) | B10: 0 | C10: 0.95 | D10: 13.002954 | E10: Linéaire (coût marginal constant) [par défaut]. | F10: 1 | G10: 1
A11: SFAF (établissement de santé) | B11: 0 | C11: 0.95 | D11: 13.002954 | E11: Linéaire (coût marginal constant) [par défaut]. | F11: 1 | G11: 1
A12: SFAF (détaillant) | B12: 0 | C12: 0.95 | D12: 13.002954 | E12: Linéaire (coût marginal constant) [par défaut]. | F12: 1 | G12: 1
A13: SFAF (école) | B13: 0 | C13: 0.95 | D13: 13.002954 | E13: Linéaire (coût marginal constant) [par défaut]. | F13: 1 | G13: 1
... A39: Supplémentation en zinc | B39: 0 | C39: 0.95 | D39: 99.99 | E39: Linéaire (coût marginal constant) [par défaut]. | F39: 1 | G39: 1

Sheet Dépendances du programme
A1: Programme | B1: Dépendance d'exclusion | C1: Dépendance de seuil
A2: SFAF pour les femmes enceintes (communautaire) | B2: Supplémentation en micronutriments multiples
A3: SFAF pour les femmes enceintes (établissement de santé) | B3: Supplémentation en micronutriments multiples
A4: Fourniture publique d'aliments complémentaires | B4: Supplémentation en nutriments à base de lipides
A5: Poudres de micronutriments | B5: Supplémentation en nutriments à base de lipides
A6: Fourniture publique d'aliments complémentaires | B6: Petite quantité de supplémentation en nutriments à base de lipides
A7: Poudres de micronutriments | B7: Petite quantité de supplémentation en nutriments à base de lipides
A8: Supplémentation en zinc | B8: Petite quantité de supplémentation en nutriments à base de lipides
A9: Supplémentation en vitamine A | B9: Petite quantité de supplémentation en nutriments à base de lipides

Sheet Programmes de référence
A1: Programme
A2: Planification familiale
A3: TPIg
A4: Moustiquaires imprégnées d'insecticide de longue durée
A5: WASH: lavage des mains
A6: WASH: Élimination hygiénique
A7: WASH: Amélioration de l'assainissement
A8: WASH: Source d'eau améliorée
A9: WASH: Eau courante

Sheet Incidence des conditions
A1: Condition | B1: <1 mois | C1: 1-5 mois | D1: 6-11 mois | E1: 12-23 mois | F1: 24-59 mois
A2: Diarrhée | B2: ='Données pop de l''année de ref'!C51 -> 3.2 | C2: ='Données pop de l''année de ref'!C52 -> 3.2 | D2: ='Données pop de l''année de ref'!C53 -> 3.2 | E2: ='Données pop de l''année de ref'!C54 -> 3.2 | F2: ='Données pop de l''année de ref'!C55 -> 3.2
A3: MM | B3: =frac_mam_1month * 2.6 -> 0.06895408 | C3: =frac_mam_1_5months * 2.6 -> 0.06895408 | D3: =frac_mam_6_11months * 2.6 -> 0.0059501 | E3: =frac_mam_12_23months * 2.6 -> 0.01320072 | F3: =frac_mam_24_59months * 2.6 -> 0.00981942
A4: MAS | B4: =frac_sam_1month * 2.6 -> 0.06071364 | C4: =frac_sam_1_5months * 2.6 -> 0.06071364 | D4: =frac_sam_6_11months * 2.6 -> 0 | E4: =frac_sam_12_23months * 2.6 -> 0.00635362 | F4: =frac_sam_24_59months * 2.6 -> 0.00395122

Sheet Programmes-population cible
A1: Groupe général de la population | B1: Programme | C1: <1 mois | D1: 1-5 mois | E1: 6-11 mois | F1: 12-23 mois | G1: 24-59 mois | H1: FE: 15-19 ans | I1: FE: 20-29 ans | J1: FE: 30-39 ans | K1: FE: 40-49 ans | L1: FAP: 15-19 ans | M1: FAP: 20-29 ans | N1: FAP: 30-39 ans | O1: FAP: 40-49 ans
A2: Enfants | B2: Transferts monétaires | C2: 0 | D2: =food_insecure -> 0.016 | E2: =food_insecure -> 0.016 | F2: =food_insecure -> 0.016 | G2: =food_insecure -> 0.016 | H2: 0 | I2: 0 | J2: 0 | K2: 0 | L2: 0 | M2: 0 | N2: 0 | O2: 0
B3: Clampage tardif du cordon | C3: 1 | D3: 0 | E3: 0 | F3: 0 | G3: 0 | H3: 0 | I3: 0 | J3: 0 | K3: 0 | L3: 0 | M3: 0 | N3: 0 | O3: 0
B4: Soins maternals kangourou | C4: 1 | D4: 0 | E4: 0 | F4: 0 | G4: 0 | H4: 0 | I4: 0 | J4: 0 | K4: 0 | L4: 0 | M4: 0 | N4: 0 | O4: 0
B5: Supplémentation en nutriments à base de lipides | C5: 0 | D5: 0 | E5: =food_insecure -> 0.016 | F5: =food_insecure -> 0.016 | G5: 0 | H5: 0 | I5: 0 | J5: 0 | K5: 0 | L5: 0 | M5: 0 | N5: 0 | O5: 0
B6: Poudres de micronutriments | C6: 0 | D6: 0 | E6: =1 -> 1 | F6: =1 -> 1 | G6: =1 -> 1 | H6: 0 | I6: 0 | J6: 0 | K6: 0 | L6: 0 | M6: 0 | N6: 0 | O6: 0
B7: Sels de réhydratation orale | C7: =diarrhoea_1mo*frac_diarrhea_severe -> 0.062 | D7: =diarrhoea_1_5mo*frac_diarrhea_severe -> 0.062 | E7: =diarrhoea_6_11mo*frac_diarrhea_severe -> 0.062 | F7: =diarrhoea_12_23mo*frac_diarrhea_severe -> 0.062 | G7: =diarrhoea_24_59mo*frac_diarrhea_severe -> 0.062 | H7: 0 | I7: 0 | J7: 0 | K7: 0 | L7: 0 | M7: 0 | N7: 0 | O7: 0
B8: Fourniture publique d'aliments complémentaires | C8: 0 | D8: 0 | E8: =food_insecure -> 0.016 | F8: =food_insecure -> 0.016 | G8: 0 | H8: 0 | I8: 0 | J8: 0 | K8: 0 | L8: 0 | M8: 0 | N8: 0 | O8: 0
B9: Petite quantité de supplémentation en nutriments à base de lipides | C9: 0 | D9: 0 | E9: =food_insecure -> 0.016 | F9: =food_insecure -> 0.016 | G9: 0 | H9: 0 | I9: 0 | J9: 0 | K9: 0 | L9: 0 | M9: 0 | N9: 0 | O9: 0
B10: Traitement de la MAS | C10: 0 | D10: =IF(ISBLANK(comm_deliv), frac_children_health_facility,1) -> 1 | E10: =IF(ISBLANK(comm_deliv), frac_children_health_facility,1) -> 1 | F10: =IF(ISBLANK(comm_deliv), frac_children_health_facility,1) -> 1 | G10: =IF(ISBLANK(comm_deliv), frac_children_health_facility,1) -> 1 | H10: 0 | I10: 0 | J10: 0 | K10: 0 | L10: 0 | M10: 0 | N10: 0 | O10: 0
B11: Supplémentation en vitamine A | C11: 0 | D11: 0 | E11: 1 | F11: 1 | G11: 1 | H11: 0 | I11: 0 | J11: 0 | K11: 0 | L11: 0 | M11: 0 | N11: 0 | O11: 0
B12: SRO+Zn pour le traitement de la diarrhée | C12: =diarrhoea_1mo*frac_diarrhea_severe -> 0.062 | D12: =diarrhoea_1_5mo*frac_diarrhea_severe -> 0.062 | E12: =diarrhoea_6_11mo*frac_diarrhea_severe -> 0.062 | F12: =diarrhoea_12_23mo*frac_diarrhea_severe -> 0.062 | G12: =diarrhoea_24_59mo*frac_diarrhea_severe -> 0.062 | H12: 0 | I12: 0 | J12: 0 | K12: 0 | L12: 0 | M12: 0 | N12: 0 | O12: 0
B13: Supplémentation en zinc | C13: 0 | D13: 0 | E13: 1 | F13: 1 | G13: 1 | H13: 0 | I13: 0 | J13: 0 | K13: 0 | L13: 0 | M13: 0 | N13: 0 | O13: 0
A15: Femmes enceintes | B15: Supplémentation équilibrée en énergie et en protéines | C15: 0 | D15: 0 | E15: 0 | F15: 0 | G15: 0 | H15: =food_insecure -> 0.016 | I15: =food_insecure -> 0.016 | J15: =food_insecure -> 0.016 | K15: =food_insecure -> 0.016 | L15: 0 | M15: 0 | N15: 0 | O15: 0
B16: Supplémentation en calcium | C16: 0 | D16: 0 | E16: 0 | F16: 0 | G16: 0 | H16: 1 | I16: 1 | J16: 1 | K16: 1 | L16: 0 | M16: 0 | N16: 0 | O16: 0
B17: SFAF pour les femmes enceintes (communautaire) | C17: 0 | D17: 0 | E17: 0 | F17: 0 | G17: 0 | H17: =1 -> 1 | I17: =1 -> 1 | J17: =1 -> 1 | K17: =1 -> 1 | L17: 0 | M17: 0 | N17: 0 | O17: 0
B18: SFAF pour les femmes enceintes (établissement de santé) | C18: 0 | D18: 0 | E18: 0 | F18: 0 | G18: 0 | H18: =frac_PW_health_facility -> 1 | I18: =frac_PW_health_facility -> 1 | J18: =frac_PW_health_facility -> 1 | K18: =frac_PW_health_facility -> 1 | L18: 0 | M18: 0 | N18: 0 | O18: 0
B19: TPIg | C19: 0 | D19: 0 | E19: 0 | F19: 0 | G19: 0 | H19: =frac_malaria_risk -> 0.01 | I19: =frac_malaria_risk -> 0.01 | J19: =frac_malaria_risk -> 0.01 | K19: =frac_malaria_risk -> 0.01 | L19: 0 | M19: 0 | N19: 0 | O19: 0
B20: Mg pour l'éclampsie | C20: 0 | D20: 0 | E20: 0 | F20: 0 | G20: 0 | H20: 1 | I20: 1 | J20: 1 | K20: 1 | L20: 0 | M20: 0 | N20: 0 | O20: 0
B21: Mg pour la pré-éclampsie | C21: 0 | D21: 0 | E21: 0 | F21: 0 | G21: 0 | H21: 1 | I21: 1 | J21: 1 | K21: 1 | L21: 0 | M21: 0 | N21: 0 | O21: 0
B22: Supplémentation en micronutriments multiples | C22: 0 | D22: 0 | E22: 0 | F22: 0 | G22: 0 | H22: =1 -> 1 | I22: =1 -> 1 | J22: =1 -> 1 | K22: =1 -> 1 | L22: 0 | M22: 0 | N22: 0 | O22: 0
A24: FAP non enceintes | B24: Planification familiale | C24: 0 | D24: 0 | E24: 0 | F24: 0 | G24: 0 | H24: 0 | I24: 0 | J24: 0 | K24: 0 | L24: =famplan_unmet_need -> 0.174 | M24: =famplan_unmet_need -> 0.174 | N24: =famplan_unmet_need -> 0.174 | O24: =famplan_unmet_need -> 0.174
B25: SFAF (communautaire) | C25: 0 | D25: 0 | E25: 0 | F25: 0 | G25: 0 | H25: 0 | I25: 0 | J25: 0 | K25: 0 | L25: =(1-food_insecure)*(0.49)*(1-school_attendance) + food_insecure*(0.7)*(1-school_attendance) -> 0.16617329 | M25: =(1-food_insecure)*(0.49)+food_insecure*(0.7) -> 0.49336 | N25: =(1-food_insecure)*(0.49)+food_insecure*(0.7) -> 0.49336 | O25: =(1-food_insecure)*(0.49)+food_insecure*(0.7) -> 0.49336
B26: SFAF (établissement de santé) | C26: 0 | D26: 0 | E26: 0 | F26: 0 | G26: 0 | H26: 0 | I26: 0 | J26: 0 | K26: 0 | L26: =(1-food_insecure)*(0.21)*(1-school_attendance) + food_insecure*(0.3)*(1-school_attendance) -> 0.071217122 | M26: =(1-food_insecure)*(0.21)+food_insecure*(0.3) -> 0.21144 | N26: =(1-food_insecure)*(0.21)+food_insecure*(0.3) -> 0.21144 | O26: =(1-food_insecure)*(0.21)+food_insecure*(0.3) -> 0.21144
B27: SFAF (détaillant) | C27: 0 | D27: 0 | E27: 0 | F27: 0 | G27: 0 | H27: 0 | I27: 0 | J27: 0 | K27: 0 | L27: =(1-food_insecure)*(0.3)*(1-school_attendance) -> 0.099429127 | M27: =(1-food_insecure)*(0.3) -> 0.2952 | N27: =(1-food_insecure)*(0.3) -> 0.2952 | O27: =(1-food_insecure)*(0.3) -> 0.2952
B28: SFAF (école) | C28: 0 | D28: 0 | E28: 0 | F28: 0 | G28: 0 | H28: 0 | I28: 0 | J28: 0 | K28: 0 | L28: =(1-food_insecure)*1*school_attendance + food_insecure*1*school_attendance -> 0.66318047 | M28: 0 | N28: 0 | O28: 0
A30: Population générale | B30: Enrichissement du maïs en FAF | C30: 0 | D30: 0 | E30: =frac_maize -> 0.01 | F30: =frac_maize -> 0.01 | G30: =frac_maize -> 0.01 | H30: =frac_maize -> 0.01 | I30: =frac_maize -> 0.01 | J30: =frac_maize -> 0.01 | K30: =frac_maize -> 0.01 | L30: =frac_maize -> 0.01 | ... O30: =frac_maize -> 0.01
B31: Enrichissement du riz en FAF | C31: 0 | D31: 0 | E31: =frac_rice -> 0.01 | F31: =frac_rice -> 0.01 | G31: =frac_rice -> 0.01 | H31: =frac_rice -> 0.01 | I31: =frac_rice -> 0.01 | J31: =frac_rice -> 0.01 | K31: =frac_rice -> 0.01 | L31: =frac_rice -> 0.01 | ... O31: =frac_rice -> 0.01
B32: Enrichissement en FAF de la farine de blé | C32: 0 | D32: 0 | E32: =frac_wheat -> 0.98 | F32: =frac_wheat -> 0.98 | G32: =frac_wheat -> 0.98 | H32: =frac_wheat -> 0.98 | I32: =frac_wheat -> 0.98 | J32: =frac_wheat -> 0.98 | K32: =frac_wheat -> 0.98 | L32: =frac_wheat -> 0.98 | ... O32: =frac_wheat -> 0.98
B33: Enrichissement du sel en fer et en iode | C33: 0 | D33: 0 | E33: 1 | F33: 1 | G33: 1 | H33: 1 | I33: 1 | J33: 1 | K33: 1 | L33: 1 | M33: 1 | N33: 1 | O33: 1
B34: Moustiquaires imprégnées d'insecticide de longue durée | C34: =frac_malaria_risk -> 0.01 | D34: =frac_malaria_risk -> 0.01 | E34: =frac_malaria_risk -> 0.01 | F34: =frac_malaria_risk -> 0.01 | G34: =frac_malaria_risk -> 0.01 | H34: =frac_malaria_risk -> 0.01 | I34: =frac_malaria_risk -> 0.01 | J34: =frac_malaria_risk -> 0.01 | ... O34: =frac_malaria_risk -> 0.01
B35: WASH: lavage des mains | C35: 1 | D35: 1 | E35: 1 | F35: 1 | G35: 1 | H35: 1 | I35: 1 | J35: 1 | K35: 1 | L35: 1 | M35: 1 | N35: 1 | O35: 1
B36: WASH: Élimination hygiénique | C36: 1 | D36: 1 | E36: 1 | F36: 1 | G36: 1 | H36: 1 | I36: 1 | J36: 1 | K36: 1 | L36: 1 | M36: 1 | N36: 1 | O36: 1
B37: WASH: Amélioration de l'assainissement | C37: 1 | D37: 1 | E37: 1 | F37: 1 | G37: 1 | H37: 1 | I37: 1 | J37: 1 | K37: 1 | L37: 1 | M37: 1 | N37: 1 | O37: 1
B38: WASH: Source d'eau améliorée | C38: 1 | D38: 1 | E38: 1 | F38: 1 | G38: 1 | H38: 1 | I38: 1 | J38: 1 | K38: 1 | L38: 1 | M38: 1 | N38: 1 | O38: 1
B39: WASH: Eau courante | C39: 1 | D39: 1 | E39: 1 | F39: 1 | G39: 1 | H39: 1 | I39: 1 | J39: 1 | K39: 1 | L39: 1 | M39: 1 | N39: 1 | O39: 1

Sheet Options de la courbe de coût
A1: Linéaire (coût marginal constant) [par défaut].
A2: Courbe avec coût marginal croissant
A3: Courbe avec coût marginal décroissant
A4: En forme de S (coût marginal décroissant puis croissant)

Sheet Programmes-planification fam.
A1: Méthode | B1: Efficacité | C1: Distribution | D1: Coût | E1: Coût proportionnel
A2: Préservatif | B2: 0.9 | C2: 0.09 | D2: 0.8 | E2: =C2*D2 -> 0.072
A3: Stérilisation masculine | B3: 1 | C3: 0.02 | D3: 1.9 | E3: =C3*D3 -> 0.038
A4: Stérilisation féminine | B4: 1 | C4: 0.08 | D4: 2 | E4: =C4*D4 -> 0.16
A5: Injection Depo Provera | B5: 1 | C5: 0.18 | D5: 0.7 | E5: =C5*D5 -> 0.126
A6: Implant | B6: 1 | C6: 0.02 | D6: 0.7 | E6: =C6*D6 -> 0.014
A7: Pilule | B7: 0.93 | C7: 0.45 | D7: 0.9 | E7: =C7*D7 -> 0.405
A8: Retrait | B8: 0.5 | C8: 0.03 | D8: 0 | E8: =C8*D8 -> 0
A9: Sensibilisation à la fertilité | B9: 0.5 | C9: 0.11 | D9: 0 | E9: =C9*D9 -> 0
A10: DIU | B10: 0.98 | C10: 0.01 | D10: 0.6 | E10: =C10*D10 -> 0.006

Sheet Programmes - population touchée
A1: Groupe général de la population | B1: Programme | C1: <1 mois | D1: 1-5 mois | E1: 6-11 mois | F1: 12-23 mois | G1: 24-59 mois | H1: FE: 15-19 ans | I1: FE: 20-29 ans | J1: FE: 30-39 ans | K1: FE: 40-49 ans | L1: FAP: 15-19 ans | M1: FAP: 20-29 ans | N1: FAP: 30-39 ans | O1: FAP: 40-49 ans
A2: Enfants | B2: Transferts monétaires | C2: 0 | D2: 1 | E2: 1 | F2: 1 | G2: 1 | H2: 0 | I2: 0 | J2: 0 | K2: 0 | L2: 0 | M2: 0 | N2: 0 | O2: 0
B3: Clampage tardif du cordon | C3: 1 | D3: 1 | E3: 0 | F3: 0 | G3: 0 | H3: 0 | I3: 0 | J3: 0 | K3: 0 | L3: 0 | M3: 0 | N3: 0 | O3: 0
B4: ANJE 1 | C4: 1 | D4: 1 | E4: 1 | F4: 1 | G4: 1 | H4: 0 | I4: 0 | J4: 0 | K4: 0 | L4: 0 | M4: 0 | N4: 0 | O4: 0
B5: ANJE 2 | C5: 1 | D5: 1 | E5: 1 | F5: 1 | G5: 1 | H5: 0 | I5: 0 | J5: 0 | K5: 0 | L5: 0 | M5: 0 | N5: 0 | O5: 0
B6: ANJE 3 | C6: 1 | D6: 1 | E6: 1 | F6: 1 | G6: 1 | H6: 0 | I6: 0 | J6: 0 | K6: 0 | L6: 0 | M6: 0 | N6: 0 | O6: 0
B7: Soins maternals kangourou | C7: 1 | D7: 1 | E7: 0 | F7: 0 | G7: 0 | H7: 0 | I7: 0 | J7: 0 | K7: 0 | L7: 0 | M7: 0 | N7: 0 | O7: 0
B8: Supplémentation en nutriments à base de lipides | C8: 0 | D8: 0 | E8: 1 | F8: 1 | G8: 0 | H8: 0 | I8: 0 | J8: 0 | K8: 0 | L8: 0 | M8: 0 | N8: 0 | O8: 0
B9: Poudres de micronutriments | C9: 0 | D9: 0 | E9: 1 | F9: 1 | G9: 1 | H9: 0 | I9: 0 | J9: 0 | K9: 0 | L9: 0 | M9: 0 | N9: 0 | O9: 0
B10: Sels de réhydratation orale | C10: 1 | D10: 1 | E10: 1 | F10: 1 | G10: 1 | H10: 0 | I10: 0 | J10: 0 | K10: 0 | L10: 0 | M10: 0 | N10: 0 | O10: 0
B11: Fourniture publique d'aliments complémentaires | C11: 0 | D11: 0 | E11: 1 | F11: 1 | G11: 0 | H11: 0 | I11: 0 | J11: 0 | K11: 0 | L11: 0 | M11: 0 | N11: 0 | O11: 0
B12: Petite quantité de supplémentation en nutriments à base de lipides | C12: 0 | D12: 0 | E12: 1 | F12: 1 | G12: 0 | H12: 0 | I12: 0 | J12: 0 | K12: 0 | L12: 0 | M12: 0 | N12: 0 | O12: 0
B13: Traitement de la MAS | C13: 0 | D13: 1 | E13: 1 | F13: 1 | G13: 1 | H13: 0 | I13: 0 | J13: 0 | K13: 0 | L13: 0 | M13: 0 | N13: 0 | O13: 0
B14: Supplémentation en vitamine A | C14: 0 | D14: 0 | E14: 1 | F14: 1 | G14: 1 | H14: 0 | I14: 0 | J14: 0 | K14: 0 | L14: 0 | M14: 0 | N14: 0 | O14: 0
... B16: Supplémentation en zinc | C16: 0 | D16: 0 | E16: 1 | F16: 1 | G16: 1 | H16: 0 | I16: 0 | J16: 0 | K16: 0 | L16: 0 | M16: 0 | N16: 0 | O16: 0
A18: Femmes enceintes | B18: Supplémentation équilibrée en énergie et en protéines | C18: 0 | D18: 0 | E18: 0 | F18: 0 | G18: 0 | H18: 1 | I18: 1 | J18: 1 | K18: 1 | L18: 0 | M18: 0 | N18: 0 | O18: 0
B19: Supplémentation en calcium | C19: 0 | D19: 0 | E19: 0 | F19: 0 | G19: 0 | H19: 1 | I19: 1 | J19: 1 | K19: 1 | L19: 0 | M19: 0 | N19: 0 | O19: 0
B20: SFAF pour les femmes enceintes (communautaire) | C20: 0 | D20: 0 | E20: 0 | F20: 0 | G20: 0 | H20: 1 | I20: 1 | J20: 1 | K20: 1 | L20: 0 | M20: 0 | N20: 0 | O20: 0
B21: SFAF pour les femmes enceintes (établissement de santé) | C21: 0 | D21: 0 | E21: 0 | F21: 0 | G21: 0 | H21: 1 | I21: 1 | J21: 1 | K21: 1 | L21: 0 | M21: 0 | N21: 0 | O21: 0
B22: TPIg | C22: 0 | D22: 0 | E22: 0 | F22: 0 | G22: 0 | H22: 1 | I22: 1 | J22: 1 | K22: 1 | L22: 0 | M22: 0 | N22: 0 | O22: 0
B23: Mg pour l'éclampsie | C23: 0 | D23: 0 | E23: 0 | F23: 0 | G23: 0 | H23: 1 | I23: 1 | J23: 1 | K23: 1 | L23: 0 | M23: 0 | N23: 0 | O23: 0
B24: Mg pour la pré-éclampsie | C24: 0 | D24: 0 | E24: 0 | F24: 0 | G24: 0 | H24: 1 | I24: 1 | J24: 1 | K24: 1 | L24: 0 | M24: 0 | N24: 0 | O24: 0
B25: Supplémentation en micronutriments multiples | C25: 0 | D25: 0 | E25: 0 | F25: 0 | G25: 0 | H25: 1 | I25: 1 | J25: 1 | K25: 1 | L25: 0 | M25: 0 | N25: 0 | O25: 0
A27: FAP non enceintes | B27: Planification familiale | C27: 0 | D27: 0 | E27: 0 | F27: 0 | G27: 0 | H27: 0 | I27: 0 | J27: 0 | K27: 0 | L27: 1 | M27: 0 | N27: 0 | O27: 0
B28: SFAF (communautaire) | C28: 0 | D28: 0 | E28: 0 | F28: 0 | G28: 0 | H28: 0 | I28: 0 | J28: 0 | K28: 0 | L28: 1 | M28: 1 | N28: 1 | O28: 1
B29: SFAF (établissement de santé) | C29: 0 | D29: 0 | E29: 0 | F29: 0 | G29: 0 | H29: 0 | I29: 0 | J29: 0 | K29: 0 | L29: 1 | M29: 1 | N29: 1 | O29: 1
B30: SFAF (détaillant) | C30: 0 | D30: 0 | E30: 0 | F30: 0 | G30: 0 | H30: 0 | I30: 0 | J30: 0 | K30: 0 | L30: 1 | M30: 1 | N30: 1 | O30: 1
B31: SFAF (école) | C31: 0 | D31: 0 | E31: 0 | F31: 0 | G31: 0 | H31: 0 | I31: 0 | J31: 0 | K31: 0 | L31: 1 | M31: 0 | N31: 0 | O31: 0
A33: Population générale | B33: Enrichissement du maïs en FAF | C33: 1 | D33: 0 | E33: 1 | F33: 1 | G33: 1 | H33: 1 | I33: 1 | J33: 1 | K33: 1 | L33: 1 | M33: 1 | N33: 1 | O33: 1
B34: Enrichissement du riz en FAF | C34: 1 | D34: 0 | E34: 1 | F34: 1 | G34: 1 | H34: 1 | I34: 1 | J34: 1 | K34: 1 | L34: 1 | M34: 1 | N34: 1 | O34: 1
B35: Enrichissement en FAF de la farine de blé | C35: 1 | D35: 0 | E35: 1 | F35: 1 | G35: 1 | H35: 1 | I35: 1 | J35: 1 | K35: 1 | L35: 1 | M35: 1 | N35: 1 | O35: 1
B36: Enrichissement du sel en fer et en iode | C36: 1 | D36: 0 | E36: 1 | F36: 1 | G36: 1 | H36: 1 | I36: 1 | J36: 1 | K36: 1 | L36: 1 | M36: 1 | N36: 1 | O36: 1
B37: Moustiquaires imprégnées d'insecticide de longue durée | C37: 1 | D37: 1 | E37: 1 | F37: 1 | G37: 1 | H37: 1 | I37: 1 | J37: 1 | K37: 1 | L37: 1 | M37: 1 | N37: 1 | O37: 1
B38: WASH: lavage des mains | C38: 1 | D38: 1 | E38: 1 | F38: 1 | G38: 1 | H38: 1 | I38: 1 | J38: 1 | K38: 1 | L38: 1 | M38: 1 | N38: 1 | O38: 1
B39: WASH: Élimination hygiénique | C39: 1 | D39: 1 | E39: 1 | F39: 1 | G39: 1 | H39: 1 | I39: 1 | J39: 1 | K39: 1 | L39: 1 | M39: 1 | N39: 1 | O39: 1
B40: WASH: Amélioration de l'assainissement | C40: 1 | D40: 1 | E40: 1 | F40: 1 | G40: 1 | H40: 1 | I40: 1 | J40: 1 | K40: 1 | L40: 1 | M40: 1 | N40: 1 | O40: 1
B41: WASH: Source d'eau améliorée | C41: 1 | D41: 1 | E41: 1 | F41: 1 | G41: 1 | H41: 1 | I41: 1 | J41: 1 | K41: 1 | L41: 1 | M41: 1 | N41: 1 | O41: 1
B42: WASH: Eau courante | C42: 1 | D42: 1 | E42: 1 | F42: 1 | G42: 1 | H42: 1 | I42: 1 | J42: 1 | K42: 1 | L42: 1 | M42: 1 | N42: 1 | O42: 1

Sheet Programme - secteurs à risque
A1: Programme | B1: Retard de croissance | C1: Anémie | D1: Prévention de l'émaciation | E1: Traitement de l'émaciation | F1: Allaitement maternel | G1: Diarrhée | H1: Mortalité | I1: Résultats des naissances | J1: Espacement des naissances | K1: Nombre de naissances
A2: Supplémentation équilibrée en énergie et en protéines | I2: x
A3: Supplémentation en calcium | H3: x
A4: Transferts monétaires | D4: x
A5: Clampage tardif du cordon | C5: x
A6: Planification familiale | J6: x | K6: x
A7: Enrichissement du maïs en FAF | C7: x | H7: x
A8: Enrichissement du riz en FAF | C8: x | H8: x
A9: Enrichissement en FAF de la farine de blé | C9: x | H9: x
A10: SFAF (communautaire) | C10: x
A11: SFAF (établissement de santé) | C11: x
A12: SFAF (détaillant) | C12: x
A13: SFAF (école) | C13: x
A14: SFAF pour les femmes enceintes (communautaire) | C14: x | I14: x
A15: SFAF pour les femmes enceintes (établissement de santé) | C15: x | I15: x
A16: TPIg | C16: x | H16: x | I16: x
A17: Enrichissement du sel en fer et en iode | C17: x
A18: ANJE 1 | B18: x | F18: x
A19: ANJE 2 | B19: x | F19: x
A20: ANJE 3 | B20: x | F20: x
A21: Soins maternals kangourou | H21: x | I21: x
A22: Supplémentation en nutriments à base de lipides | B22: x | C22: x | D22: x
A23: Moustiquaires imprégnées d'insecticide de longue durée | C23: x | I23: x
A24: Mg pour l'éclampsie | H24: x
A25: Mg pour la pré-éclampsie | H25: x
A26: Poudres de micronutriments | C26: x
A27: Supplémentation en micronutriments multiples | C27: x | I27: x
A28: Sels de réhydratation orale | H28: x
A29: Fourniture publique d'aliments complémentaires | B29: x | D29: x
A30: Petite quantité de supplémentation en nutriments à base de lipides | B30: x | C30: x | D30: x
A31: Traitement de la MAS | E31: x
A32: Supplémentation en vitamine A | G32: x | H32: x
A33: WASH: lavage des mains | G33: x | H33: x
A34: WASH: Élimination hygiénique | G34: x | H34: x
A35: WASH: Amélioration de l'assainissement | G35: x | H35: x
A36: WASH: Source d'eau améliorée | G36: x | H36: x
A37: WASH: Eau courante | G37: x | H37: x
A38: SRO+Zn pour le traitement de la diarrhée | H38: x
A39: Supplémentation en zinc | B39: x | G39: x | H39: x

Sheet Population des sect. à risque
A1: Tranche d'âge | B1: Retard de croissance | C1: Anémie | D1: Prévention de l'émaciation | E1: Traitement de l'émaciation | F1: Allaitement maternel | G1: Diarrhée | H1: Mortalité | I1: Résultats des naissances | J1: Espacement des naissances | K1: Nombre de naissances
A2: <1 mois | B2: x | C2: x | D2: x | E2: x | F2: x | G2: x | H2: x
A3: 1-5 mois | B3: x | C3: x | D3: x | E3: x | F3: x | G3: x | H3: x
A4: 6-11 mois | B4: x | C4: x | D4: x | E4: x | F4: x | G4: x | H4: x
A5: 12-23 mois | B5: x | C5: x | D5: x | E5: x | F5: x | G5: x | H5: x
A6: 24-59 mois | B6: x | C6: x | D6: x | E6: x | F6: x | G6: x | H6: x
A7: FE: 15-19 ans | C7: x | H7: x | I7: x
A8: FE: 20-29 ans | C8: x | H8: x | I8: x
A9: FE: 30-39 ans | C9: x | H9: x | I9: x
A10: FE: 40-49 ans | C10: x | H10: x | I10: x
A11: FAP: 15-19 ans | C11: x | J11: x | K11: x
A12: FAP: 20-29 ans | C12: x | K12: x
A13: FAP: 30-39 ans | C13: x | K13: x
A14: FAP: 40-49 ans | C14: x | K14: x

Sheet Rapport des cotes ANJE
A1: Comportement | B1: Population cible | C1: Mode de livraison | D1: <1 mois | E1: 1-5 mois | F1: 6-11 mois | G1: 12-23 mois | H1: 24-59 mois
A2: Rapport des cotes pour l'allaitement maternelle correct | B2: Femmes enceintes | C2: Établissement de santé | D2: 1 | E2: 1 | F2: 1 | G2: 1 | H2: 1
C3: Communautaire | D3: 1 | E3: 1 | F3: 1 | G3: 1 | H3: 1
C4: Médias de masse | D4: 1 | E4: 1 | F4: 1 | G4: 1 | H4: 1
B5: <1 mois | C5: Établissement de santé | D5: 1.73 | E5: 1 | F5: 1 | G5: 1 | H5: 1
C6: Communautaire | D6: 1.73 | E6: 1 | F6: 1 | G6: 1 | H6: 1
C7: Médias de masse | D7: 1 | E7: 1 | F7: 1 | G7: 1 | H7: 1
B8: 1-5 mois | C8: Établissement de santé | D8: 1 | E8: 1.73 | F8: 1 | G8: 1 | H8: 1
C9: Communautaire | D9: 1 | E9: 1.73 | F9: 1 | G9: 1 | H9: 1
C10: Médias de masse | D10: 1 | E10: 1 | F10: 1 | G10: 1 | H10: 1
B11: 6-11 mois | C11: Établissement de santé | D11: 1 | E11: 1 | F11: 1.73 | G11: 1 | H11: 1
C12: Communautaire | D12: 1 | E12: 1 | F12: 1.73 | G12: 1 | H12: 1
C13: Médias de masse | D13: 1 | E13: 1 | F13: 1 | G13: 1 | H13: 1
B14: 12-23 mois | C14: Établissement de santé | D14: 1 | E14: 1 | F14: 1 | G14: 1.73 | H14: 1
C15: Communautaire | D15: 1 | E15: 1 | F15: 1 | G15: 1.73 | H15: 1
C16: Médias de masse | D16: 1 | E16: 1 | F16: 1 | G16: 1 | H16: 1
B17: Tous | C17: Médias de masse | D17: 1.05 | E17: 1.05 | F17: 1.05 | G17: 1.05 | H17: 1
A19: Rapport des cotes pour le retard de croissance | B19: Femmes enceintes | C19: Établissement de santé | D19: 1 | E19: 1 | F19: 1 | G19: 1 | H19: 1
C20: Communautaire | D20: 1 | E20: 1 | F20: 1 | G20: 1 | H20: 1
C21: Médias de masse | D21: 1 | E21: 1 | F21: 1 | G21: 1 | H21: 1
B22: <1 mois | C22: Établissement de santé | D22: 1 | E22: 1 | F22: 1 | G22: 1 | H22: 1
C23: Communautaire | D23: 1 | E23: 1 | F23: 1 | G23: 1 | H23: 1
C24: Médias de masse | D24: 1 | E24: 1 | F24: 1 | G24: 1 | H24: 1
B25: 1-5 mois | C25: Établissement de santé | D25: 1 | E25: 1 | F25: 1 | G25: 1 | H25: 1
C26: Communautaire | D26: 1 | E26: 1 | F26: 1 | G26: 1 | H26: 1
C27: Médias de masse | D27: 1 | E27: 1 | F27: 1 | G27: 1 | H27: 1
B28: 6-11 mois | C28: Établissement de santé | D28: 1 | E28: 1 | F28: 1 | G28: 1 | H28: 1
C29: Communautaire | D29: 1 | E29: 1 | F29: 1 | G29: 1 | H29: 1
C30: Médias de masse | D30: 1 | E30: 1 | F30: 1 | G30: 1 | H30: 1
B31: 12-23 mois | C31: Établissement de santé | D31: 1 | E31: 1 | F31: 1 | G31: 1 | H31: 1
C32: Communautaire | D32: 1 | E32: 1 | F32: 1 | G32: 1 | H32: 1
C33: Médias de masse | D33: 1 | E33: 1 | F33: 1 | G33: 1 | H33: 1
B34: Tous | C34: Médias de masse | D34: 1 | E34: 1 | F34: 1 | G34: 1 | H34: 1
A36: Rapport des cotes pour l'alimentation complémentaire | B36: Femmes enceintes | C36: Établissement de santé | D36: 1 | E36: 1 | F36: 1 | G36: 1 | H36: 1
C37: Communautaire | D37: 1 | E37: 1 | F37: 1 | G37: 1 | H37: 1
C38: Médias de masse | D38: 1 | E38: 1 | F38: 1 | G38: 1 | H38: 1
B39: <1 mois | C39: Établissement de santé | D39: 1 | E39: 1 | F39: 1 | G39: 1 | H39: 1
C40: Communautaire | D40: 1 | E40: 1 | F40: 1 | G40: 1 | H40: 1
C41: Médias de masse | D41: 1 | E41: 1 | F41: 1 | G41: 1 | H41: 1
B42: 1-5 mois | C42: Établissement de santé | D42: 1 | E42: 1 | F42: 1 | G42: 1 | H42: 1
...

Sheet Risques des rés. des naissances
A1: Facteurs de risque maternels contribuant aux résultats des naissances
C2: AGA à terme | D2: SGA à terme | E2: AGA prématuré | F2: SGA prématuré
A3: Risque relatif par espacement des naissances
B4: Première naissance | C4: 1 | D4: 1 | E4: 1 | F4: 1
B5: moins de 18 mois | C5: 1 | D5: 1.41 | E5: 1.49 | F5: 3.03
B6: 18 à 23 mois | C6: 1 | D6: 1.18 | E6: 1.1 | F6: 1.77
B7: 24 mois ou plus | C7: 1 | D7: 1 | E7: 1 | F7: 1
A9: Rapport des cotes pour les femmes avec l'anémie maternelle | C9: 1 | D9: 1.53 | E9: 1.32 | F9: 1.53
A11: Risques pour les enfants touchés par chaque résultat des naissances
A12: Rapport des cotes pour des conditions
B13: Émaciation (score-HAZ < -2) | C13: 1 | D13: 5 | E13: 6.4 | F13: 46.5
B14: MM (score WHZ entre -3 et -2) | C14: 1 | D14: 2.52 | E14: 1.96 | F14: 4.19
B15: MAS (score WHZ < -3) | C15: 1 | D15: 2.52 | E15: 1.96 | F15: 4.19
A17: Risques relatifs des causes du décès néonatales
B18: Diarrhée néonatale | C18: 1 | D18: 1 | E18: 1 | F18: 1
B19: Sepsis néonatal | C19: 1 | D19: 2.07 | E19: 3.39 | F19: 11.89
B20: Pneumonie néonatale | C20: 1 | D20: 2.07 | E20: 3.39 | F20: 11.89
B21: Asphyxie néonatale | C21: 1 | D21: 2.07 | E21: 3.39 | F21: 11.89
B22: Prématurité néonatale | C22: 1 | D22: 1 | E22: 999.99 | F22: 999.99
B23: Tétanos néonatal | C23: 1 | D23: 1 | E23: 1 | F23: 1
B24: Anomalies congénitales néonatales | C24: 1 | D24: 1 | E24: 1 | F24: 1
B25: Autres pathologies néonatales | C25: 1 | D25: 1 | E25: 1 | F25: 1
A27: Bornes inférieures
A28: Facteurs de risque maternels contribuant aux résultats des naissances
C29: AGA à terme | D29: SGA à terme | E29: AGA prématuré | F29: SGA prématuré
A30: Risque relatif par espacement des naissances - inférieur
B31: Première naissance | C31: =IF(C4=1,1,C4*0.9) -> 1 | D31: =IF(D4=1,1,D4*0.9) -> 1 | E31: =IF(E4=1,1,E4*0.9) -> 1 | F31: =IF(F4=1,1,F4*0.9) -> 1
B32: moins de 18 mois | C32: =IF(C5=1,1,C5*0.9) -> 1 | D32: =IF(D5=1,1,D5*0.9) -> 1.269 | E32: =IF(E5=1,1,E5*0.9) -> 1.341 | F32: =IF(F5=1,1,F5*0.9) -> 2.727
B33: 18 à 23 mois | C33: =IF(C6=1,1,C6*0.9) -> 1 | D33: =IF(D6=1,1,D6*0.9) -> 1.062 | E33: =IF(E6=1,1,E6*0.9) -> 0.99 | F33: =IF(F6=1,1,F6*0.9) -> 1.593
B34: 24 mois ou plus | C34: =IF(C7=1,1,C7*0.9) -> 1 | D34: =IF(D7=1,1,D7*0.9) -> 1 | E34: =IF(E7=1,1,E7*0.9) -> 1 | F34: =IF(F7=1,1,F7*0.9) -> 1
A36: Rapports des cotes pour les femmes avec l'anémie maternelle - inférieur | C36: =IF(C9=1,1,C9*0.9) -> 1 | D36: =IF(D9=1,1,D9*0.9) -> 1.377 | E36: =IF(E9=1,1,E9*0.9) -> 1.188 | F36: =IF(F9=1,1,F9*0.9) -> 1.377
A38: Risques pour les enfants touchés par chaque résultat des naissances
A39: Rapport des cotes pour des conditions - inférieur
B40: Retard de croissance (HAZ-score < -2)-i | C40: =IF(C13=1,1,C13*0.9) -> 1 | D40: =IF(D13=1,1,D13*0.9) -> 4.5 | E40: =IF(E13=1,1,E13*0.9) -> 5.76 | F40: =IF(F13=1,1,F13*0.9) -> 41.85
B41: MM (score WHZ entre -3 et -2)-i | C41: =IF(C14=1,1,C14*0.9) -> 1 | D41: =IF(D14=1,1,D14*0.9) -> 2.268 | E41: =IF(E14=1,1,E14*0.9) -> 1.764 | F41: =IF(F14=1,1,F14*0.9) -> 3.771
B42: MAS (score WHZ < -3)-i | C42: =IF(C15=1,1,C15*0.9) -> 1 | D42: =IF(D15=1,1,D15*0.9) -> 2.268 | E42: =IF(E15=1,1,E15*0.9) -> 1.764 | F42: =IF(F15=1,1,F15*0.9) -> 3.771
A44: Risques relatifs des causes du décès néonatales - inférieur
B45: Diarrhée néonatale | C45: =IF(C18=1,1,C18*0.9) -> 1 | D45: =IF(D18=1,1,D18*0.9) -> 1 | E45: =IF(E18=1,1,E18*0.9) -> 1 | F45: =IF(F18=1,1,F18*0.9) -> 1
B46: Sepsis néonatal | C46: =IF(C19=1,1,C19*0.9) -> 1 | D46: =IF(D19=1,1,D19*0.9) -> 1.863 | E46: =IF(E19=1,1,E19*0.9) -> 3.051 | F46: =IF(F19=1,1,F19*0.9) -> 10.701
B47: Pneumonie néonatale | C47: =IF(C20=1,1,C20*0.9) -> 1 | D47: =IF(D20=1,1,D20*0.9) -> 1.863 | E47: =IF(E20=1,1,E20*0.9) -> 3.051 | F47: =IF(F20=1,1,F20*0.9) -> 10.701
...

Sheet Risques relatifs
A1: Risque relatif des causes du décès par la distribution de la taille-pour-âge (retard de croissance)
A2: Retard de croissance | B2: Cause du décès | C2: Niveau HAZ | D2: <1 mois | E2: 1-5 mois | F2: 6-11 mois | G2: 12-23 mois | H2: 24-59 mois
B3: Diarrhée | C3: Normal | D3: 1 | E3: 1 | F3: 1 | G3: 1 | H3: 1
C4: Léger | D4: 1 | E4: 1.67 | F4: 1.67 | G4: 1.67 | H4: 1.67
C5: Modéré | D5: 1 | E5: 2.38 | F5: 2.38 | G5: 2.38 | H5: 2.38
C6: Élevé | D6: 1 | E6: 6.33 | F6: 6.33 | G6: 6.33 | H6: 6.33
B7: Pneumonie | C7: Normal | D7: 1 | E7: 1 | F7: 1 | G7: 1 | H7: 1
C8: Léger | D8: 1 | E8: 1.55 | F8: 1.55 | G8: 1.55 | H8: 1.55
C9: Modéré | D9: 1 | E9: 2.18 | F9: 2.18 | G9: 2.18 | H9: 2.18
C10: Élevé | D10: 1 | E10: 6.39 | F10: 6.39 | G10: 6.39 | H10: 6.39
B11: Rougeole | C11: Normal | D11: 1 | E11: 1 | F11: 1 | G11: 1 | H11: 1
C12: Léger | D12: 1 | E12: 1 | F12: 1 | G12: 1 | H12: 1
C13: Modéré | D13: 1 | E13: 2.79 | F13: 2.79 | G13: 2.79 | H13: 2.79
C14: Élevé | D14: 1 | E14: 6.01 | F14: 6.01 | G14: 6.01 | H14: 6.01
B15: Paludisme | C15: Normal | D15: 1 | E15: 1 | F15: 1 | G15: 1 | H15: 1
C16: Léger | D16: 1 | E16: 1 | F16: 1 | G16: 1 | H16: 1
C17: Modéré | D17: 1 | E17: 1 | F17: 1 | G17: 1 | H17: 1
C18: Élevé | D18: 1 | E18: 1 | F18: 1 | G18: 1 | H18: 1
B19: Méningite | C19: Normal | D19: 1 | E19: 1 | F19: 1 | G19: 1 | H19: 1
C20: Léger | D20: 1 | E20: 1 | F20: 1 | G20: 1 | H20: 1
C21: Modéré | D21: 1 | E21: 1.86 | F21: 1.86 | G21: 1.86 | H21: 1.86
C22: Élevé | D22: 1 | E22: 3.01 | F22: 3.01 | G22: 3.01 | H22: 3.01
B23: Autre | C23: Normal | D23: 1 | E23: 1 | F23: 1 | G23: 1 | H23: 1
C24: Léger | D24: 1 | E24: 1 | F24: 1 | G24: 1 | H24: 1
C25: Modéré | D25: 1 | E25: 1.86 | F25: 1.86 | G25: 1.86 | H25: 1.86
C26: Élevé | D26: 1 | E26: 3.01 | F26: 3.01 | G26: 3.01 | H26: 3.01
A28: Risque relatif des causes du décès par la distribution du poids-pour-taille (émaciation)
A29: Émaciation | B29: Cause du décès | C29: Niveau WHZ | D29: <1 mois | E29: 1-5 mois | F29: 6-11 mois | G29: 12-23 mois | H29: 24-59 mois
B30: Diarrhée | C30: Normal | D30: 1 | E30: 1 | F30: 1 | G30: 1 | H30: 1
C31: Léger | D31: 1 | E31: 1.6 | F31: 1.6 | G31: 1.6 | H31: 1.6
C32: MM | D32: 1 | E32: 3.41 | F32: 3.41 | G32: 3.41 | H32: 3.41
C33: MAS | D33: 1 | E33: 12.33 | F33: 12.33 | G33: 12.33 | H33: 12.33
B34: Pneumonie | C34: Normal | D34: 1 | E34: 1 | F34: 1 | G34: 1 | H34: 1
C35: Léger | D35: 1 | E35: 1.92 | F35: 1.92 | G35: 1.92 | H35: 1.92
C36: MM | D36: 1 | E36: 4.66 | F36: 4.66 | G36: 4.66 | H36: 4.66
C37: MAS | D37: 1 | E37: 9.68 | F37: 9.68 | G37: 9.68 | H37: 9.68
B38: Rougeole | C38: Normal | D38: 1 | E38: 1 | F38: 1 | G38: 1 | H38: 1
C39: Léger | D39: 1 | E39: 1 | F39: 1 | G39: 1 | H39: 1
C40: MM | D40: 1 | E40: 2.58 | F40: 2.58 | G40: 2.58 | H40: 2.58
C41: MAS | D41: 1 | E41: 9.63 | F41: 9.63 | G41: 9.63 | H41: 9.63
...

Sheet Rapports des cotes
A1: Rapport des cotes pour le retard de croissance
A2: Condition | C2: <1 mois | D2: 1-5 mois | E2: 6-11 mois | F2: 12-23 mois | G2: 24-59 mois
B3: Compte tenu du retard de croissance antérieur (HAZ < -2 dans la tranche d’âge précédente) | C3: N/A | D3: 45 | E3: 361.6 | F3: 174.7 | G3: 174.7
B4: Diarrhée (par épisode supplémentaire) | C4: 1.025 | D4: 1.025 | E4: 1.025 | F4: 1.025 | G4: 1.025
A5: Par programme
B6: Fourniture publique d'aliments complémentaires | C6: 1 | D6: 1 | E6: 0.89 | F6: 0.89 | G6: 1
B7: Supplémentation en nutriments à base de lipides | C7: 1 | D7: 1 | E7: 0.88 | F7: 0.88 | G7: 1
B8: Petite quantité de supplémentation en nutriments à base de lipides | C8: 1 | D8: 1 | E8: 0.88 | F8: 0.88 | G8: 1
B9: Supplémentation en zinc | C9: 1 | D9: 1 | E9: 1 | F9: 1 | G9: 1
A11: Rapport des cotes pour l'allaitement maternel correct par programme
B12: Soins maternals kangourou | C12: 1.5 | D12: 1.39 | E12: 1 | F12: 1 | G12: 1
A14: Rapports des cotes supplémentaires
A15: Émaciation | B15: Pour MAS par épisode supplémentaire de la diarrhée | C15: 1.025 | D15: 1.025 | E15: 1.025 | F15: 1.025 | G15: 1.025
B16: Pour MM par épisode supplémentaire de la diarrhée | C16: 1.025 | D16: 1.025 | E16: 1.025 | F16: 1.025 | G16: 1.025
A17: Anémie | B17: Pour l'anémie par épisode supplémentaire de la diarrhée aiguë | C17: 1 | D17: 1 | E17: 1 | F17: 1 | G17: 1
A19: Rapports des cotes pour l'espacement des naissances optimal par programme
C20: FAP: 15-19 ans | D20: FAP: 20-29 ans | E20: FAP: 30-39 ans | F20: FAP: 40-49 ans
B21: Planification familiale | C21: 1.52 | D21: 1 | E21: 1 | F21: 1
A23: Bornes inférieures
A24: Rapport des cotes pour le retard de croissance
A25: Condition | C25: <1 mois | D25: 1-5 mois | E25: 6-11 mois | F25: 12-23 mois | G25: 24-59 mois
B26: Compte tenu du retard de croissance antérieur (HAZ < -2 dans la tranche d’âge précédente) - inférieur | C26: N/A | D26: =D3*0.9 -> 40.5 | E26: =E3*0.9 -> 325.44 | F26: =F3*0.9 -> 157.23 | G26: =G3*0.9 -> 157.23
B27: Diarrhée (par épisode supplémentaire) - inférieur | C27: =IF(C4=1,1,C4*0.9) -> 0.9225 | D27: =IF(D4=1,1,D4*0.9) -> 0.9225 | E27: =IF(E4=1,1,E4*0.9) -> 0.9225 | F27: =IF(F4=1,1,F4*0.9) -> 0.9225 | G27: =IF(G4=1,1,G4*0.9) -> 0.9225
A28: Par programme - inférieur
B29: Fourniture publique d'aliments complémentaires - inférieur | C29: =IF(C6=1,1,C6*0.9) -> 1 | D29: =IF(D6=1,1,D6*0.9) -> 1 | E29: =E6*0.9 -> 0.801 | F29: =F6*0.9 -> 0.801 | G29: =IF(G6=1,1,G6*0.9) -> 1
B30: Supplémentation en nutriments à base de lipids - inférieur | C30: =IF(C7=1,1,C7*0.9) -> 1 | D30: =IF(D7=1,1,D7*0.9) -> 1 | E30: 0.85 | F30: 0.85 | G30: =IF(G7=1,1,G7*0.9) -> 1
B31: Petite quantité de supplémentation en nutriments à base de lipids - inférieur | C31: =IF(C8=1,1,C8*0.9) -> 1 | D31: =IF(D8=1,1,D8*0.9) -> 1 | E31: 0.85 | F31: 0.85 | G31: =IF(G8=1,1,G8*0.9) -> 1
B32: Supplémentation en zinc - inférieur | C32: =IF(C9=1,1,C9*0.9) -> 1 | D32: =IF(D9=1,1,D9*0.9) -> 1 | E32: =IF(E9=1,1,E9*0.9) -> 1 | F32: =IF(F9=1,1,F9*0.9) -> 1 | G32: =IF(G9=1,1,G9*0.9) -> 1
A34: Rapport des cotes pour l'allaitement correct par programme - inférieur
B35: Soins maternals kangourou - inférieur | C35: 1.26 | D35: 1.11 | E35: 1 | F35: 1 | G35: 1
A37: Rapports des cotes supplémentaires
A38: Émaciation | B38: Pour MAS par épisode supplémentaire de la diarrhée - inférieur | C38: =IF(C15=1,1,C15*0.9) -> 0.9225 | D38: =IF(D15=1,1,D15*0.9) -> 0.9225 | E38: =IF(E15=1,1,E15*0.9) -> 0.9225 | F38: =IF(F15=1,1,F15*0.9) -> 0.9225 | G38: =IF(G15=1,1,G15*0.9) -> 0.9225
B39: Pour MM par épisode supplémentaire de la diarrhée - inférieur | C39: =IF(C16=1,1,C16*0.9) -> 0.9225 | D39: =IF(D16=1,1,D16*0.9) -> 0.9225 | E39: =IF(E16=1,1,E16*0.9) -> 0.9225 | F39: =IF(F16=1,1,F16*0.9) -> 0.9225 | G39: =IF(G16=1,1,G16*0.9) -> 0.9225
A40: Anémie | B40: Pour l'anémie par épisode supplémentaire de la diarrhée aiguë - inférieur | C40: =IF(C17=1,1,C17*0.9) -> 1 | D40: =IF(D17=1,1,D17*0.9) -> 1 | E40: =IF(E17=1,1,E17*0.9) -> 1 | F40: =IF(F17=1,1,F17*0.9) -> 1 | G40: =IF(G17=1,1,G17*0.9) -> 1
A42: Rapports des cotes pour l'espacement des naissances optimal par programme - inférieur
C43: FAP: 15-19 ans | D43: FAP: 20-29 ans | E43: FAP: 30-39 ans | F43: FAP: 40-49 ans
B44: Planification familiale - inférieur | C44: =C21*0.9 -> 1.368 | D44: 1 | E44: 1 | F44: 1
A46: Bornes supérieures
A47: Rapport des cotes pour le retard de croissance
A48: Condition | C48: <1 mois | D48: 1-5 mois | E48: 6-11 mois | F48: 12-23 mois | G48: 24-59 mois
...

Sheet Programmes-rés. des naissances
A1: Programme | C1: SGA prématuré | D1: SGA à terme | E1: AGA prématuré | F1: AGA à terme
A2: Supplémentation équilibrée en énergie et en protéines | B2: efficacité | C2: 0.29 | D2: 0.29 | E2: 0 | F2: 0
B3: fraction touchée | C3: 1 | D3: 1 | E3: 1 | F3: 1
A4: SFAF pour les femmes enceintes (communautaire) | B4: efficacité | C4: 0.61 | D4: 0.61 | E4: 0 | F4: 0
B5: fraction touchée | C5: 1 | D5: 1 | E5: 1 | F5: 1
A6: SFAF pour les femmes enceintes (établissement de santé) | B6: efficacité | C6: 0.61 | D6: 0.61 | E6: 0 | F6: 0
B7: fraction touchée | C7: 1 | D7: 1 | E7: 1 | F7: 1
A8: TPIg | B8: efficacité | C8: 0.35 | D8: 0.35 | E8: 0 | F8: 0
B9: fraction touchée | C9: 1 | D9: 1 | E9: 0 | F9: 0
A10: Moustiquaires imprégnées d'insecticide de longue durée | B10: efficacité | C10: 0.35 | D10: 0.35 | E10: 0 | F10: 0
B11: fraction touchée | C11: 1 | D11: 1 | E11: 0 | F11: 0
A12: Supplémentation en micronutriments multiples | B12: efficacité | C12: =1-0.93*0.39 -> 0.6373 | D12: =1-0.93*0.39 -> 0.6373 | E12: 0 | F12: 0
B13: fraction touchée | C13: 1 | D13: 1 | E13: 1 | F13: 1
A15: Bornes inférieures
A16: Programme | C16: SGA prématuré | D16: SGA à terme | E16: AGA prématuré | F16: AGA à terme
A17: Supplémentation équilibrée en énergie et en protéines | B17: efficacité | C17: =1-0.94 -> 0.06 | D17: =1-0.94 -> 0.06 | E17: =E2*0.9 -> 0 | F17: =F2*0.9 -> 0
B18: fraction touchée | C18: 1 | D18: 1 | E18: 1 | F18: 1
A19: SFAF pour les femmes enceintes (communautaire) | B19: efficacité | C19: =1-0.86 -> 0.14 | D19: =1-0.86 -> 0.14 | E19: =E4*0.9 -> 0 | F19: =F4*0.9 -> 0
B20: fraction touchée | C20: 1 | D20: 1 | E20: 1 | F20: 1
A21: SFAF pour les femmes enceintes (établissement de santé) | B21: efficacité | C21: =1-0.86 -> 0.14 | D21: =1-0.86 -> 0.14 | E21: =E6*0.9 -> 0 | F21: =F6*0.9 -> 0
B22: fraction touchée | C22: 1 | D22: 1 | E22: 1 | F22: 1
A23: TPIg | B23: efficacité | C23: =1-0.77 -> 0.23 | D23: =1-0.77 -> 0.23 | E23: =E10*0.9 -> 0 | F23: =F10*0.9 -> 0
B24: fraction touchée | C24: 1 | D24: 1 | E24: 1 | F24: 1
A25: Moustiquaires imprégnées d'insecticide de longue durée | B25: efficacité | C25: =1-0.77 -> 0.23 | D25: =1-0.77 -> 0.23 | E25: =E10*0.9 -> 0 | F25: =F10*0.9 -> 0
B26: fraction touchée | C26: 1 | D26: 1 | E26: 1 | F26: 1
A27: Supplémentation en micronutriments multiples | B27: efficacité | C27: =1-0.98*0.86 -> 0.1572 | D27: =1-0.98*0.86 -> 0.1572 | E27: =E12*0.9 -> 0 | F27: =F12*0.9 -> 0
B28: fraction touchée | C28: 1 | D28: 1 | E28: 1 | F28: 1
A30: Bornes supérieures
A31: Programme | C31: SGA prématuré | D31: SGA à terme | E31: AGA prématuré | F31: AGA à terme
A32: Supplémentation équilibrée en énergie et en protéines | B32: efficacité | C32: =1-0.54 -> 0.46 | D32: =1-0.54 -> 0.46 | E32: =E2*1.1 -> 0 | F32: =F2*1.1 -> 0
B33: fraction touchée | C33: 1 | D33: 1 | E33: 1 | F33: 1
A34: SFAF pour les femmes enceintes (communautaire) | B34: efficacité | C34: =1-0.17 -> 0.83 | D34: =1-0.17 -> 0.83 | E34: =E4*1.1 -> 0 | F34: =F4*1.1 -> 0
B35: fraction touchée | C35: 1 | D35: 1 | E35: 1 | F35: 1
A36: SFAF pour les femmes enceintes (établissement de santé) | B36: efficacité | C36: =1-0.17 -> 0.83 | D36: =1-0.17 -> 0.83 | E36: =E6*1.1 -> 0 | F36: =F6*1.1 -> 0
B37: fraction touchée | C37: 1 | D37: 1 | E37: 1 | F37: 1
A38: TPIg | B38: efficacité | C38: =1-0.55 -> 0.45 | D38: =1-0.55 -> 0.45 | E38: =E8*1.1 -> 0 | F38: =F8*1.1 -> 0
B39: fraction touchée | C39: 1 | D39: 1 | E39: 1 | F39: 1
A40: Moustiquaires imprégnées d'insecticide de longue durée | B40: efficacité | C40: =1-0.55 -> 0.45 | D40: =1-0.55 -> 0.45 | E40: =E10*1.1 -> 0 | F40: =F10*1.1 -> 0
B41: fraction touchée | C41: 1 | D41: 1 | E41: 1 | F41: 1
A42: Supplémentation en micronutriments multiples | B42: efficacité | C42: =1-0.88*0.17 -> 0.8504 | D42: =1-0.88*0.17 -> 0.8504 | E42: =E12*1.1 -> 0 | F42: =F12*1.1 -> 0
...

Sheet Programmes-anémie
