Workbook
Name abortion: 'Baseline year population inputs'!$C$38
Name abortion: 'Baseline year population inputs'!$C$41
Name comm_deliv: 'Treatment of SAM'!$D$3
Name diarrhoea_1_5mo: 'Baseline year population inputs'!$C$52
Name diarrhoea_12_23mo: 'Baseline year population inputs'!$C$54
Name diarrhoea_1mo: 'Baseline year population inputs'!$C$51
Name diarrhoea_24_59mo: 'Baseline year population inputs'!$C$55
Name diarrhoea_6_11mo: 'Baseline year population inputs'!$C$53
Name end_year: 'Baseline year population inputs'!$C$4
Name famplan_unmet_need: 'Baseline year population inputs'!$C$13
Name food_insecure: 'Baseline year population inputs'!$C$8
Name frac_children_health_facility: 'Baseline year population inputs'!$C$12
Name frac_diarrhea_severe: 'Baseline year population inputs'!$C$58
Name frac_maize: 'Baseline year population inputs'!$C$19
Name frac_malaria_risk: 'Baseline year population inputs'!$C$9
Name frac_mam_1_5months: 'Nutritional status distribution'!$D$10
Name frac_mam_12_23months: 'Nutritional status distribution'!$F$10
Name frac_mam_1month: 'Nutritional status distribution'!$C$10
Name frac_mam_24_59months: 'Nutritional status distribution'!$G$10
Name frac_mam_6_11months: 'Nutritional status distribution'!$E$10
Name frac_MAMtoSAM: 'Baseline year population inputs'!#REF!
Name frac_other_staples: 'Baseline year population inputs'!$C$20
Name frac_PW_health_facility: 'Baseline year population inputs'!$C$11
Name frac_rice: 'Baseline year population inputs'!$C$17
Name frac_sam_1_5months: 'Nutritional status distribution'!$D$11
Name frac_sam_12_23months: 'Nutritional status distribution'!$F$11
Name frac_sam_1month: 'Nutritional status distribution'!$C$11
Name frac_sam_24_59months: 'Nutritional status distribution'!$G$11
Name frac_sam_6_11months: 'Nutritional status distribution'!$E$11
Name frac_SAMtoMAM: 'Baseline year population inputs'!#REF!
Name frac_subsistence_farming: 'Baseline year population inputs'!$C$16
Name frac_wheat: 'Baseline year population inputs'!$C$18
Name infant_mortality: 'Baseline year population inputs'!$C$38
Name iron_deficiency_anaemia: 'Baseline year population inputs'!$C$59
Name manage_mam: 'Treatment of SAM'!$D$2
Name maternal_mortality: 'Baseline year population inputs'!$C$40
Name neonatal_mortality: 'Baseline year population inputs'!$C$37
Name Percentage_of_pregnant_women_attending_health_facility: 'Baseline year population inputs'!$C$11
Name preterm_AGA: 'Baseline year population inputs'!$C$46
Name preterm_SGA: 'Baseline year population inputs'!$C$45
Name school_attendance: 'Baseline year population inputs'!$C$10
Name start_year: 'Baseline year population inputs'!$C$3
Name stillbirth: 'Baseline year population inputs'!$C$39
Name stillbirth: 'Baseline year population inputs'!$C$42
Name term_AGA: 'Baseline year population inputs'!$C$48
Name term_SGA: 'Baseline year population inputs'!$C$47
Name U5_mortality: 'Baseline year population inputs'!$C$39

Sheet Baseline year population inputs
A1: Baseline year data | B1: Field | C1: Data
A2: Projection years
B3: Baseline year (projection start year) | C3: 2024
B4: End year | C4: 2035
A6: Population data
B7: Children under 5 population | C7: 1323554.8
B8: Percentage of population food insecure (default poor) | C8: 0.498
B9: Percentage of population at risk of malaria | C9: 1
B10: School attendance (percentage of 15-19 year women) | C10: 0.33364899
B11: Percentage of pregnant women attending health facility | C11: 1
B12: Percentage of children attending health facility | C12: 1
B13: Unmet need for family planning | C13: 0.679
A15: Food
B16: Fraction of subsistence farming | C16: 0.1
B17: Fraction eating rice as main staple food | C17: 0.7
B18: Fraction eating wheat as main staple food | C18: 0.05
B19: Fraction eating maize as main staple food | C19: 0.05
B20: Fraction on other staples as main staple food | C20: =1-frac_rice-frac_wheat-frac_maize -> 0.2
A22: Age distribution of pregnant women
B23: Percentage of pregnant women 15-19 years | C23: 0.1015
B24: Percentage of pregnant women 20-29 years | C24: 0.4874
B25: Percentage of pregnant women 30-39 years | C25: 0.3307
B26: Percentage of pregnant women 40-49 years | C26: 0.0804
A28: Birth spacing
B29: First birth | C29: 0.23555809
B30: less than 18 months | C30: 0.034184984
B31: 18-23 months | C31: 0.068897622
B32: 24 months or greater | C32: 0.6613593
B33: Total (must be 100%) | C33: =SUM(C29:C32) -> 1
A35: Baseline year mortality and risk factors
A36: Mortality
B37: Neonatal mortality (per 1,000 live births) | C37: 24.0424
B38: Infant mortality (per 1,000 live births) | C38: 43.35671
B39: Under 5 mortality (per 1,000 live births) | C39: 62.60445
B40: Maternal mortality (per 1,000 live births) | C40: 3.99
B41: Fraction of pregnancies ending in spontaneous abortion | C41: 0.12
B42: Stillbirths (per 1,000 total births) | C42: 20.87259
A44: Birth outcome distribution
B45: Pre-term SGA | C45: 0.007938
B46: Pre-term AGA | C46: 0.0852926
...

Sheet Demographic projections
A1: year | B1: Number of births | C1: WRA: 15-19 years | D1: WRA: 20-29 years | E1: WRA: 30-39 years | F1: WRA: 40-49 years | G1: Total WRA | H1: Estimated pregnant women | I1: non-pregnant WRA
A2: =start_year -> 2024 | B2: 284756.23 | C2: 499000 | D2: 777000 | E2: 6300 | F2: 5500 | G2: =C2+D2+E2+F2 -> 1287800 | H2: =(B2 + stillbirth*B2/(1000-stillbirth))/(1-abortion) -> 330484.69 | I2: =G2-H2 -> 957315.31
A3: =IF($A$2+ROW(A3)-2<=end_year,A2+1,"") -> 2025 | B3: 288193.05 | C3: 510000 | D3: 802000 | E3: 6400 | F3: 5500 | G3: =C3+D3+E3+F3 -> 1323900 | H3: =(B3 + stillbirth*B3/(1000-stillbirth))/(1-abortion) -> 334473.43 | I3: =G3-H3 -> 989426.57
A4: =IF($A$2+ROW(A4)-2<=end_year,A3+1,"") -> 2026 | B4: 292184.2 | C4: 520000 | D4: 827000 | E4: 6600 | F4: 5400 | G4: =C4+D4+E4+F4 -> 1359000 | H4: =(B4 + stillbirth*B4/(1000-stillbirth))/(1-abortion) -> 339105.51 | I4: =G4-H4 -> 1019894.5
A5: =IF($A$2+ROW(A5)-2<=end_year,A4+1,"") -> 2027 | B5: 296151.69 | C5: 529000 | D5: 854000 | E5: 6900 | F5: 5300 | G5: =C5+D5+E5+F5 -> 1395200 | H5: =(B5 + stillbirth*B5/(1000-stillbirth))/(1-abortion) -> 343710.13 | I5: =G5-H5 -> 1051489.9
A6: =IF($A$2+ROW(A6)-2<=end_year,A5+1,"") -> 2028 | B6: 300063.29 | C6: 537000 | D6: 881000 | E6: 7200 | F6: 5200 | G6: =C6+D6+E6+F6 -> 1430400 | H6: =(B6 + stillbirth*B6/(1000-stillbirth))/(1-abortion) -> 348249.89 | I6: =G6-H6 -> 1082150.1
A7: =IF($A$2+ROW(A7)-2<=end_year,A6+1,"") -> 2029 | B7: 303946.97 | C7: 545000 | D7: 907000 | E7: 7500 | F7: 5100 | G7: =C7+D7+E7+F7 -> 1464600 | H7: =(B7 + stillbirth*B7/(1000-stillbirth))/(1-abortion) -> 352757.24 | I7: =G7-H7 -> 1111842.8
A8: =IF($A$2+ROW(A8)-2<=end_year,A7+1,"") -> 2030 | B8: 307771.04 | C8: 553000 | D8: 932000 | E8: 7700 | F8: 5000 | G8: =C8+D8+E8+F8 -> 1497700 | H8: =(B8 + stillbirth*B8/(1000-stillbirth))/(1-abortion) -> 357195.42 | I8: =G8-H8 -> 1140504.6
A9: =IF($A$2+ROW(A9)-2<=end_year,A8+1,"") -> 2031 | B9: 311058.87 | C9: 560714.29 | D9: 954142.86 | E9: 7900 | F9: 4928.5714 | G9: =C9+D9+E9+F9 -> 1527685.7 | H9: =(B9 + stillbirth*B9/(1000-stillbirth))/(1-abortion) -> 361011.23 | I9: =G9-H9 -> 1166674.5
A10: =IF($A$2+ROW(A10)-2<=end_year,A9+1,"") -> 2032 | B10: 314325.42 | C10: 567959.18 | D10: 975877.55 | E10: 8114.2857 | F10: 4846.9388 | G10: =C10+D10+E10+F10 -> 1556798 | H10: =(B10 + stillbirth*B10/(1000-stillbirth))/(1-abortion) -> 364802.35 | I10: =G10-H10 -> 1191995.6
A11: =IF($A$2+ROW(A11)-2<=end_year,A10+1,"") -> 2033 | B11: 317488.45 | C11: 574810.5 | D11: 997145.77 | E11: 8330.6122 | F11: 4767.93 | G11: =C11+D11+E11+F11 -> 1585054.8 | H11: =(B11 + stillbirth*B11/(1000-stillbirth))/(1-abortion) -> 368473.32 | I11: =G11-H11 -> 1216581.5
A12: =IF($A$2+ROW(A12)-2<=end_year,A11+1,"") -> 2034 | B12: 320536.56 | C12: 581354.85 | D12: 1017595.2 | E12: 8534.9854 | F12: 4691.92 | G12: =C12+D12+E12+F12 -> 1612176.9 | H12: =(B12 + stillbirth*B12/(1000-stillbirth))/(1-abortion) -> 372010.92 | I12: =G12-H12 -> 1240166
A13: =IF($A$2+ROW(A13)-2<=end_year,A12+1,"") -> 2035 | B13: 323461.32 | C13: 587691.26 | D13: 1037108.8 | E13: 8725.6976 | F13: 4619.3372 | G13: =C13+D13+E13+F13 -> 1638145.1 | H13: =(B13 + stillbirth*B13/(1000-stillbirth))/(1-abortion) -> 375405.36 | I13: =G13-H13 -> 1262739.7
A14: =IF($A$2+ROW(A14)-2<=end_year,A13+1,"")
A15: =IF($A$2+ROW(A15)-2<=end_year,A14+1,"")
A16: =IF($A$2+ROW(A16)-2<=end_year,A15+1,"")
A17: =IF($A$2+ROW(A17)-2<=end_year,A16+1,"")
A18: =IF($A$2+ROW(A18)-2<=end_year,A17+1,"")
A19: =IF($A$2+ROW(A19)-2<=end_year,A18+1,"")
A20: =IF($A$2+ROW(A20)-2<=end_year,A19+1,"")
A21: =IF($A$2+ROW(A21)-2<=end_year,A20+1,"")
A22: =IF($A$2+ROW(A22)-2<=end_year,A21+1,"")
A23: =IF($A$2+ROW(A23)-2<=end_year,A22+1,"")
A24: =IF($A$2+ROW(A24)-2<=end_year,A23+1,"")
A25: =IF($A$2+ROW(A25)-2<=end_year,A24+1,"")
... A37: =IF($A$2+ROW(A37)-2<=end_year,A36+1,"")
A38: =IF($A$2+ROW(A38)-2<=end_year,A37+1,"") | G38: =C38+D38+E38+F38 -> 0 | H38: =(B38 + stillbirth*B38/(1000-stillbirth))/(1-abortion) -> 0 | I38: =G38-H38 -> 0
A39: =IF($A$2+ROW(A39)-2<=end_year,A38+1,"") | G39: =C39+D39+E39+F39 -> 0 | H39: =(B39 + stillbirth*B39/(1000-stillbirth))/(1-abortion) -> 0 | I39: =G39-H39 -> 0
A40: =IF($A$2+ROW(A40)-2<=end_year,A39+1,"") | G40: =C40+D40+E40+F40 -> 0 | H40: =(B40 + stillbirth*B40/(1000-stillbirth))/(1-abortion) -> 0 | I40: =G40-H40 -> 0

Sheet Causes of death
A1: ="Percentage of deaths in baseline year ("&start_year&") attributable to cause" -> Percentage of deaths in baseline year (2024) attributable to cause
A2: Neonatal | B2: Causes | C2: <1 month
B3: Neonatal diarrhoea | C3: 0.016570675
B4: Neonatal sepsis | C4: 0.074120555
B5: Neonatal pneumonia | C5: 0.10880084
B6: Neonatal asphyxia | C6: 0.25677874
B7: Neonatal prematurity | C7: 0.36988412
B8: Neonatal tetanus | C8: 0.0028233694
B9: Neonatal congenital anomalies | C9: 0.055443066
B10: Neonatal other | C10: 0.11557863
B11: Total (must be 100%) | C11: =SUM(C3:C10) -> 1
A13: Children | B13: Causes | C13: 1-5 months | D13: 6-11 months | E13: 12-23 months | F13: 24-59 months
B14: Diarrhoea | C14: 0.15073771 | D14: 0.15073771 | E14: 0.15073771 | F14: 0.15073771
B15: Pneumonia | C15: 0.22464495 | D15: 0.22464495 | E15: 0.22464495 | F15: 0.22464495
B16: Meningitis | C16: 0.028228398 | D16: 0.028228398 | E16: 0.028228398 | F16: 0.028228398
B17: Measles | C17: 0.00027112008 | D17: 0.00027112008 | E17: 0.00027112008 | F17: 0.00027112008
B18: Malaria | C18: 0.27503508 | D18: 0.27503508 | E18: 0.27503508 | F18: 0.27503508
B19: Pertussis | C19: 0.020409623 | D19: 0.020409623 | E19: 0.020409623 | F19: 0.020409623
B20: AIDS | C20: 0.058000995 | D20: 0.058000995 | E20: 0.058000995 | F20: 0.058000995
B21: Injury | C21: 0.099798367 | D21: 0.099798367 | E21: 0.099798367 | F21: 0.099798367
B22: Other | C22: 0.14287376 | D22: 0.14287376 | E22: 0.14287376 | F22: 0.14287376
B23: Total (must be 100%) | C23: =SUM(C14:C22) -> 1 | D23: =SUM(D14:D22) -> 1 | E23: =SUM(E14:E22) -> 1 | F23: =SUM(F14:F22) -> 1
A25: Pregnant women | B25: Causes | C25: Pregnant women
B26: Antepartum haemorrhage | C26: 0.086770852
B27: Intrapartum haemorrhage | C27: 0.008643773
B28: Postpartum haemorrhage | C28: 0.15321535
B29: Hypertensive disorders | C29: 0.16509719
B30: Sepsis | C30: 0.10312302
B31: Abortion | C31: 0.10621867
B32: Embolism | C32: 0.018201771
B33: Other direct causes | C33: 0.082691195
B34: Indirect causes | C34: 0.27603818
B35: Total (must be 100%) | C35: =SUM(C26:C34) -> 1

Sheet Nutritional status distribution
A1: ="Percentage of population in each category in baseline year ("&start_year&")" -> Percentage of population in each category in baseline year (2024) | B1: Status | C1: <1 month | D1: 1-5 months | E1: 6-11 months | F1: 12-23 months | G1: 24-59 months
A2: Stunting (height-for-age) | B2: Normal (HAZ-score > -1) | C2: =IFERROR(1-_xlfn.NORM.DIST(_xlfn.NORM.INV(SUM(C4:C5), 0, 1) + 1, 0, 1, TRUE), "") -> 0.5791936 | D2: =IFERROR(1-_xlfn.NORM.DIST(_xlfn.NORM.INV(SUM(D4:D5), 0, 1) + 1, 0, 1, TRUE), "") -> 0.5791936 | E2: =IFERROR(1-_xlfn.NORM.DIST(_xlfn.NORM.INV(SUM(E4:E5), 0, 1) + 1, 0, 1, TRUE), "") -> 0.5463948 | F2: =IFERROR(1-_xlfn.NORM.DIST(_xlfn.NORM.INV(SUM(F4:F5), 0, 1) + 1, 0, 1, TRUE), "") -> 0.37279201 | G2: =IFERROR(1-_xlfn.NORM.DIST(_xlfn.NORM.INV(SUM(G4:G5), 0, 1) + 1, 0, 1, TRUE), "") -> 0.34714278
B3: Mild (HAZ-score between -2 and -1) | C3: =IFERROR(_xlfn.NORM.DIST(_xlfn.NORM.INV(SUM(C4:C5), 0, 1) + 1, 0, 1, TRUE) - SUM(C4:C5), "") -> 0.3057039 | D3: =IFERROR(_xlfn.NORM.DIST(_xlfn.NORM.INV(SUM(D4:D5), 0, 1) + 1, 0, 1, TRUE) - SUM(D4:D5), "") -> 0.3057039 | E3: =IFERROR(_xlfn.NORM.DIST(_xlfn.NORM.INV(SUM(E4:E5), 0, 1) + 1, 0, 1, TRUE) - SUM(E4:E5), "") -> 0.3215135 | F3: =IFERROR(_xlfn.NORM.DIST(_xlfn.NORM.INV(SUM(F4:F5), 0, 1) + 1, 0, 1, TRUE) - SUM(F4:F5), "") -> 0.37753919 | G3: =IFERROR(_xlfn.NORM.DIST(_xlfn.NORM.INV(SUM(G4:G5), 0, 1) + 1, 0, 1, TRUE) - SUM(G4:G5), "") -> 0.38091652
B4: Moderate (HAZ-score between -3 and -2) | C4: 0.081605 | D4: 0.081605 | E4: 0.1052949 | F4: 0.1823117 | G4: 0.1931236
B5: High (HAZ-score < -3) | C5: 0.0334975 | D5: 0.0334975 | E5: 0.0267968 | F5: 0.0673571 | G5: 0.0788171
A8: Wasting (weight-for-height) | B8: Normal (WHZ-score > -1) | C8: =IFERROR(1-_xlfn.NORM.DIST(_xlfn.NORM.INV(SUM(C10:C11), 0, 1) + 1, 0, 1, TRUE), "") -> 0.73361145 | D8: =IFERROR(1-_xlfn.NORM.DIST(_xlfn.NORM.INV(SUM(D10:D11), 0, 1) + 1, 0, 1, TRUE), "") -> 0.73361145 | E8: =IFERROR(1-_xlfn.NORM.DIST(_xlfn.NORM.INV(SUM(E10:E11), 0, 1) + 1, 0, 1, TRUE), "") -> 0.6426729 | F8: =IFERROR(1-_xlfn.NORM.DIST(_xlfn.NORM.INV(SUM(F10:F11), 0, 1) + 1, 0, 1, TRUE), "") -> 0.64945179 | G8: =IFERROR(1-_xlfn.NORM.DIST(_xlfn.NORM.INV(SUM(G10:G11), 0, 1) + 1, 0, 1, TRUE), "") -> 0.75907849
B9: Mild (WHZ-score between -2 and -1) | C9: =IFERROR(_xlfn.NORM.DIST(_xlfn.NORM.INV(SUM(C10:C11), 0, 1) + 1, 0, 1, TRUE) - SUM(C10:C11), "") -> 0.21417635 | D9: =IFERROR(_xlfn.NORM.DIST(_xlfn.NORM.INV(SUM(D10:D11), 0, 1) + 1, 0, 1, TRUE) - SUM(D10:D11), "") -> 0.21417635 | E9: =IFERROR(_xlfn.NORM.DIST(_xlfn.NORM.INV(SUM(E10:E11), 0, 1) + 1, 0, 1, TRUE) - SUM(E10:E11), "") -> 0.2712968 | F9: =IFERROR(_xlfn.NORM.DIST(_xlfn.NORM.INV(SUM(F10:F11), 0, 1) + 1, 0, 1, TRUE) - SUM(F10:F11), "") -> 0.26734461 | G9: =IFERROR(_xlfn.NORM.DIST(_xlfn.NORM.INV(SUM(G10:G11), 0, 1) + 1, 0, 1, TRUE) - SUM(G10:G11), "") -> 0.19666941
B10: MAM (WHZ-score between -3 and -2) | C10: 0.0280967 | D10: 0.0280967 | E10: 0.0638479 | F10: 0.0766164 | G10: 0.0358124
B11: SAM (WHZ-score < -3) | C11: 0.0241155 | D11: 0.0241155 | E11: 0.0221824 | F11: 0.0065872 | G11: 0.0084397
A13: Anaemia | C13: <1 month | D13: 1-5 months | E13: 6-11 months | F13: 12-23 months | G13: 24-59 months | H13: PW: 15-19 years | I13: PW: 20-29 years | J13: PW: 30-39 years | K13: PW: 40-49 years | L13: WRA: 15-19 years | M13: WRA: 20-29 years | N13: WRA: 30-39 years | O13: WRA: 40-49 years
B14: Prevalence of anaemia | C14: 0.88048884 | D14: 0.87291715 | E14: 0.87291715 | F14: 0.76156849 | G14: 0.76156849 | H14: 0.614 | I14: 0.614 | J14: 0.614 | K14: 0.614 | L14: 0.477 | M14: 0.477 | N14: 0.477 | O14: 0.477
B15: Prevalence of iron deficiency anaemia | C15: =iron_deficiency_anaemia*C14 -> 0.37117535 | D15: =iron_deficiency_anaemia*D14 -> 0.36798346 | E15: =iron_deficiency_anaemia*E14 -> 0.36798346 | F15: =iron_deficiency_anaemia*F14 -> 0.32104377 | G15: =iron_deficiency_anaemia*G14 -> 0.32104377 | H15: =iron_deficiency_anaemia*H14 -> 0.25883538 | I15: =iron_deficiency_anaemia*I14 -> 0.25883538 | J15: =iron_deficiency_anaemia*J14 -> 0.25883538 | ... O15: =iron_deficiency_anaemia*O14 -> 0.20108221

Sheet Breastfeeding distribution
A1: ="Percentage of children in each category in baseline year ("&start_year&")" -> Percentage of children in each category in baseline year (2024) | B1: Status | C1: <1 month | D1: 1-5 months | E1: 6-11 months | F1: 12-23 months | G1: 24-59 months
A2: Breastfeeding | B2: Exclusive | C2: 0.8569893 | D2: 0.6185904 | E2: 0 | F2: 0 | G2: 0
B3: Predominant | C3: 0.0480514 | D3: 0.1611971 | E3: 0 | F3: 0 | G3: 0
B4: Partial | C4: 0.0839393 | D4: 0.2121906 | E4: 0.9778422 | F4: 0.7983601 | G4: 0
B5: None | C5: 0.01102 | D5: 0.0080219 | E5: =1-SUM(E2:E4) -> 0.0221578 | F5: =1-SUM(F2:F4) -> 0.2016399 | G5: =1-SUM(G2:G4) -> 1

Sheet Time trends
A1: Risk | B1: Population | C1: 2010 | D1: 2011 | E1: 2012 | F1: 2013 | G1: 2014 | H1: 2015 | I1: 2016 | J1: 2017 | K1: 2018
A2: Stunting prevalence (%) | B2: Children 0-59 months
A4: Wasting prevalence (%) | B4: Children 0-59 months
A6: Anaemia prevalence (%) | B6: Children 0-59 months
B7: Pregnant women
B8: Women of reproductive age
A10: Prevalence of age-appropriate breastfeeding | B10: Children 0-5 months
B11: Children 6-23 months
A13: Mortality | B13: Under five (deaths per 1,000 births)
B14: Maternal (deaths per 1,000 births)

Sheet Economic loss
A1: Type | B1: Cost
A2: Child wasting episode | B2: 10
A3: Child turning age 5 stunted (over lifetime) | B3: 10
A4: Child death | B4: 10
A5: Maternal death | B5: 10
A6: Anaemic child (per year) | B6: 10
A7: Anaemic pregnant woman (per pregnancy) | B7: 10

Sheet IYCF packages
A1: IYCF package | B1: Target population | C1: Health facility | D1: Community | E1: Mass media
A2: IYCF 1 | B2: Pregnant women | E2: =IF(E$7="","",E$7)
B3: <1 month | D3: x | E3: =IF(E$7="","",E$7)
B4: 1-5 months | D4: x | E4: =IF(E$7="","",E$7)
B5: 6-11 months | E5: =IF(E$7="","",E$7)
B6: 12-23 months | E6: =IF(E$7="","",E$7)
B7: All
A9: IYCF 2 | B9: Pregnant women | E9: =IF(E$7="","",E$7)
B10: <1 month | E10: =IF(E$7="","",E$7)
B11: 1-5 months | E11: =IF(E$7="","",E$7)
B12: 6-11 months | D12: x | E12: =IF(E$7="","",E$7)
B13: 12-23 months | D13: x | E13: =IF(E$7="","",E$7)
B14: All
A16: IYCF 3 | B16: Pregnant women | D16: x | E16: =IF(E$7="","",E$7)
B17: <1 month | D17: x | E17: =IF(E$7="","",E$7)
B18: 1-5 months | D18: x | E18: =IF(E$7="","",E$7)
B19: 6-11 months | D19: x | E19: =IF(E$7="","",E$7)
B20: 12-23 months | D20: x | E20: =IF(E$7="","",E$7)
B21: All

Sheet Treatment of SAM
A1: Field | B1: Default | C1: Extension | D1: Add extension
A2: Program | B2: Treatment of SAM | C2: Management of MAM
A3: Delivery mode | B3: Health facility | C3: Community-based

Sheet Programs cost and coverage
A1: Program | B1: ="Baseline ("&start_year&") coverage" -> Baseline (2024) coverage | C1: Saturation coverage of target population | D1: Unit cost (US$) | E1: Cost-coverage relationship | F1: Max-increase per annum | G1: Max-decrease per annum
A2: Balanced energy-protein supplementation | B2: 0.17805547 | C2: 0.95 | D2: 35.286532 | E2: Linear (constant marginal cost) [default] | F2: 1 | G2: 1
A3: Calcium supplementation | B3: 0 | C3: 0.95 | D3: 44.64511 | E3: Linear (constant marginal cost) [default] | F3: 1 | G3: 1
A4: Cash transfers | B4: 0 | C4: 0.95 | D4: 57.846169 | E4: Linear (constant marginal cost) [default] | F4: 1 | G4: 1
A5: Delayed cord clamping | B5: 0 | C5: 0.95 | D5: 0.14631854 | E5: Linear (constant marginal cost) [default] | F5: 1 | G5: 1
A6: Family planning | B6: 0 | C6: 0.95 | D6: 99.99 | E6: Linear (constant marginal cost) [default] | F6: 1 | G6: 1
A7: IFA fortification of maize | B7: 0 | C7: 0.95 | D7: 99.99 | E7: Linear (constant marginal cost) [default] | F7: 1 | G7: 1
A8: IFA fortification of rice | B8: 0 | C8: 0.95 | D8: 99.99 | E8: Linear (constant marginal cost) [default] | F8: 1 | G8: 1
A9: IFA fortification of wheat flour | B9: 0 | C9: 0.95 | D9: 99.99 | E9: Linear (constant marginal cost) [default] | F9: 1 | G9: 1
A10: IFAS (community) | B10: 0 | C10: 0.95 | D10: 14.170172 | E10: Linear (constant marginal cost) [default] | F10: 1 | G10: 1
A11: IFAS (health facility) | B11: 0 | C11: 0.95 | D11: 14.170172 | E11: Linear (constant marginal cost) [default] | F11: 1 | G11: 1
A12: IFAS (retailer) | B12: 0 | C12: 0.95 | D12: 14.170172 | E12: Linear (constant marginal cost) [default] | F12: 1 | G12: 1
A13: IFAS (school) | B13: 0 | C13: 0.95 | D13: 14.170172 | E13: Linear (constant marginal cost) [default] | F13: 1 | G13: 1
... A39: Zinc supplementation | B39: 0.1860724 | C39: 0.95 | D39: 99.99 | E39: Linear (constant marginal cost) [default] | F39: 1 | G39: 1

Sheet Program dependencies
A1: Program | B1: Exclusion dependency | C1: Threshold dependency
A2: IFAS for pregnant women (community) | B2: Multiple micronutrient supplementation
A3: IFAS for pregnant women (health facility) | B3: Multiple micronutrient supplementation
A4: Public provision of complementary foods | B4: Lipid-based nutrition supplements
A5: Micronutrient powders | B5: Lipid-based nutrition supplements

Sheet Reference programs
A1: Program
A2: Family planning
A3: IPTp
A4: Long-lasting insecticide-treated bednets
A5: WASH: Handwashing
A6: WASH: Hygenic disposal
A7: WASH: Improved sanitation
A8: WASH: Improved water source
A9: WASH: Piped water

Sheet Incidence of conditions
A1: Condition | B1: <1 month | C1: 1-5 months | D1: 6-11 months | E1: 12-23 months | F1: 24-59 months
A2: Diarrhoea | B2: ='Baseline year population inputs'!C51 -> 3.3 | C2: ='Baseline year population inputs'!C52 -> 3.3 | D2: ='Baseline year population inputs'!C53 -> 3.3 | E2: ='Baseline year population inputs'!C54 -> 3.3 | F2: ='Baseline year population inputs'!C55 -> 3.3
A3: MAM | B3: =frac_mam_1month * 2.6 -> 0.07305142 | C3: =frac_mam_1_5months * 2.6 -> 0.07305142 | D3: =frac_mam_6_11months * 2.6 -> 0.16600454 | E3: =frac_mam_12_23months * 2.6 -> 0.19920264 | F3: =frac_mam_24_59months * 2.6 -> 0.09311224
A4: SAM | B4: =frac_sam_1month * 2.6 -> 0.0627003 | C4: =frac_sam_1_5months * 2.6 -> 0.0627003 | D4: =frac_sam_6_11months * 2.6 -> 0.05767424 | E4: =frac_sam_12_23months * 2.6 -> 0.01712672 | F4: =frac_sam_24_59months * 2.6 -> 0.02194322

Sheet Programs target population
A1: Broad population group | B1: Program | C1: <1 month | D1: 1-5 months | E1: 6-11 months | F1: 12-23 months | G1: 24-59 months | H1: PW: 15-19 years | I1: PW: 20-29 years | J1: PW: 30-39 years | K1: PW: 40-49 years | L1: WRA: 15-19 years | M1: WRA: 20-29 years | N1: WRA: 30-39 years | O1: WRA: 40-49 years
A2: Children | B2: Cash transfers | C2: 0 | D2: =food_insecure -> 0.498 | E2: =food_insecure -> 0.498 | F2: =food_insecure -> 0.498 | G2: =food_insecure -> 0.498 | H2: 0 | I2: 0 | J2: 0 | K2: 0 | L2: 0 | M2: 0 | N2: 0 | O2: 0
B3: Delayed cord clamping | C3: 1 | D3: 0 | E3: 0 | F3: 0 | G3: 0 | H3: 0 | I3: 0 | J3: 0 | K3: 0 | L3: 0 | M3: 0 | N3: 0 | O3: 0
B4: Kangaroo mother care | C4: 1 | D4: 0 | E4: 0 | F4: 0 | G4: 0 | H4: 0 | I4: 0 | J4: 0 | K4: 0 | L4: 0 | M4: 0 | N4: 0 | O4: 0
B5: Lipid-based nutrition supplements | C5: 0 | D5: 0 | E5: =food_insecure -> 0.498 | F5: =food_insecure -> 0.498 | G5: 0 | H5: 0 | I5: 0 | J5: 0 | K5: 0 | L5: 0 | M5: 0 | N5: 0 | O5: 0
B6: Micronutrient powders | C6: 0 | D6: 0 | E6: =1 -> 1 | F6: =1 -> 1 | G6: =1 -> 1 | H6: 0 | I6: 0 | J6: 0 | K6: 0 | L6: 0 | M6: 0 | N6: 0 | O6: 0
B7: Oral rehydration salts | C7: =diarrhoea_1mo*frac_diarrhea_severe -> 0.072 | D7: =diarrhoea_1_5mo*frac_diarrhea_severe -> 0.072 | E7: =diarrhoea_6_11mo*frac_diarrhea_severe -> 0.072 | F7: =diarrhoea_12_23mo*frac_diarrhea_severe -> 0.072 | G7: =diarrhoea_24_59mo*frac_diarrhea_severe -> 0.072 | H7: 0 | I7: 0 | J7: 0 | K7: 0 | L7: 0 | M7: 0 | N7: 0 | O7: 0
B8: Public provision of complementary foods | C8: 0 | D8: 0 | E8: =food_insecure -> 0.498 | F8: =food_insecure -> 0.498 | G8: 0 | H8: 0 | I8: 0 | J8: 0 | K8: 0 | L8: 0 | M8: 0 | N8: 0 | O8: 0
B9: Small quantity lipid-based nutrition supplements | C9: 0 | D9: 0 | E9: =food_insecure -> 0.498 | F9: =food_insecure -> 0.498 | G9: 0 | H9: 0 | I9: 0 | J9: 0 | K9: 0 | L9: 0 | M9: 0 | N9: 0 | O9: 0
B10: Treatment of SAM | C10: 0 | D10: =IF(ISBLANK(comm_deliv), frac_children_health_facility,1) -> 1 | E10: =IF(ISBLANK(comm_deliv), frac_children_health_facility,1) -> 1 | F10: =IF(ISBLANK(comm_deliv), frac_children_health_facility,1) -> 1 | G10: =IF(ISBLANK(comm_deliv), frac_children_health_facility,1) -> 1 | H10: 0 | I10: 0 | J10: 0 | K10: 0 | L10: 0 | M10: 0 | N10: 0 | O10: 0
B11: Vitamin A supplementation | C11: 0 | D11: 0 | E11: 1 | F11: 1 | G11: 1 | H11: 0 | I11: 0 | J11: 0 | K11: 0 | L11: 0 | M11: 0 | N11: 0 | O11: 0
B12: Zinc for treatment + ORS | C12: =diarrhoea_1mo*frac_diarrhea_severe -> 0.072 | D12: =diarrhoea_1_5mo*frac_diarrhea_severe -> 0.072 | E12: =diarrhoea_6_11mo*frac_diarrhea_severe -> 0.072 | F12: =diarrhoea_12_23mo*frac_diarrhea_severe -> 0.072 | G12: =diarrhoea_24_59mo*frac_diarrhea_severe -> 0.072 | H12: 0 | I12: 0 | J12: 0 | K12: 0 | L12: 0 | M12: 0 | N12: 0 | O12: 0
B13: Zinc supplementation | C13: 0 | D13: 0 | E13: 1 | F13: 1 | G13: 1 | H13: 0 | I13: 0 | J13: 0 | K13: 0 | L13: 0 | M13: 0 | N13: 0 | O13: 0
A15: Pregnant women | B15: Balanced energy-protein supplementation | C15: 0 | D15: 0 | E15: 0 | F15: 0 | G15: 0 | H15: =food_insecure -> 0.498 | I15: =food_insecure -> 0.498 | J15: =food_insecure -> 0.498 | K15: =food_insecure -> 0.498 | L15: 0 | M15: 0 | N15: 0 | O15: 0
B16: Calcium supplementation | C16: 0 | D16: 0 | E16: 0 | F16: 0 | G16: 0 | H16: 1 | I16: 1 | J16: 1 | K16: 1 | L16: 0 | M16: 0 | N16: 0 | O16: 0
B17: IFAS for pregnant women (community) | C17: 0 | D17: 0 | E17: 0 | F17: 0 | G17: 0 | H17: =1 -> 1 | I17: =1 -> 1 | J17: =1 -> 1 | K17: =1 -> 1 | L17: 0 | M17: 0 | N17: 0 | O17: 0
B18: IFAS for pregnant women (health facility) | C18: 0 | D18: 0 | E18: 0 | F18: 0 | G18: 0 | H18: =frac_PW_health_facility -> 1 | I18: =frac_PW_health_facility -> 1 | J18: =frac_PW_health_facility -> 1 | K18: =frac_PW_health_facility -> 1 | L18: 0 | M18: 0 | N18: 0 | O18: 0
B19: IPTp | C19: 0 | D19: 0 | E19: 0 | F19: 0 | G19: 0 | H19: =frac_malaria_risk -> 1 | I19: =frac_malaria_risk -> 1 | J19: =frac_malaria_risk -> 1 | K19: =frac_malaria_risk -> 1 | L19: 0 | M19: 0 | N19: 0 | O19: 0
B20: Mg for eclampsia | C20: 0 | D20: 0 | E20: 0 | F20: 0 | G20: 0 | H20: 1 | I20: 1 | J20: 1 | K20: 1 | L20: 0 | M20: 0 | N20: 0 | O20: 0
B21: Mg for pre-eclampsia | C21: 0 | D21: 0 | E21: 0 | F21: 0 | G21: 0 | H21: 1 | I21: 1 | J21: 1 | K21: 1 | L21: 0 | M21: 0 | N21: 0 | O21: 0
B22: Multiple micronutrient supplementation | C22: 0 | D22: 0 | E22: 0 | F22: 0 | G22: 0 | H22: =1 -> 1 | I22: =1 -> 1 | J22: =1 -> 1 | K22: =1 -> 1 | L22: 0 | M22: 0 | N22: 0 | O22: 0
A24: Non-pregnant WRA | B24: Family planning | C24: 0 | D24: 0 | E24: 0 | F24: 0 | G24: 0 | H24: 0 | I24: 0 | J24: 0 | K24: 0 | L24: =famplan_unmet_need -> 0.679 | M24: =famplan_unmet_need -> 0.679 | N24: =famplan_unmet_need -> 0.679 | O24: =famplan_unmet_need -> 0.679
B25: IFAS (community) | C25: 0 | D25: 0 | E25: 0 | F25: 0 | G25: 0 | H25: 0 | I25: 0 | J25: 0 | K25: 0 | L25: =(1-food_insecure)*(0.49)*(1-school_attendance) + food_insecure*(0.7)*(1-school_attendance) -> 0.39619899 | M25: =(1-food_insecure)*(0.49)+food_insecure*(0.7) -> 0.59458 | N25: =(1-food_insecure)*(0.49)+food_insecure*(0.7) -> 0.59458 | O25: =(1-food_insecure)*(0.49)+food_insecure*(0.7) -> 0.59458
B26: IFAS (health facility) | C26: 0 | D26: 0 | E26: 0 | F26: 0 | G26: 0 | H26: 0 | I26: 0 | J26: 0 | K26: 0 | L26: =(1-food_insecure)*(0.21)*(1-school_attendance) + food_insecure*(0.3)*(1-school_attendance) -> 0.16979957 | M26: =(1-food_insecure)*(0.21)+food_insecure*(0.3) -> 0.25482 | N26: =(1-food_insecure)*(0.21)+food_insecure*(0.3) -> 0.25482 | O26: =(1-food_insecure)*(0.21)+food_insecure*(0.3) -> 0.25482
B27: IFAS (retailer) | C27: 0 | D27: 0 | E27: 0 | F27: 0 | G27: 0 | H27: 0 | I27: 0 | J27: 0 | K27: 0 | L27: =(1-food_insecure)*(0.3)*(1-school_attendance) -> 0.10035246 | M27: =(1-food_insecure)*(0.3) -> 0.1506 | N27: =(1-food_insecure)*(0.3) -> 0.1506 | O27: =(1-food_insecure)*(0.3) -> 0.1506
B28: IFAS (school) | C28: 0 | D28: 0 | E28: 0 | F28: 0 | G28: 0 | H28: 0 | I28: 0 | J28: 0 | K28: 0 | L28: =(1-food_insecure)*1*school_attendance + food_insecure*1*school_attendance -> 0.33364899 | M28: 0 | N28: 0 | O28: 0
A30: General population | B30: IFA fortification of maize | C30: 0 | D30: 0 | E30: =frac_maize -> 0.05 | F30: =frac_maize -> 0.05 | G30: =frac_maize -> 0.05 | H30: =frac_maize -> 0.05 | I30: =frac_maize -> 0.05 | J30: =frac_maize -> 0.05 | K30: =frac_maize -> 0.05 | L30: =frac_maize -> 0.05 | ... O30: =frac_maize -> 0.05
B31: IFA fortification of rice | C31: 0 | D31: 0 | E31: =frac_rice -> 0.7 | F31: =frac_rice -> 0.7 | G31: =frac_rice -> 0.7 | H31: =frac_rice -> 0.7 | I31: =frac_rice -> 0.7 | J31: =frac_rice -> 0.7 | K31: =frac_rice -> 0.7 | L31: =frac_rice -> 0.7 | ... O31: =frac_rice -> 0.7
B32: IFA fortification of wheat flour | C32: 0 | D32: 0 | E32: =frac_wheat -> 0.05 | F32: =frac_wheat -> 0.05 | G32: =frac_wheat -> 0.05 | H32: =frac_wheat -> 0.05 | I32: =frac_wheat -> 0.05 | J32: =frac_wheat -> 0.05 | K32: =frac_wheat -> 0.05 | L32: =frac_wheat -> 0.05 | ... O32: =frac_wheat -> 0.05
B33: Iron and iodine fortification of salt | C33: 0 | D33: 0 | E33: 1 | F33: 1 | G33: 1 | H33: 1 | I33: 1 | J33: 1 | K33: 1 | L33: 1 | M33: 1 | N33: 1 | O33: 1
B34: Long-lasting insecticide-treated bednets | C34: =frac_malaria_risk -> 1 | D34: =frac_malaria_risk -> 1 | E34: =frac_malaria_risk -> 1 | F34: =frac_malaria_risk -> 1 | G34: =frac_malaria_risk -> 1 | H34: =frac_malaria_risk -> 1 | I34: =frac_malaria_risk -> 1 | J34: =frac_malaria_risk -> 1 | ... O34: =frac_malaria_risk -> 1
B35: WASH: Handwashing | C35: 1 | D35: 1 | E35: 1 | F35: 1 | G35: 1 | H35: 1 | I35: 1 | J35: 1 | K35: 1 | L35: 1 | M35: 1 | N35: 1 | O35: 1
B36: WASH: Hygenic disposal | C36: 1 | D36: 1 | E36: 1 | F36: 1 | G36: 1 | H36: 1 | I36: 1 | J36: 1 | K36: 1 | L36: 1 | M36: 1 | N36: 1 | O36: 1
B37: WASH: Improved sanitation | C37: 1 | D37: 1 | E37: 1 | F37: 1 | G37: 1 | H37: 1 | I37: 1 | J37: 1 | K37: 1 | L37: 1 | M37: 1 | N37: 1 | O37: 1
B38: WASH: Improved water source | C38: 1 | D38: 1 | E38: 1 | F38: 1 | G38: 1 | H38: 1 | I38: 1 | J38: 1 | K38: 1 | L38: 1 | M38: 1 | N38: 1 | O38: 1
B39: WASH: Piped water | C39: 1 | D39: 1 | E39: 1 | F39: 1 | G39: 1 | H39: 1 | I39: 1 | J39: 1 | K39: 1 | L39: 1 | M39: 1 | N39: 1 | O39: 1

Sheet Cost curve options
A1: Linear (constant marginal cost) [default]
A2: Curved with increasing marginal cost
A3: Curved with decreasing marginal cost
A4: S-shaped (decreasing then increasing marginal cost)

Sheet Programs family planning
A1: Method | B1: Effectiveness | C1: Distribution | D1: Cost | E1: Proportional Cost
A2: Condom | B2: 0.9 | C2: 0.09 | D2: 0.8 | E2: =C2*D2 -> 0.072
A3: Male sterilization | B3: 1 | C3: 0.02 | D3: 1.9 | E3: =C3*D3 -> 0.038
A4: Female sterilization | B4: 1 | C4: 0.08 | D4: 2 | E4: =C4*D4 -> 0.16
A5: Injectable | B5: 1 | C5: 0.18 | D5: 0.7 | E5: =C5*D5 -> 0.126
A6: Implant | B6: 1 | C6: 0.02 | D6: 0.7 | E6: =C6*D6 -> 0.014
A7: Pill | B7: 0.93 | C7: 0.45 | D7: 0.9 | E7: =C7*D7 -> 0.405
A8: Withdrawal | B8: 0.5 | C8: 0.03 | D8: 0 | E8: =C8*D8 -> 0
A9: Fertility awareness | B9: 0.5 | C9: 0.11 | D9: 0 | E9: =C9*D9 -> 0
A10: IUD | B10: 0.98 | C10: 0.01 | D10: 0.6 | E10: =C10*D10 -> 0.006

Sheet Programs impacted population
A1: Broad population group | B1: Program | C1: <1 month | D1: 1-5 months | E1: 6-11 months | F1: 12-23 months | G1: 24-59 months | H1: PW: 15-19 years | I1: PW: 20-29 years | J1: PW: 30-39 years | K1: PW: 40-49 years | L1: WRA: 15-19 years | M1: WRA: 20-29 years | N1: WRA: 30-39 years | O1: WRA: 40-49 years
A2: Children | B2: Cash transfers | C2: 0 | D2: 1 | E2: 1 | F2: 1 | G2: 1 | H2: 0 | I2: 0 | J2: 0 | K2: 0 | L2: 0 | M2: 0 | N2: 0 | O2: 0
B3: Delayed cord clamping | C3: 1 | D3: 1 | E3: 0 | F3: 0 | G3: 0 | H3: 0 | I3: 0 | J3: 0 | K3: 0 | L3: 0 | M3: 0 | N3: 0 | O3: 0
B4: IYCF 1 | C4: 1 | D4: 1 | E4: 1 | F4: 1 | G4: 1 | H4: 0 | I4: 0 | J4: 0 | K4: 0 | L4: 0 | M4: 0 | N4: 0 | O4: 0
B5: IYCF 2 | C5: 1 | D5: 1 | E5: 1 | F5: 1 | G5: 1 | H5: 0 | I5: 0 | J5: 0 | K5: 0 | L5: 0 | M5: 0 | N5: 0 | O5: 0
B6: IYCF 3 | C6: 1 | D6: 1 | E6: 1 | F6: 1 | G6: 1 | H6: 0 | I6: 0 | J6: 0 | K6: 0 | L6: 0 | M6: 0 | N6: 0 | O6: 0
B7: Kangaroo mother care | C7: 1 | D7: 1 | E7: 0 | F7: 0 | G7: 0 | H7: 0 | I7: 0 | J7: 0 | K7: 0 | L7: 0 | M7: 0 | N7: 0 | O7: 0
B8: Lipid-based nutrition supplements | C8: 0 | D8: 0 | E8: 1 | F8: 1 | G8: 0 | H8: 0 | I8: 0 | J8: 0 | K8: 0 | L8: 0 | M8: 0 | N8: 0 | O8: 0
B9: Micronutrient powders | C9: 0 | D9: 0 | E9: 1 | F9: 1 | G9: 1 | H9: 0 | I9: 0 | J9: 0 | K9: 0 | L9: 0 | M9: 0 | N9: 0 | O9: 0
B10: Oral rehydration salts | C10: 1 | D10: 1 | E10: 1 | F10: 1 | G10: 1 | H10: 0 | I10: 0 | J10: 0 | K10: 0 | L10: 0 | M10: 0 | N10: 0 | O10: 0
B11: Public provision of complementary foods | C11: 0 | D11: 0 | E11: 1 | F11: 1 | G11: 0 | H11: 0 | I11: 0 | J11: 0 | K11: 0 | L11: 0 | M11: 0 | N11: 0 | O11: 0
B12: Small quantity lipid-based nutrition supplements | C12: 0 | D12: 0 | E12: 1 | F12: 1 | G12: 0 | H12: 0 | I12: 0 | J12: 0 | K12: 0 | L12: 0 | M12: 0 | N12: 0 | O12: 0
B13: Treatment of SAM | C13: 0 | D13: 1 | E13: 1 | F13: 1 | G13: 1 | H13: 0 | I13: 0 | J13: 0 | K13: 0 | L13: 0 | M13: 0 | N13: 0 | O13: 0
B14: Vitamin A supplementation | C14: 0 | D14: 0 | E14: 1 | F14: 1 | G14: 1 | H14: 0 | I14: 0 | J14: 0 | K14: 0 | L14: 0 | M14: 0 | N14: 0 | O14: 0
... B16: Zinc supplementation | C16: 0 | D16: 0 | E16: 1 | F16: 1 | G16: 1 | H16: 0 | I16: 0 | J16: 0 | K16: 0 | L16: 0 | M16: 0 | N16: 0 | O16: 0
A18: Pregnant women | B18: Balanced energy-protein supplementation | C18: 0 | D18: 0 | E18: 0 | F18: 0 | G18: 0 | H18: 1 | I18: 1 | J18: 1 | K18: 1 | L18: 0 | M18: 0 | N18: 0 | O18: 0
B19: Calcium supplementation | C19: 0 | D19: 0 | E19: 0 | F19: 0 | G19: 0 | H19: 1 | I19: 1 | J19: 1 | K19: 1 | L19: 0 | M19: 0 | N19: 0 | O19: 0
B20: IFAS for pregnant women (community) | C20: 0 | D20: 0 | E20: 0 | F20: 0 | G20: 0 | H20: 1 | I20: 1 | J20: 1 | K20: 1 | L20: 0 | M20: 0 | N20: 0 | O20: 0
B21: IFAS for pregnant women (health facility) | C21: 0 | D21: 0 | E21: 0 | F21: 0 | G21: 0 | H21: 1 | I21: 1 | J21: 1 | K21: 1 | L21: 0 | M21: 0 | N21: 0 | O21: 0
B22: IPTp | C22: 0 | D22: 0 | E22: 0 | F22: 0 | G22: 0 | H22: 1 | I22: 1 | J22: 1 | K22: 1 | L22: 0 | M22: 0 | N22: 0 | O22: 0
B23: Mg for eclampsia | C23: 0 | D23: 0 | E23: 0 | F23: 0 | G23: 0 | H23: 1 | I23: 1 | J23: 1 | K23: 1 | L23: 0 | M23: 0 | N23: 0 | O23: 0
B24: Mg for pre-eclampsia | C24: 0 | D24: 0 | E24: 0 | F24: 0 | G24: 0 | H24: 1 | I24: 1 | J24: 1 | K24: 1 | L24: 0 | M24: 0 | N24: 0 | O24: 0
B25: Multiple micronutrient supplementation | C25: 0 | D25: 0 | E25: 0 | F25: 0 | G25: 0 | H25: 1 | I25: 1 | J25: 1 | K25: 1 | L25: 0 | M25: 0 | N25: 0 | O25: 0
A27: Non-pregnant WRA | B27: Family planning | C27: 0 | D27: 0 | E27: 0 | F27: 0 | G27: 0 | H27: 0 | I27: 0 | J27: 0 | K27: 0 | L27: 1 | M27: 0 | N27: 0 | O27: 0
B28: IFAS (community) | C28: 0 | D28: 0 | E28: 0 | F28: 0 | G28: 0 | H28: 0 | I28: 0 | J28: 0 | K28: 0 | L28: 1 | M28: 1 | N28: 1 | O28: 1
B29: IFAS (health facility) | C29: 0 | D29: 0 | E29: 0 | F29: 0 | G29: 0 | H29: 0 | I29: 0 | J29: 0 | K29: 0 | L29: 1 | M29: 1 | N29: 1 | O29: 1
B30: IFAS (retailer) | C30: 0 | D30: 0 | E30: 0 | F30: 0 | G30: 0 | H30: 0 | I30: 0 | J30: 0 | K30: 0 | L30: 1 | M30: 1 | N30: 1 | O30: 1
B31: IFAS (school) | C31: 0 | D31: 0 | E31: 0 | F31: 0 | G31: 0 | H31: 0 | I31: 0 | J31: 0 | K31: 0 | L31: 1 | M31: 0 | N31: 0 | O31: 0
A33: General population | B33: IFA fortification of maize | C33: 1 | D33: 0 | E33: 1 | F33: 1 | G33: 1 | H33: 1 | I33: 1 | J33: 1 | K33: 1 | L33: 1 | M33: 1 | N33: 1 | O33: 1
B34: IFA fortification of rice | C34: 1 | D34: 0 | E34: 1 | F34: 1 | G34: 1 | H34: 1 | I34: 1 | J34: 1 | K34: 1 | L34: 1 | M34: 1 | N34: 1 | O34: 1
B35: IFA fortification of wheat flour | C35: 1 | D35: 0 | E35: 1 | F35: 1 | G35: 1 | H35: 1 | I35: 1 | J35: 1 | K35: 1 | L35: 1 | M35: 1 | N35: 1 | O35: 1
B36: Iron and iodine fortification of salt | C36: 1 | D36: 0 | E36: 1 | F36: 1 | G36: 1 | H36: 1 | I36: 1 | J36: 1 | K36: 1 | L36: 1 | M36: 1 | N36: 1 | O36: 1
B37: Long-lasting insecticide-treated bednets | C37: 1 | D37: 1 | E37: 1 | F37: 1 | G37: 1 | H37: 1 | I37: 1 | J37: 1 | K37: 1 | L37: 1 | M37: 1 | N37: 1 | O37: 1
B38: WASH: Handwashing | C38: 1 | D38: 1 | E38: 1 | F38: 1 | G38: 1 | H38: 1 | I38: 1 | J38: 1 | K38: 1 | L38: 1 | M38: 1 | N38: 1 | O38: 1
B39: WASH: Hygenic disposal | C39: 1 | D39: 1 | E39: 1 | F39: 1 | G39: 1 | H39: 1 | I39: 1 | J39: 1 | K39: 1 | L39: 1 | M39: 1 | N39: 1 | O39: 1
B40: WASH: Improved sanitation | C40: 1 | D40: 1 | E40: 1 | F40: 1 | G40: 1 | H40: 1 | I40: 1 | J40: 1 | K40: 1 | L40: 1 | M40: 1 | N40: 1 | O40: 1
B41: WASH: Improved water source | C41: 1 | D41: 1 | E41: 1 | F41: 1 | G41: 1 | H41: 1 | I41: 1 | J41: 1 | K41: 1 | L41: 1 | M41: 1 | N41: 1 | O41: 1
B42: WASH: Piped water | C42: 1 | D42: 1 | E42: 1 | F42: 1 | G42: 1 | H42: 1 | I42: 1 | J42: 1 | K42: 1 | L42: 1 | M42: 1 | N42: 1 | O42: 1

Sheet Program risk areas
A1: Program | B1: Stunting | C1: Anaemia | D1: Wasting prevention | E1: Wasting treatment | F1: Breastfeeding | G1: Diarrhoea | H1: Mortality | I1: Birth outcomes | J1: Birth spacing | K1: Birth number
A2: Balanced energy-protein supplementation | I2: x
A3: Calcium supplementation | H3: x
A4: Cash transfers | D4: x
A5: Delayed cord clamping | C5: x
A6: Family planning | J6: x | K6: x
A7: IFA fortification of maize | C7: x | H7: x
A8: IFA fortification of rice | C8: x | H8: x
A9: IFA fortification of wheat flour | C9: x | H9: x
A10: IFAS (community) | C10: x
A11: IFAS (health facility) | C11: x
A12: IFAS (retailer) | C12: x
A13: IFAS (school) | C13: x
A14: IFAS for pregnant women (community) | C14: x | I14: x
A15: IFAS for pregnant women (health facility) | C15: x | I15: x
A16: IPTp | C16: x | H16: x | I16: x
A17: Iron and iodine fortification of salt | C17: x
A18: IYCF 1 | B18: x | F18: x
A19: IYCF 2 | B19: x | F19: x
A20: IYCF 3 | B20: x | F20: x
A21: Kangaroo mother care | H21: x | I21: x
A22: Lipid-based nutrition supplements | B22: x | C22: x | D22: x
A23: Long-lasting insecticide-treated bednets | C23: x | I23: x
A24: Mg for eclampsia | H24: x
A25: Mg for pre-eclampsia | H25: x
A26: Micronutrient powders | C26: x
A27: Multiple micronutrient supplementation | C27: x | I27: x
A28: Oral rehydration salts | H28: x
A29: Public provision of complementary foods | B29: x | D29: x
A30: Small quantity lipid-based nutrition supplements | B30: x | C30: x | D30: x
A31: Treatment of SAM | E31: x
A32: Vitamin A supplementation | G32: x | H32: x
A33: WASH: Handwashing | G33: x | H33: x
A34: WASH: Hygenic disposal | G34: x | H34: x
A35: WASH: Improved sanitation | G35: x | H35: x
A36: WASH: Improved water source | G36: x | H36: x
A37: WASH: Piped water | G37: x | H37: x
A38: Zinc for treatment + ORS | H38: x
A39: Zinc supplementation | B39: x | G39: x | H39: x

Sheet Population risk areas
A1: Age group | B1: Stunting | C1: Anaemia | D1: Wasting prevention | E1: Wasting treatment | F1: Breastfeeding | G1: Diarrhoea | H1: Mortality | I1: Birth outcomes | J1: Birth spacing | K1: Birth number
A2: <1 month | B2: x | C2: x | D2: x | E2: x | F2: x | G2: x | H2: x
A3: 1-5 months | B3: x | C3: x | D3: x | E3: x | F3: x | G3: x | H3: x
A4: 6-11 months | B4: x | C4: x | D4: x | E4: x | F4: x | G4: x | H4: x
A5: 12-23 months | B5: x | C5: x | D5: x | E5: x | F5: x | G5: x | H5: x
A6: 24-59 months | B6: x | C6: x | D6: x | E6: x | F6: x | G6: x | H6: x
A7: PW: 15-19 years | C7: x | H7: x | I7: x
A8: PW: 20-29 years | C8: x | H8: x | I8: x
A9: PW: 30-39 years | C9: x | H9: x | I9: x
A10: PW: 40-49 years | C10: x | H10: x | I10: x
A11: WRA: 15-19 years | C11: x | J11: x | K11: x
A12: WRA: 20-29 years | C12: x | K12: x
A13: WRA: 30-39 years | C13: x | K13: x
A14: WRA: 40-49 years | C14: x | K14: x

Sheet IYCF odds ratios
A1: Behaviour | B1: Target population | C1: Delivery mode | D1: <1 month | E1: 1-5 months | F1: 6-11 months | G1: 12-23 months | H1: 24-59 months
A2: Odds ratio for correct breastfeeding | B2: Pregnant women | C2: Health facility | D2: 1 | E2: 1 | F2: 1 | G2: 1 | H2: 1
C3: Community | D3: 1 | E3: 1 | F3: 1 | G3: 1 | H3: 1
C4: Mass media | D4: 1 | E4: 1 | F4: 1 | G4: 1 | H4: 1
B5: <1 month | C5: Health facility | D5: 1.56 | E5: 1 | F5: 1 | G5: 1 | H5: 1
C6: Community | D6: 1.56 | E6: 1 | F6: 1 | G6: 1 | H6: 1
C7: Mass media | D7: 1 | E7: 1 | F7: 1 | G7: 1 | H7: 1
B8: 1-5 months | C8: Health facility | D8: 1 | E8: 1.56 | F8: 1 | G8: 1 | H8: 1
C9: Community | D9: 1 | E9: 1.56 | F9: 1 | G9: 1 | H9: 1
C10: Mass media | D10: 1 | E10: 1 | F10: 1 | G10: 1 | H10: 1
B11: 6-11 months | C11: Health facility | D11: 1 | E11: 1 | F11: 1.73 | G11: 1 | H11: 1
C12: Community | D12: 1 | E12: 1 | F12: 1.73 | G12: 1 | H12: 1
C13: Mass media | D13: 1 | E13: 1 | F13: 1 | G13: 1 | H13: 1
B14: 12-23 months | C14: Health facility | D14: 1 | E14: 1 | F14: 1 | G14: 1.73 | H14: 1
C15: Community | D15: 1 | E15: 1 | F15: 1 | G15: 1.73 | H15: 1
C16: Mass media | D16: 1 | E16: 1 | F16: 1 | G16: 1 | H16: 1
B17: All | C17: Mass media | D17: 1.05 | E17: 1.05 | F17: 1.05 | G17: 1.05 | H17: 1
A19: Odds ratio for stunting | B19: Pregnant women | C19: Health facility | D19: 1 | E19: 1 | F19: 1 | G19: 1 | H19: 1
C20: Community | D20: 1 | E20: 1 | F20: 1 | G20: 1 | H20: 1
C21: Mass media | D21: 1 | E21: 1 | F21: 1 | G21: 1 | H21: 1
B22: <1 month | C22: Health facility | D22: 1 | E22: 1 | F22: 1 | G22: 1 | H22: 1
C23: Community | D23: 1 | E23: 1 | F23: 1 | G23: 1 | H23: 1
C24: Mass media | D24: 1 | E24: 1 | F24: 1 | G24: 1 | H24: 1
B25: 1-5 months | C25: Health facility | D25: 1 | E25: 1 | F25: 1 | G25: 1 | H25: 1
C26: Community | D26: 1 | E26: 1 | F26: 1 | G26: 1 | H26: 1
C27: Mass media | D27: 1 | E27: 1 | F27: 1 | G27: 1 | H27: 1
B28: 6-11 months | C28: Health facility | D28: 1 | E28: 1 | F28: 1 | G28: 1 | H28: 1
C29: Community | D29: 1 | E29: 1 | F29: 1 | G29: 1 | H29: 1
C30: Mass media | D30: 1 | E30: 1 | F30: 1 | G30: 1 | H30: 1
B31: 12-23 months | C31: Health facility | D31: 1 | E31: 1 | F31: 1 | G31: 1 | H31: 1
C32: Community | D32: 1 | E32: 1 | F32: 1 | G32: 1 | H32: 1
C33: Mass media | D33: 1 | E33: 1 | F33: 1 | G33: 1 | H33: 1
B34: All | C34: Mass media | D34: 1 | E34: 1 | F34: 1 | G34: 1 | H34: 1
A36: Odds ratio for correct complementary feeding | B36: Pregnant women | C36: Health facility | D36: 1 | E36: 1 | F36: 1 | G36: 1 | H36: 1
C37: Community | D37: 1 | E37: 1 | F37: 1 | G37: 1 | H37: 1
C38: Mass media | D38: 1 | E38: 1 | F38: 1 | G38: 1 | H38: 1
B39: <1 month | C39: Health facility | D39: 1 | E39: 1 | F39: 1 | G39: 1 | H39: 1
C40: Community | D40: 1 | E40: 1 | F40: 1 | G40: 1 | H40: 1
C41: Mass media | D41: 1 | E41: 1 | F41: 1 | G41: 1 | H41: 1
B42: 1-5 months | C42: Health facility | D42: 1 | E42: 1 | F42: 1 | G42: 1 | H42: 1
...

Sheet Birth outcome risks
A1: Maternal risk factors leading to birth outcomes
C2: Term AGA | D2: Term SGA | E2: Pre-term AGA | F2: Pre-term SGA
A3: Relative risk by birth spacing
B4: First birth | C4: 1 | D4: 1 | E4: 1 | F4: 1
B5: less than 18 months | C5: 1 | D5: 1.41 | E5: 1.49 | F5: 3.03
B6: 18-23 months | C6: 1 | D6: 1.18 | E6: 1.1 | F6: 1.77
B7: 24 months or greater | C7: 1 | D7: 1 | E7: 1 | F7: 1
A9: Odds ratios for women with maternal anaemia | C9: 1 | D9: 1.53 | E9: 1.32 | F9: 1.53
A11: Risks for children who experience birth outcomes
A12: Odds ratios for conditions
B13: Stunting (HAZ-score < -2) | C13: 1 | D13: 5 | E13: 6.4 | F13: 46.5
B14: MAM (WHZ-score between -3 and -2) | C14: 1 | D14: 2.52 | E14: 1.96 | F14: 4.19
B15: SAM (WHZ-score < -3) | C15: 1 | D15: 2.52 | E15: 1.96 | F15: 4.19
A17: Relative risks of neonatal causes of death
B18: Neonatal diarrhoea | C18: 1 | D18: 1 | E18: 1 | F18: 1
B19: Neonatal sepsis | C19: 1 | D19: 2.07 | E19: 3.39 | F19: 11.89
B20: Neonatal pneumonia | C20: 1 | D20: 2.07 | E20: 3.39 | F20: 11.89
B21: Neonatal asphyxia | C21: 1 | D21: 2.07 | E21: 3.39 | F21: 11.89
B22: Neonatal prematurity | C22: 1 | D22: 1 | E22: 999.99 | F22: 999.99
B23: Neonatal tetanus | C23: 1 | D23: 1 | E23: 1 | F23: 1
B24: Neonatal congenital anomalies | C24: 1 | D24: 1 | E24: 1 | F24: 1
B25: Neonatal other | C25: 1 | D25: 1 | E25: 1 | F25: 1
A27: Lower bounds
A28: Maternal risk factors leading to birth outcomes
C29: Term AGA | D29: Term SGA | E29: Pre-term AGA | F29: Pre-term SGA
A30: Relative risk by birth spacing - lower
B31: First birth | C31: =IF(C4=1,1,C4*0.9) -> 1 | D31: =IF(D4=1,1,D4*0.9) -> 1 | E31: =IF(E4=1,1,E4*0.9) -> 1 | F31: =IF(F4=1,1,F4*0.9) -> 1
B32: less than 18 months | C32: =IF(C5=1,1,C5*0.9) -> 1 | D32: =IF(D5=1,1,D5*0.9) -> 1.269 | E32: =IF(E5=1,1,E5*0.9) -> 1.341 | F32: =IF(F5=1,1,F5*0.9) -> 2.727
B33: 18-23 months | C33: =IF(C6=1,1,C6*0.9) -> 1 | D33: =IF(D6=1,1,D6*0.9) -> 1.062 | E33: =IF(E6=1,1,E6*0.9) -> 0.99 | F33: =IF(F6=1,1,F6*0.9) -> 1.593
B34: 24 months or greater | C34: =IF(C7=1,1,C7*0.9) -> 1 | D34: =IF(D7=1,1,D7*0.9) -> 1 | E34: =IF(E7=1,1,E7*0.9) -> 1 | F34: =IF(F7=1,1,F7*0.9) -> 1
A36: Odds ratios for women with maternal anaemia - lower | C36: =IF(C9=1,1,C9*0.9) -> 1 | D36: =IF(D9=1,1,D9*0.9) -> 1.377 | E36: =IF(E9=1,1,E9*0.9) -> 1.188 | F36: =IF(F9=1,1,F9*0.9) -> 1.377
A38: Risks for children who experience birth outcomes
A39: Odds ratios for conditions - lower
B40: Stunting (HAZ-score < -2)-l | C40: =IF(C13=1,1,C13*0.9) -> 1 | D40: =IF(D13=1,1,D13*0.9) -> 4.5 | E40: =IF(E13=1,1,E13*0.9) -> 5.76 | F40: =IF(F13=1,1,F13*0.9) -> 41.85
B41: MAM (WHZ-score between -3 and -2)-l | C41: =IF(C14=1,1,C14*0.9) -> 1 | D41: =IF(D14=1,1,D14*0.9) -> 2.268 | E41: =IF(E14=1,1,E14*0.9) -> 1.764 | F41: =IF(F14=1,1,F14*0.9) -> 3.771
B42: SAM (WHZ-score < -3)-l | C42: =IF(C15=1,1,C15*0.9) -> 1 | D42: =IF(D15=1,1,D15*0.9) -> 2.268 | E42: =IF(E15=1,1,E15*0.9) -> 1.764 | F42: =IF(F15=1,1,F15*0.9) -> 3.771
A44: Relative risks of neonatal causes of death - lower
B45: Neonatal diarrhoea | C45: =IF(C18=1,1,C18*0.9) -> 1 | D45: =IF(D18=1,1,D18*0.9) -> 1 | E45: =IF(E18=1,1,E18*0.9) -> 1 | F45: =IF(F18=1,1,F18*0.9) -> 1
B46: Neonatal sepsis | C46: =IF(C19=1,1,C19*0.9) -> 1 | D46: =IF(D19=1,1,D19*0.9) -> 1.863 | E46: =IF(E19=1,1,E19*0.9) -> 3.051 | F46: =IF(F19=1,1,F19*0.9) -> 10.701
B47: Neonatal pneumonia | C47: =IF(C20=1,1,C20*0.9) -> 1 | D47: =IF(D20=1,1,D20*0.9) -> 1.863 | E47: =IF(E20=1,1,E20*0.9) -> 3.051 | F47: =IF(F20=1,1,F20*0.9) -> 10.701
...

Sheet Relative risks
A1: Relative risk of causes of death by height-for-age (stunting) distribution
A2: Stunting | B2: Cause of death | C2: HAZ status | D2: <1 month | E2: 1-5 months | F2: 6-11 months | G2: 12-23 months | H2: 24-59 months
B3: Diarrhoea | C3: Normal | D3: 1 | E3: 1 | F3: 1 | G3: 1 | H3: 1
C4: Mild | D4: 1 | E4: 1.67 | F4: 1.67 | G4: 1.67 | H4: 1.67
C5: Moderate | D5: 1 | E5: 2.38 | F5: 2.38 | G5: 2.38 | H5: 2.38
C6: High | D6: 1 | E6: 6.33 | F6: 6.33 | G6: 6.33 | H6: 6.33
B7: Pneumonia | C7: Normal | D7: 1 | E7: 1 | F7: 1 | G7: 1 | H7: 1
C8: Mild | D8: 1 | E8: 1.55 | F8: 1.55 | G8: 1.55 | H8: 1.55
C9: Moderate | D9: 1 | E9: 2.18 | F9: 2.18 | G9: 2.18 | H9: 2.18
C10: High | D10: 1 | E10: 6.39 | F10: 6.39 | G10: 6.39 | H10: 6.39
B11: Measles | C11: Normal | D11: 1 | E11: 1 | F11: 1 | G11: 1 | H11: 1
C12: Mild | D12: 1 | E12: 1 | F12: 1 | G12: 1 | H12: 1
C13: Moderate | D13: 1 | E13: 2.79 | F13: 2.79 | G13: 2.79 | H13: 2.79
C14: High | D14: 1 | E14: 6.01 | F14: 6.01 | G14: 6.01 | H14: 6.01
B15: Malaria | C15: Normal | D15: 1 | E15: 1 | F15: 1 | G15: 1 | H15: 1
C16: Mild | D16: 1 | E16: 1 | F16: 1 | G16: 1 | H16: 1
C17: Moderate | D17: 1 | E17: 1 | F17: 1 | G17: 1 | H17: 1
C18: High | D18: 1 | E18: 1 | F18: 1 | G18: 1 | H18: 1
B19: Meningitis | C19: Normal | D19: 1 | E19: 1 | F19: 1 | G19: 1 | H19: 1
C20: Mild | D20: 1 | E20: 1 | F20: 1 | G20: 1 | H20: 1
C21: Moderate | D21: 1 | E21: 1.86 | F21: 1.86 | G21: 1.86 | H21: 1.86
C22: High | D22: 1 | E22: 3.01 | F22: 3.01 | G22: 3.01 | H22: 3.01
B23: Other | C23: Normal | D23: 1 | E23: 1 | F23: 1 | G23: 1 | H23: 1
C24: Mild | D24: 1 | E24: 1 | F24: 1 | G24: 1 | H24: 1
C25: Moderate | D25: 1 | E25: 1.86 | F25: 1.86 | G25: 1.86 | H25: 1.86
C26: High | D26: 1 | E26: 3.01 | F26: 3.01 | G26: 3.01 | H26: 3.01
A28: Relative risk of causes of death by weight-for-height (wasting) distribution
A29: Wasting | B29: Cause of death | C29: WHZ status | D29: <1 month | E29: 1-5 months | F29: 6-11 months | G29: 12-23 months | H29: 24-59 months
B30: Diarrhoea | C30: Normal | D30: 1 | E30: 1 | F30: 1 | G30: 1 | H30: 1
C31: Mild | D31: 1 | E31: 1.6 | F31: 1.6 | G31: 1.6 | H31: 1.6
C32: MAM | D32: 1 | E32: 3.41 | F32: 3.41 | G32: 3.41 | H32: 3.41
C33: SAM | D33: 1 | E33: 12.33 | F33: 12.33 | G33: 12.33 | H33: 12.33
B34: Pneumonia | C34: Normal | D34: 1 | E34: 1 | F34: 1 | G34: 1 | H34: 1
C35: Mild | D35: 1 | E35: 1.92 | F35: 1.92 | G35: 1.92 | H35: 1.92
C36: MAM | D36: 1 | E36: 4.66 | F36: 4.66 | G36: 4.66 | H36: 4.66
C37: SAM | D37: 1 | E37: 9.68 | F37: 9.68 | G37: 9.68 | H37: 9.68
B38: Measles | C38: Normal | D38: 1 | E38: 1 | F38: 1 | G38: 1 | H38: 1
C39: Mild | D39: 1 | E39: 1 | F39: 1 | G39: 1 | H39: 1
C40: MAM | D40: 1 | E40: 2.58 | F40: 2.58 | G40: 2.58 | H40: 2.58
C41: SAM | D41: 1 | E41: 9.63 | F41: 9.63 | G41: 9.63 | H41: 9.63
...

Sheet Odds ratios
A1: Odds ratios for stunting
A2: Condition | C2: <1 month | D2: 1-5 months | E2: 6-11 months | F2: 12-23 months | G2: 24-59 months
B3: Given previous stunting (HAZ < -2 in previous age band) | C3: N/A | D3: 45 | E3: 361.6 | F3: 174.7 | G3: 174.7
B4: Diarrhoea (per additional episode) | C4: 1.025 | D4: 1.025 | E4: 1.025 | F4: 1.025 | G4: 1.025
A5: By program
B6: Public provision of complementary foods | C6: 1 | D6: 1 | E6: 0.64 | F6: 0.64 | G6: 1
B7: Lipid-based nutrition supplements | C7: 1 | D7: 1 | E7: 0.88 | F7: 0.88 | G7: 1
B8: Small quantity lipid-based nutrition supplements | C8: 1 | D8: 1 | E8: 0.88 | F8: 0.88 | G8: 1
B9: Zinc supplementation | C9: 1 | D9: 1 | E9: 1 | F9: 1 | G9: 1
A11: Odds ratios for correct breastfeeding by program
B12: Kangaroo mother care | C12: 1.5 | D12: 1.39 | E12: 1 | F12: 1 | G12: 1
A14: Other odds ratios
A15: Wasting | B15: For SAM per additional episode of diarrhoea | C15: 1.025 | D15: 1.025 | E15: 1.025 | F15: 1.025 | G15: 1.025
B16: For MAM per additional episode of diarrhoea | C16: 1.025 | D16: 1.025 | E16: 1.025 | F16: 1.025 | G16: 1.025
A17: Anaemia | B17: For anaemia per additional episode of severe diarrhoea | C17: 1 | D17: 1 | E17: 1 | F17: 1 | G17: 1
A19: Odds ratios for optimal birth spacing by program
C20: WRA: 15-19 years | D20: WRA: 20-29 years | E20: WRA: 30-39 years | F20: WRA: 40-49 years
B21: Family planning | C21: 1.52 | D21: 1 | E21: 1 | F21: 1
A23: Lower bounds
A24: Odds ratios for stunting
A25: Condition | C25: <1 month | D25: 1-5 months | E25: 6-11 months | F25: 12-23 months | G25: 24-59 months
B26: Given previous stunting (HAZ < -2 in previous age band) - lower | C26: N/A | D26: =D3*0.9 -> 40.5 | E26: =E3*0.9 -> 325.44 | F26: =F3*0.9 -> 157.23 | G26: =G3*0.9 -> 157.23
B27: Diarrhoea (per additional episode) - lower | C27: =IF(C4=1,1,C4*0.9) -> 0.9225 | D27: =IF(D4=1,1,D4*0.9) -> 0.9225 | E27: =IF(E4=1,1,E4*0.9) -> 0.9225 | F27: =IF(F4=1,1,F4*0.9) -> 0.9225 | G27: =IF(G4=1,1,G4*0.9) -> 0.9225
A28: By program - lower
B29: Public provision of complementary foods - lower | C29: =IF(C6=1,1,C6*0.9) -> 1 | D29: =IF(D6=1,1,D6*0.9) -> 1 | E29: 0.44 | F29: 0.44 | G29: =IF(G6=1,1,G6*0.9) -> 1
B30: Lipid-based nutrition supplements - lower | C30: =IF(C7=1,1,C7*0.9) -> 1 | D30: =IF(D7=1,1,D7*0.9) -> 1 | E30: 0.85 | F30: 0.85 | G30: =IF(G7=1,1,G7*0.9) -> 1
B31: Small quantity lipid-based nutrition supplements - lower | C31: =IF(C8=1,1,C8*0.9) -> 1 | D31: =IF(D8=1,1,D8*0.9) -> 1 | E31: 0.85 | F31: 0.85 | G31: =IF(G8=1,1,G8*0.9) -> 1
B32: Zinc supplementation - lower | C32: =IF(C9=1,1,C9*0.9) -> 1 | D32: =IF(D9=1,1,D9*0.9) -> 1 | E32: =IF(E9=1,1,E9*0.9) -> 1 | F32: =IF(F9=1,1,F9*0.9) -> 1 | G32: =IF(G9=1,1,G9*0.9) -> 1
A34: Odds ratios for correct breastfeeding by program - lower
B35: Kangaroo mother care - lower | C35: 1.26 | D35: 1.11 | E35: 1 | F35: 1 | G35: 1
A37: Other odds ratios
A38: Wasting | B38: For SAM per additional episode of diarrhoea - lower | C38: =IF(C15=1,1,C15*0.9) -> 0.9225 | D38: =IF(D15=1,1,D15*0.9) -> 0.9225 | E38: =IF(E15=1,1,E15*0.9) -> 0.9225 | F38: =IF(F15=1,1,F15*0.9) -> 0.9225 | G38: =IF(G15=1,1,G15*0.9) -> 0.9225
B39: For MAM per additional episode of diarrhoea - lower | C39: =IF(C16=1,1,C16*0.9) -> 0.9225 | D39: =IF(D16=1,1,D16*0.9) -> 0.9225 | E39: =IF(E16=1,1,E16*0.9) -> 0.9225 | F39: =IF(F16=1,1,F16*0.9) -> 0.9225 | G39: =IF(G16=1,1,G16*0.9) -> 0.9225
A40: Anaemia | B40: For anaemia per additional episode of severe diarrhoea - lower | C40: =IF(C17=1,1,C17*0.9) -> 1 | D40: =IF(D17=1,1,D17*0.9) -> 1 | E40: =IF(E17=1,1,E17*0.9) -> 1 | F40: =IF(F17=1,1,F17*0.9) -> 1 | G40: =IF(G17=1,1,G17*0.9) -> 1
A42: Odds ratios for optimal birth spacing by program - lower
C43: WRA: 15-19 years | D43: WRA: 20-29 years | E43: WRA: 30-39 years | F43: WRA: 40-49 years
B44: Family planning - lower | C44: =C21*0.9 -> 1.368 | D44: 1 | E44: 1 | F44: 1
A46: Upper bounds
A47: Odds ratios for stunting
A48: Condition | C48: <1 month | D48: 1-5 months | E48: 6-11 months | F48: 12-23 months | G48: 24-59 months
...

Sheet Programs birth outcomes
A1: Program | C1: Pre-term SGA | D1: Term SGA | E1: Pre-term AGA | F1: Term AGA
A2: Balanced energy-protein supplementation | B2: effectiveness | C2: 0.29 | D2: 0.29 | E2: 0 | F2: 0
B3: affected fraction | C3: 1 | D3: 1 | E3: 1 | F3: 1
A4: IFAS for pregnant women (community) | B4: effectiveness | C4: 0.61 | D4: 0.61 | E4: 0 | F4: 0
B5: affected fraction | C5: 1 | D5: 1 | E5: 1 | F5: 1
A6: IFAS for pregnant women (health facility) | B6: effectiveness | C6: 0.61 | D6: 0.61 | E6: 0 | F6: 0
B7: affected fraction | C7: 1 | D7: 1 | E7: 1 | F7: 1
A8: IPTp | B8: effectiveness | C8: 0.35 | D8: 0.35 | E8: 0 | F8: 0
B9: affected fraction | C9: 1 | D9: 1 | E9: 0 | F9: 0
A10: Long-lasting insecticide-treated bednets | B10: effectiveness | C10: 0.35 | D10: 0.35 | E10: 0 | F10: 0
B11: affected fraction | C11: 1 | D11: 1 | E11: 0 | F11: 0
A12: Multiple micronutrient supplementation | B12: effectiveness | C12: =1-0.93*0.39 -> 0.6373 | D12: =1-0.93*0.39 -> 0.6373 | E12: 0 | F12: 0
B13: affected fraction | C13: 1 | D13: 1 | E13: 1 | F13: 1
A15: Lower bounds
A16: Program | C16: Pre-term SGA | D16: Term SGA | E16: Pre-term AGA | F16: Term AGA
A17: Balanced energy-protein supplementation | B17: effectiveness | C17: =1-0.94 -> 0.06 | D17: =1-0.94 -> 0.06 | E17: =E2*0.9 -> 0 | F17: =F2*0.9 -> 0
B18: affected fraction | C18: 1 | D18: 1 | E18: 1 | F18: 1
A19: IFAS for pregnant women (community) | B19: effectiveness | C19: =1-0.86 -> 0.14 | D19: =1-0.86 -> 0.14 | E19: =E4*0.9 -> 0 | F19: =F4*0.9 -> 0
B20: affected fraction | C20: 1 | D20: 1 | E20: 1 | F20: 1
A21: IFAS for pregnant women (health facility) | B21: effectiveness | C21: =1-0.86 -> 0.14 | D21: =1-0.86 -> 0.14 | E21: =E6*0.9 -> 0 | F21: =F6*0.9 -> 0
B22: affected fraction | C22: 1 | D22: 1 | E22: 1 | F22: 1
A23: IPTp | B23: effectiveness | C23: =1-0.77 -> 0.23 | D23: =1-0.77 -> 0.23 | E23: =E10*0.9 -> 0 | F23: =F10*0.9 -> 0
B24: affected fraction | C24: 1 | D24: 1 | E24: 1 | F24: 1
A25: Long-lasting insecticide-treated bednets | B25: effectiveness | C25: =1-0.77 -> 0.23 | D25: =1-0.77 -> 0.23 | E25: =E10*0.9 -> 0 | F25: =F10*0.9 -> 0
B26: affected fraction | C26: 1 | D26: 1 | E26: 1 | F26: 1
A27: Multiple micronutrient supplementation | B27: effectiveness | C27: =1-0.98*0.86 -> 0.1572 | D27: =1-0.98*0.86 -> 0.1572 | E27: =E12*0.9 -> 0 | F27: =F12*0.9 -> 0
B28: affected fraction | C28: 1 | D28: 1 | E28: 1 | F28: 1
A30: Upper bounds
A31: Program | C31: Pre-term SGA | D31: Term SGA | E31: Pre-term AGA | F31: Term AGA
A32: Balanced energy-protein supplementation | B32: effectiveness | C32: =1-0.54 -> 0.46 | D32: =1-0.54 -> 0.46 | E32: =E2*1.1 -> 0 | F32: =F2*1.1 -> 0
B33: affected fraction | C33: 1 | D33: 1 | E33: 1 | F33: 1
A34: IFAS for pregnant women (community) | B34: effectiveness | C34: =1-0.17 -> 0.83 | D34: =1-0.17 -> 0.83 | E34: =E4*1.1 -> 0 | F34: =F4*1.1 -> 0
B35: affected fraction | C35: 1 | D35: 1 | E35: 1 | F35: 1
A36: IFAS for pregnant women (health facility) | B36: effectiveness | C36: =1-0.17 -> 0.83 | D36: =1-0.17 -> 0.83 | E36: =E6*1.1 -> 0 | F36: =F6*1.1 -> 0
B37: affected fraction | C37: 1 | D37: 1 | E37: 1 | F37: 1
A38: IPTp | B38: effectiveness | C38: =1-0.55 -> 0.45 | D38: =1-0.55 -> 0.45 | E38: =E8*1.1 -> 0 | F38: =F8*1.1 -> 0
B39: affected fraction | C39: 1 | D39: 1 | E39: 1 | F39: 1
A40: Long-lasting insecticide-treated bednets | B40: effectiveness | C40: =1-0.55 -> 0.45 | D40: =1-0.55 -> 0.45 | E40: =E10*1.1 -> 0 | F40: =F10*1.1 -> 0
B41: affected fraction | C41: 1 | D41: 1 | E41: 1 | F41: 1
A42: Multiple micronutrient supplementation | B42: effectiveness | C42: =1-0.88*0.17 -> 0.8504 | D42: =1-0.88*0.17 -> 0.8504 | E42: =E12*1.1 -> 0 | F42: =F12*1.1 -> 0
...

Sheet Programs anaemia
C1: <1 month | D1: 1-5 months | E1: 6-11 months | F1: 12-23 months | G1: 24-59 months | H1: WRA: 15-19 years | I1: WRA: 20-29 years | J1: WRA: 30-39 years | K1: WRA: 40-49 years | L1: PW: 15-19 years | M1: PW: 20-29 years | N1: PW: 30-39 years | O1: PW: 40-49 years
A2: Relative risks of anaemia when receiving intervention
B3: Delayed cord clamping | C3: 0.53 | D3: 0.53 | E3: 1 | F3: 1 | G3: 1 | H3: 1 | I3: 1 | J3: 1 | K3: 1 | L3: 1 | M3: 1 | N3: 1 | O3: 1
B4: IFAS (community) | C4: 1 | D4: 1 | E4: 1 | F4: 1 | G4: 1 | H4: 0.73 | I4: 0.73 | J4: 0.73 | K4: 0.73 | L4: 1 | M4: 1 | N4: 1 | O4: 1
B5: IFAS (health facility) | C5: 1 | D5: 1 | E5: 1 | F5: 1 | G5: 1 | H5: 0.73 | I5: 0.73 | J5: 0.73 | K5: 0.73 | L5: 1 | M5: 1 | N5: 1 | O5: 1
B6: IFAS (retailer) | C6: 1 | D6: 1 | E6: 1 | F6: 1 | G6: 1 | H6: 0.73 | I6: 0.73 | J6: 0.73 | K6: 0.73 | L6: 1 | M6: 1 | N6: 1 | O6: 1
B7: IFAS (school) | C7: 1 | D7: 1 | E7: 1 | F7: 1 | G7: 1 | H7: 0.73 | I7: 0.73 | J7: 0.73 | K7: 0.73 | L7: 1 | M7: 1 | N7: 1 | O7: 1
B8: IFAS for pregnant women (community) | C8: 1 | D8: 1 | E8: 1 | F8: 1 | G8: 1 | H8: 1 | I8: 1 | J8: 1 | K8: 1 | L8: 0.51 | M8: 0.51 | N8: 0.51 | O8: 0.51
B9: IFAS for pregnant women (health facility) | C9: 1 | D9: 1 | E9: 1 | F9: 1 | G9: 1 | H9: 1 | I9: 1 | J9: 1 | K9: 1 | L9: 0.51 | M9: 0.51 | N9: 0.51 | O9: 0.51
B10: IPTp | C10: 1 | D10: 1 | E10: 1 | F10: 1 | G10: 1 | H10: 1 | I10: 1 | J10: 1 | K10: 1 | L10: 0.9 | M10: 0.9 | N10: 0.9 | O10: 0.9
B11: Lipid-based nutrition supplements | C11: 1 | D11: 1 | E11: 0.69 | F11: 0.69 | G11: 1 | H11: 1 | I11: 1 | J11: 1 | K11: 1 | L11: 1 | M11: 1 | N11: 1 | O11: 1
B12: Long-lasting insecticide-treated bednets | C12: 0.83 | D12: 0.83 | E12: 0.83 | F12: 0.83 | G12: 0.83 | H12: 0.83 | I12: 0.83 | J12: 0.83 | K12: 0.83 | L12: 0.83 | M12: 0.83 | N12: 0.83 | O12: 0.83
B13: Micronutrient powders | C13: 1 | D13: 1 | E13: 0.69 | F13: 0.69 | G13: 0.69 | H13: 1 | I13: 1 | J13: 1 | K13: 1 | L13: 1 | M13: 1 | N13: 1 | O13: 1
B14: Multiple micronutrient supplementation | C14: 1 | D14: 1 | E14: 1 | F14: 1 | G14: 1 | H14: 1 | I14: 1 | J14: 1 | K14: 1 | L14: 0.51 | M14: 0.51 | N14: 0.51 | O14: 0.51
B15: Small quantity lipid-based nutrition supplements | C15: 1 | D15: 1 | E15: 0.36 | F15: 0.36 | G15: 1 | H15: 1 | I15: 1 | J15: 1 | K15: 1 | L15: 1 | M15: 1 | N15: 1 | O15: 1
A17: Odds ratios of being anaemic when covered by intervention
B18: IFA fortification of maize | C18: 1 | D18: 1 | E18: 1 | F18: 1 | G18: 1 | H18: 1 | I18: 1 | J18: 1 | K18: 1 | L18: 1 | M18: 1 | N18: 1 | O18: 1
B19: IFA fortification of rice | C19: 1 | D19: 1 | E19: =0.72 -> 0.72 | F19: =0.72 -> 0.72 | G19: =0.72 -> 0.72 | H19: =0.72 -> 0.72 | I19: =0.72 -> 0.72 | J19: =0.72 -> 0.72 | K19: =0.72 -> 0.72 | L19: =0.72 -> 0.72 | ... O19: =0.72 -> 0.72
B20: IFA fortification of wheat flour | C20: 1 | D20: 1 | E20: 1 | F20: 1 | G20: 1 | H20: 1 | I20: 1 | J20: 1 | K20: 1 | L20: 1 | M20: 1 | N20: 1 | O20: 1
B21: Iron and iodine fortification of salt | C21: 1 | D21: 1 | E21: 0.8 | F21: 0.8 | G21: 0.8 | H21: 0.8 | I21: 0.8 | J21: 0.8 | K21: 0.8 | L21: 0.8 | M21: 0.8 | N21: 0.8 | O21: 0.8
A23: Lower bounds
C24: <1 month | D24: 1-5 months | E24: 6-11 months | F24: 12-23 months | G24: 24-59 months | H24: WRA: 15-19 years | I24: WRA: 20-29 years | J24: WRA: 30-39 years | K24: WRA: 40-49 years | L24: PW: 15-19 years | M24: PW: 20-29 years | N24: PW: 30-39 years | O24: PW: 40-49 years
