Workbook
Name abortion: 'Entradas de población-año base'!$C$38
Name abortion: '[1]Baseline year population inputs'!$C$41
Name abortion: '[1]Baseline year population inputs'!$C$41
Name abortion: 'Entradas de población-año base'!$C$41
Name comm_deliv: '[1]Treatment of SAM'!$D$3
Name comm_deliv: '[1]Treatment of SAM'!$D$3
Name comm_deliv: 'Tratamiento de la MAS'!$D$3
Name diarrhoea_1_5mo: '[1]Baseline year population inputs'!$C$52
Name diarrhoea_1_5mo: '[1]Baseline year population inputs'!$C$52
Name diarrhoea_1_5mo: 'Entradas de población-año base'!$C$52
Name diarrhoea_12_23mo: '[1]Baseline year population inputs'!$C$54
Name diarrhoea_12_23mo: '[1]Baseline year population inputs'!$C$54
Name diarrhoea_12_23mo: 'Entradas de población-año base'!$C$54
Name diarrhoea_1mo: '[1]Baseline year population inputs'!$C$51
Name diarrhoea_1mo: '[1]Baseline year population inputs'!$C$51
Name diarrhoea_1mo: 'Entradas de población-año base'!$C$51
Name diarrhoea_24_59mo: '[1]Baseline year population inputs'!$C$55
Name diarrhoea_24_59mo: '[1]Baseline year population inputs'!$C$55
Name diarrhoea_24_59mo: 'Entradas de población-año base'!$C$55
Name diarrhoea_6_11mo: '[1]Baseline year population inputs'!$C$53
Name diarrhoea_6_11mo: '[1]Baseline year population inputs'!$C$53
Name diarrhoea_6_11mo: 'Entradas de población-año base'!$C$53
Name end_year: '[1]Baseline year population inputs'!$C$4
Name end_year: '[1]Baseline year population inputs'!$C$4
Name end_year: 'Entradas de población-año base'!$C$4
Name famplan_unmet_need: '[1]Baseline year population inputs'!$C$13
Name famplan_unmet_need: '[1]Baseline year population inputs'!$C$13
Name famplan_unmet_need: 'Entradas de población-año base'!$C$13
Name food_insecure: '[1]Baseline year population inputs'!$C$8
Name food_insecure: '[1]Baseline year population inputs'!$C$8
Name food_insecure: 'Entradas de población-año base'!$C$8
Name frac_children_health_facility: '[1]Baseline year population inputs'!$C$12
Name frac_children_health_facility: '[1]Baseline year population inputs'!$C$12
Name frac_children_health_facility: 'Entradas de población-año base'!$C$12
Name frac_diarrhea_severe: '[1]Baseline year population inputs'!$C$58
Name frac_diarrhea_severe: '[1]Baseline year population inputs'!$C$58
Name frac_diarrhea_severe: 'Entradas de población-año base'!$C$58
Name frac_maize: '[1]Baseline year population inputs'!$C$19
Name frac_maize: '[1]Baseline year population inputs'!$C$19
Name frac_maize: 'Entradas de población-año base'!$C$19
Name frac_malaria_risk: '[1]Baseline year population inputs'!$C$9
Name frac_malaria_risk: '[1]Baseline year population inputs'!$C$9
Name frac_malaria_risk: 'Entradas de población-año base'!$C$9
Name frac_mam_1_5months: '[1]Nutritional status distribution'!$D$10
Name frac_mam_1_5months: '[1]Nutritional status distribution'!$D$10
Name frac_mam_1_5months: 'Distribución estado nutricional'!$D$10
Name frac_mam_12_23months: '[1]Nutritional status distribution'!$F$10
Name frac_mam_12_23months: '[1]Nutritional status distribution'!$F$10
Name frac_mam_12_23months: 'Distribución estado nutricional'!$F$10
Name frac_mam_1month: '[1]Nutritional status distribution'!$C$10
Name frac_mam_1month: '[1]Nutritional status distribution'!$C$10
Name frac_mam_1month: 'Distribución estado nutricional'!$C$10
Name frac_mam_24_59months: '[1]Nutritional status distribution'!$G$10
Name frac_mam_24_59months: '[1]Nutritional status distribution'!$G$10
Name frac_mam_24_59months: 'Distribución estado nutricional'!$G$10
Name frac_mam_6_11months: '[1]Nutritional status distribution'!$E$10
Name frac_mam_6_11months: '[1]Nutritional status distribution'!$E$10
Name frac_mam_6_11months: 'Distribución estado nutricional'!$E$10
Name frac_MAMtoSAM: '[1]Baseline year population inputs'!#REF!
Name frac_MAMtoSAM: '[1]Baseline year population inputs'!#REF!

Sheet Entradas de población-año base
A1: Datos del año de referencia | B1: Field | C1: Datos
A2: Años de proyección
B3: Año de referencia (año de inicio de la proyección) | C3: 2017
B4: Año final | C4: 2030
A6: Datos poblacionales
B7: Población infantil menor de 5 años | C7: 9862402
B8: Porcentaje de población con inseguridad alimentaria (pobre por defecto) | C8: 0.282
B9: Porcentaje de población con riesgo de malaria | C9: 1
B10: Asistencia a la escuela (porcentaje de mujeres de 15 a 19 años) | C10: 0.23
B11: Porcentaje de mujeres embarazadas que acuden a un centro de salud | C11: 0.51
B12: Porcentaje de niños que acuden a un centro de salud | C12: 0.37
B13: Necesidad insatisfecha de planificación familiar | C13: 0.221
A15: Alimento
B16: Fracción de agricultura de subsistencia | C16: 0.3
B17: Fracción que consume arroz como principal alimento básico | C17: 0.1
B18: Fracción que consume trigo como principal alimento básico | C18: 0.1
B19: Fracción que consume maíz como principal alimento básico | C19: 0.8
B20: Fracción de otros alimentos básicos como alimento principal | C20: =1-frac_rice-frac_wheat-frac_maize -> 0
A22: Distribución de edad de las mujeres embarazadas
B23: Porcentaje de mujeres embarazadas de 15 a 19 años | C23: 0.127
B24: Porcentaje de mujeres embarazadas de 20 a 29 años | C24: 0.452
B25: Porcentaje de mujeres embarazadas de 30 a 39 años | C25: 0.334
B26: Porcentaje de mujeres embarazadas de 40 a 49 años | C26: 0.087
A28: Espaciamiento entre los nacimientos
B29: El primer nacimiento | C29: 0.208
B30: menos de 18 meses | C30: 0.637
B31: 18-23 meses | C31: 0.119
B32: 24 meses o más | C32: 0.036
B33: Total (debe ser el 100%) | C33: =SUM(C29:C32) -> 1
A35: Mortalidad y factores de riesgo en el año de referencia
A36: Mortalidad
B37: Mortalidad neonatal (por cada 1.000 nacidos vivos) | C37: 25
B38: Mortalidad infantil (por cada 1.000 nacidos vivos) | C38: 43
B39: Mortalidad de menores de 5 años (por cada 1.000 nacidos vivos) | C39: 67
B40: Mortalidad materna (por cada 1.000 nacidos vivos) | C40: 4.01
B41: Fracción de embarazos que terminan en aborto espontáneo | C41: 0.13
B42: Nacidos muertos (por cada 1.000 nacimientos totales) | C42: 22.4
A44: Distribución del desenlace del nacimiento
B45: Prematuro PEG (pequeño para la edad gestacional) | C45: 0.031
B46: Prematuro AEG (adecuado para edad gestacional) | C46: 0.109
...

Sheet Proyecciones demográficas
A1: año | B1: Número de nacimientos | C1: WRA: 15-19 años (mujeres en edad reproductiva) | D1: WRA: 20-29 años (mujeres en edad reproductiva) | E1: WRA: 30-39 años (mujeres en edad reproductiva) | F1: WRA: 40-49 años (mujeres en edad reproductiva) | G1: Total mujeres en edad reproductiva | H1: Estimación de mujeres embarazadas | I1: mujeres en edad reproductiva no embarazadas
A2: =start_year -> 2017 | B2: 2110000 | C2: 3032037 | D2: 4756743 | E2: 3406589 | F2: 2174712 | G2: =C2+D2+E2+F2 -> 13370081 | H2: =(B2 + stillbirth*B2/(1000-stillbirth))/(1-abortion) -> 2480858.6 | I2: =G2-H2 -> 10889222
A3: =IF($A$2+ROW(A3)-2<=end_year,A2+1,"") -> 2018 | B3: 2150000 | C3: 3164674 | D3: 4882700 | E3: 3520083 | F3: 2275309 | G3: =C3+D3+E3+F3 -> 13842766 | H3: =(B3 + stillbirth*B3/(1000-stillbirth))/(1-abortion) -> 2527889.1 | I3: =G3-H3 -> 11314877
A4: =IF($A$2+ROW(A4)-2<=end_year,A3+1,"") -> 2019 | B4: 2200000 | C4: 3296354 | D4: 5018666 | E4: 3634703 | F4: 2379017 | G4: =C4+D4+E4+F4 -> 14328740 | H4: =(B4 + stillbirth*B4/(1000-stillbirth))/(1-abortion) -> 2586677.2 | I4: =G4-H4 -> 11742063
A5: =IF($A$2+ROW(A5)-2<=end_year,A4+1,"") -> 2020 | B5: 2240000 | C5: 3418969 | D5: 5168014 | E5: 3750324 | F5: 2484409 | G5: =C5+D5+E5+F5 -> 14821716 | H5: =(B5 + stillbirth*B5/(1000-stillbirth))/(1-abortion) -> 2633707.7 | I5: =G5-H5 -> 12188008
A6: =IF($A$2+ROW(A6)-2<=end_year,A5+1,"") -> 2021 | B6: 2280000 | C6: 3532758 | D6: 5332455 | E6: 3869436 | F6: 2592003 | G6: =C6+D6+E6+F6 -> 15326652 | H6: =(B6 + stillbirth*B6/(1000-stillbirth))/(1-abortion) -> 2680738.2 | I6: =G6-H6 -> 12645914
A7: =IF($A$2+ROW(A7)-2<=end_year,A6+1,"") -> 2022 | B7: 2330000 | C7: 3637390 | D7: 5508952 | E7: 3990560 | F7: 2701259 | G7: =C7+D7+E7+F7 -> 15838161 | H7: =(B7 + stillbirth*B7/(1000-stillbirth))/(1-abortion) -> 2739526.3 | I7: =G7-H7 -> 13098635
A8: =IF($A$2+ROW(A8)-2<=end_year,A7+1,"") -> 2023 | B8: 2380000 | C8: 3737403 | D8: 5696990 | E8: 4112898 | F8: 2811667 | G8: =C8+D8+E8+F8 -> 16358958 | H8: =(B8 + stillbirth*B8/(1000-stillbirth))/(1-abortion) -> 2798314.4 | I8: =G8-H8 -> 13560644
A9: =IF($A$2+ROW(A9)-2<=end_year,A8+1,"") -> 2024 | B9: 2420000 | C9: 3840674 | D9: 5895615 | E9: 4235117 | F9: 2922818 | G9: =C9+D9+E9+F9 -> 16894224 | H9: =(B9 + stillbirth*B9/(1000-stillbirth))/(1-abortion) -> 2845344.9 | I9: =G9-H9 -> 14048879
A10: =IF($A$2+ROW(A10)-2<=end_year,A9+1,"") -> 2025 | B10: 2480000 | C10: 3951644 | D10: 6103745 | E10: 4356516 | F10: 3034340 | G10: =C10+D10+E10+F10 -> 17446245 | H10: =(B10 + stillbirth*B10/(1000-stillbirth))/(1-abortion) -> 2915890.7 | I10: =G10-H10 -> 14530354
A11: =IF($A$2+ROW(A11)-2<=end_year,A10+1,"") -> 2026 | B11: 2530000 | C11: 4065313 | D11: 6319831 | E11: 4477188 | F11: 3144612 | G11: =C11+D11+E11+F11 -> 18006944 | H11: =(B11 + stillbirth*B11/(1000-stillbirth))/(1-abortion) -> 2974678.8 | I11: =G11-H11 -> 15032265
A12: =IF($A$2+ROW(A12)-2<=end_year,A11+1,"") -> 2027 | B12: 2580000 | C12: 4185562 | D12: 6545116 | E12: 4597739 | F12: 3255252 | G12: =C12+D12+E12+F12 -> 18583669 | H12: =(B12 + stillbirth*B12/(1000-stillbirth))/(1-abortion) -> 3033466.9 | I12: =G12-H12 -> 15550202
A13: =IF($A$2+ROW(A13)-2<=end_year,A12+1,"") -> 2028 | B13: 2630000 | C13: 4309237 | D13: 6776307 | E13: 4722286 | F13: 3366750 | G13: =C13+D13+E13+F13 -> 19174580 | H13: =(B13 + stillbirth*B13/(1000-stillbirth))/(1-abortion) -> 3092255 | I13: =G13-H13 -> 16082325
A14: =IF($A$2+ROW(A14)-2<=end_year,A13+1,"") -> 2029 | B14: 2690000 | C14: 4430738 | D14: 7008703 | E14: 4856898 | F14: 3479917 | G14: =C14+D14+E14+F14 -> 19776256 | H14: =(B14 + stillbirth*B14/(1000-stillbirth))/(1-abortion) -> 3162800.8 | I14: =G14-H14 -> 16613455
A15: =IF($A$2+ROW(A15)-2<=end_year,A14+1,"") -> 2030 | B15: 2740000 | C15: 4546624 | D15: 7239465 | E15: 5005361 | F15: 3595278 | G15: =C15+D15+E15+F15 -> 20386728 | H15: =(B15 + stillbirth*B15/(1000-stillbirth))/(1-abortion) -> 3221588.9 | I15: =G15-H15 -> 17165139
A16: =IF($A$2+ROW(A16)-2<=end_year,A15+1,"") | G16: =C16+D16+E16+F16 -> 0 | H16: =(B16 + stillbirth*B16/(1000-stillbirth))/(1-abortion) -> 0 | I16: =G16-H16 -> 0
A17: =IF($A$2+ROW(A17)-2<=end_year,A16+1,"") | G17: =C17+E17+#REF!+F17 -> #REF! | H17: =(B17 + stillbirth*B17/(1000-stillbirth))/(1-abortion) -> 0 | I17: =G17-H17 -> #REF!
A18: =IF($A$2+ROW(A18)-2<=end_year,A17+1,"") | G18: =C18+D18+E18+F18 -> 0 | H18: =(B18 + stillbirth*B18/(1000-stillbirth))/(1-abortion) -> 0 | I18: =G18-H18 -> 0
A19: =IF($A$2+ROW(A19)-2<=end_year,A18+1,"") | G19: =C19+D19+E19+F19 -> 0 | H19: =(B19 + stillbirth*B19/(1000-stillbirth))/(1-abortion) -> 0 | I19: =G19-H19 -> 0
A20: =IF($A$2+ROW(A20)-2<=end_year,A19+1,"") | G20: =C20+D20+E20+F20 -> 0 | H20: =(B20 + stillbirth*B20/(1000-stillbirth))/(1-abortion) -> 0 | I20: =G20-H20 -> 0
A21: =IF($A$2+ROW(A21)-2<=end_year,A20+1,"") | G21: =C21+D21+E21+F21 -> 0 | H21: =(B21 + stillbirth*B21/(1000-stillbirth))/(1-abortion) -> 0 | I21: =G21-H21 -> 0
A22: =IF($A$2+ROW(A22)-2<=end_year,A21+1,"") | G22: =C22+D22+E22+F22 -> 0 | H22: =(B22 + stillbirth*B22/(1000-stillbirth))/(1-abortion) -> 0 | I22: =G22-H22 -> 0
A23: =IF($A$2+ROW(A23)-2<=end_year,A22+1,"") | G23: =C23+D23+E23+F23 -> 0 | H23: =(B23 + stillbirth*B23/(1000-stillbirth))/(1-abortion) -> 0 | I23: =G23-H23 -> 0
A24: =IF($A$2+ROW(A24)-2<=end_year,A23+1,"") | G24: =C24+D24+E24+F24 -> 0 | H24: =(B24 + stillbirth*B24/(1000-stillbirth))/(1-abortion) -> 0 | I24: =G24-H24 -> 0
A25: =IF($A$2+ROW(A25)-2<=end_year,A24+1,"") | G25: =C25+D25+E25+F25 -> 0 | H25: =(B25 + stillbirth*B25/(1000-stillbirth))/(1-abortion) -> 0 | I25: =G25-H25 -> 0
A26: =IF($A$2+ROW(A26)-2<=end_year,A25+1,"") | G26: =C26+D26+E26+F26 -> 0 | H26: =(B26 + stillbirth*B26/(1000-stillbirth))/(1-abortion) -> 0 | I26: =G26-H26 -> 0
A27: =IF($A$2+ROW(A27)-2<=end_year,A26+1,"") | G27: =C27+D27+E27+F27 -> 0 | H27: =(B27 + stillbirth*B27/(1000-stillbirth))/(1-abortion) -> 0 | I27: =G27-H27 -> 0
A28: =IF($A$2+ROW(A28)-2<=end_year,A27+1,"") | G28: =C28+D28+E28+F28 -> 0 | H28: =(B28 + stillbirth*B28/(1000-stillbirth))/(1-abortion) -> 0 | I28: =G28-H28 -> 0
A29: =IF($A$2+ROW(A29)-2<=end_year,A28+1,"") | G29: =C29+D29+E29+F29 -> 0 | H29: =(B29 + stillbirth*B29/(1000-stillbirth))/(1-abortion) -> 0 | I29: =G29-H29 -> 0
... A40: =IF($A$2+ROW(A40)-2<=end_year,A39+1,"") | G40: =C40+D40+E40+F40 -> 0 | H40: =(B40 + stillbirth*B40/(1000-stillbirth))/(1-abortion) -> 0 | I40: =G40-H40 -> 0

Sheet Causas de muerte
A1: ="Porcentaje de muertes en el año de referencia ("&start_year&") atribuible a la causa" -> Porcentaje de muertes en el año de referencia (2017) atribuible a la causa
A2: Neonatal | B2: Causas | C2: <1 mes
B3: Diarrea neonatal | C3: 0.0027
B4: Sepsis neonatal | C4: 0.1966
B5: Neumonía neonatal | C5: 0.0621
B6: Asfixia neonatal | C6: 0.2929
B7: Prematuridad neonatal | C7: 0.2471
B8: Tétanos neonatal | C8: 0.0048
B9: Anomalías congénitas neonatales | C9: 0.132
B10: Neonatal otros | C10: 0.0618
B11: Total (debe ser el 100%) | C11: =SUM(C3:C10) -> 1
A13: Niños | B13: Causas | C13: 1-5 meses | D13: 6-11 meses | E13: 12-23 meses | F13: 24-59 meses
B14: Diarrea | C14: 0.1368 | D14: 0.1368 | E14: 0.1368 | F14: 0.1368
B15: Neumonía | C15: 0.2066 | D15: 0.2066 | E15: 0.2066 | F15: 0.2066
B16: Meningitis | C16: 0.0211 | D16: 0.0211 | E16: 0.0211 | F16: 0.0211
B17: Sarampión | C17: 0.0075 | D17: 0.0075 | E17: 0.0075 | F17: 0.0075
B18: Malaria | C18: 0.0862 | D18: 0.0862 | E18: 0.0862 | F18: 0.0862
B19: Tosferina | C19: 0.0286 | D19: 0.0286 | E19: 0.0286 | F19: 0.0286
B20: SIDA | C20: 0.0153 | D20: 0.0153 | E20: 0.0153 | F20: 0.0153
B21: Lesión | C21: 0.1359 | D21: 0.1359 | E21: 0.1359 | F21: 0.1359
B22: Otro | C22: 0.362 | D22: 0.362 | E22: 0.362 | F22: 0.362
B23: Total (debe ser el 100%) | C23: =SUM(C14:C22) -> 1 | D23: =SUM(D14:D22) -> 1 | E23: =SUM(E14:E22) -> 1 | F23: =SUM(F14:F22) -> 1
A25: Mujeres embarazadas | B25: Causas | C25: Mujeres embarazadas
B26: Hemorragia pre-parto | C26: 0.10082724
B27: Hemorragia intraparto | C27: 0.00031206
B28: Hemorragia posparto | C28: 0.15891214
B29: Trastornos hipertensivos | C29: 0.12598689
B30: Sepsis | C30: 0.12434007
B31: Aborto | C31: 0.03902841
B32: Embolia | C32: 0.00085255
B33: Otras causas directas | C33: 0.06846781
B34: Causas indirectas | C34: 0.38127283
B35: Total (debe ser el 100%) | C35: =SUM(C26:C34) -> 1

Sheet Distribución estado nutricional
A1: ="Porcentaje de población en cada categoría en el año de referencia ("&start_year&")" -> Porcentaje de población en cada categoría en el año de referencia (2017) | B1: Estado | C1: <1 mes | D1: 1-5 meses | E1: 6-11 meses | F1: 12-23 meses | G1: 24-59 meses
A2: Retraso en el crecimiento (Talla para la edad) | B2: Normal (score HAZ > -1) | C2: =IFERROR(1-_xlfn.NORM.DIST(_xlfn.NORM.INV(SUM(C4:C5), 0, 1) + 1, 0, 1, TRUE), "") -> 0.5447157 | D2: =IFERROR(1-_xlfn.NORM.DIST(_xlfn.NORM.INV(SUM(D4:D5), 0, 1) + 1, 0, 1, TRUE), "") -> 0.5447157 | E2: =IFERROR(1-_xlfn.NORM.DIST(_xlfn.NORM.INV(SUM(E4:E5), 0, 1) + 1, 0, 1, TRUE), "") -> 0.4498283 | F2: =IFERROR(1-_xlfn.NORM.DIST(_xlfn.NORM.INV(SUM(F4:F5), 0, 1) + 1, 0, 1, TRUE), "") -> 0.2445714 | G2: =IFERROR(1-_xlfn.NORM.DIST(_xlfn.NORM.INV(SUM(G4:G5), 0, 1) + 1, 0, 1, TRUE), "") -> 0.23269075
B3: Leve (score HAZ entre -2 y -1) | C3: =IFERROR(_xlfn.NORM.DIST(_xlfn.NORM.INV(SUM(C4:C5), 0, 1) + 1, 0, 1, TRUE) - SUM(C4:C5), "") -> 0.3222843 | D3: =IFERROR(_xlfn.NORM.DIST(_xlfn.NORM.INV(SUM(D4:D5), 0, 1) + 1, 0, 1, TRUE) - SUM(D4:D5), "") -> 0.3222843 | E3: =IFERROR(_xlfn.NORM.DIST(_xlfn.NORM.INV(SUM(E4:E5), 0, 1) + 1, 0, 1, TRUE) - SUM(E4:E5), "") -> 0.35908666 | F3: =IFERROR(_xlfn.NORM.DIST(_xlfn.NORM.INV(SUM(F4:F5), 0, 1) + 1, 0, 1, TRUE) - SUM(F4:F5), "") -> 0.37651189 | G3: =IFERROR(_xlfn.NORM.DIST(_xlfn.NORM.INV(SUM(G4:G5), 0, 1) + 1, 0, 1, TRUE) - SUM(G4:G5), "") -> 0.37372366
B4: Moderado (score HAZ entre -3 y -2) | C4: 0.087 | D4: 0.087 | E4: 0.13443033 | F4: 0.24673187 | G4: 0.2592961
B5: Alto (puntuación HAZ < -3) | C5: 0.046 | D5: 0.046 | E5: 0.056654713 | F5: 0.13218484 | G5: 0.13428949
A8: Emaciación (peso para la talla) | B8: Normal (score WHZ > -1) | C8: =IFERROR(1-_xlfn.NORM.DIST(_xlfn.NORM.INV(SUM(C10:C11), 0, 1) + 1, 0, 1, TRUE), "") -> 0.62419559 | D8: =IFERROR(1-_xlfn.NORM.DIST(_xlfn.NORM.INV(SUM(D10:D11), 0, 1) + 1, 0, 1, TRUE), "") -> 0.62419559 | E8: =IFERROR(1-_xlfn.NORM.DIST(_xlfn.NORM.INV(SUM(E10:E11), 0, 1) + 1, 0, 1, TRUE), "") -> 0.68355844 | F8: =IFERROR(1-_xlfn.NORM.DIST(_xlfn.NORM.INV(SUM(F10:F11), 0, 1) + 1, 0, 1, TRUE), "") -> 0.73228841 | G8: =IFERROR(1-_xlfn.NORM.DIST(_xlfn.NORM.INV(SUM(G10:G11), 0, 1) + 1, 0, 1, TRUE), "") -> 0.81212055
B9: Leve (score WHZ entre -2 y -1) | C9: =IFERROR(_xlfn.NORM.DIST(_xlfn.NORM.INV(SUM(C10:C11), 0, 1) + 1, 0, 1, TRUE) - SUM(C10:C11), "") -> 0.28180441 | D9: =IFERROR(_xlfn.NORM.DIST(_xlfn.NORM.INV(SUM(D10:D11), 0, 1) + 1, 0, 1, TRUE) - SUM(D10:D11), "") -> 0.28180441 | E9: =IFERROR(_xlfn.NORM.DIST(_xlfn.NORM.INV(SUM(E10:E11), 0, 1) + 1, 0, 1, TRUE) - SUM(E10:E11), "") -> 0.24669387 | F9: =IFERROR(_xlfn.NORM.DIST(_xlfn.NORM.INV(SUM(F10:F11), 0, 1) + 1, 0, 1, TRUE) - SUM(F10:F11), "") -> 0.21506847 | G9: =IFERROR(_xlfn.NORM.DIST(_xlfn.NORM.INV(SUM(G10:G11), 0, 1) + 1, 0, 1, TRUE) - SUM(G10:G11), "") -> 0.15821429
B10: MAM (puntuación WHZ entre -3 y -2) | C10: 0.054 | D10: 0.054 | E10: 0.054022564 | F10: 0.042547708 | G10: 0.022330661
B11: MAS (score WHZ < -3) | C11: 0.04 | D11: 0.04 | E11: 0.015725128 | F11: 0.010095416 | G11: 0.0073344954
A13: Anemia | C13: <1 mes | D13: 1-5 meses | E13: 6-11 meses | F13: 12-23 meses | G13: 24-59 meses | H13: PW: 15-19 años | I13: PW: 20-29 años | J13: PW: 30-39 años | K13: PW: 40-49 años | L13: WRA: 15-19 años (mujeres en edad reproductiva) | M13: WRA: 20-29 años (mujeres en edad reproductiva) | N13: WRA: 30-39 años (mujeres en edad reproductiva) | O13: WRA: 40-49 años (mujeres en edad reproductiva)
B14: Prevalencia de anemia | C14: 0.1 | D14: 0.1 | E14: 0.781 | F14: 0.7295 | G14: 0.48366667 | H14: 0.473 | I14: 0.447 | J14: 0.433 | K14: 0.442 | L14: 0.473 | M14: 0.447 | N14: 0.433 | O14: 0.442
B15: Prevalencia de anemia por deficiencia de hierro | C15: =iron_deficiency_anaemia*C14 -> 0.042 | D15: =iron_deficiency_anaemia*D14 -> 0.042 | E15: =iron_deficiency_anaemia*E14 -> 0.32802 | F15: =iron_deficiency_anaemia*F14 -> 0.30639 | G15: =iron_deficiency_anaemia*G14 -> 0.20314 | H15: =iron_deficiency_anaemia*H14 -> 0.19866 | I15: =iron_deficiency_anaemia*I14 -> 0.18774 | J15: =iron_deficiency_anaemia*J14 -> 0.18186 | ... O15: =iron_deficiency_anaemia*O14 -> 0.18564

Sheet Distribución de lactancia
A1: ="Porcentaje de niños en cada categoría en el año de referencia ("&start_year&")" -> Porcentaje de niños en cada categoría en el año de referencia (2017) | B1: Estado | C1: <1 mes | D1: 1-5 meses | E1: 6-11 meses | F1: 12-23 meses | G1: 24-59 meses
A2: Lactancia materna | B2: Exclusivo | C2: 0.84 | D2: 0.44307448 | E2: 0.013624458 | F2: 0 | G2: 0
B3: Predominante | C3: 0.092 | D3: 0.21674802 | E3: 0.032771032 | F3: 0.001 | G3: 0
B4: Parcial | C4: 0.058 | D4: 0.31577813 | E4: 0.93464267 | F4: 0.721 | G4: 0
B5: Ninguno | C5: =1-SUM(C2:C4) -> 0.01 | D5: =1-SUM(D2:D4) -> 0.024399366 | E5: =1-SUM(E2:E4) -> 0.018961839 | F5: =1-SUM(F2:F4) -> 0.278 | G5: =1-SUM(G2:G4) -> 1

Sheet Tendencias temporales
A1: Riesgo | B1: Población | C1: 2010 | D1: 2011 | E1: 2012 | F1: 2013 | G1: 2014 | H1: 2015 | I1: 2016 | J1: 2017 | K1: 2018
A2: Prevalencia del retraso del crecimiento (%) | B2: Niños de 0 a 59 meses
A4: Prevalencia de emaciación (%) | B4: Niños de 0 a 59 meses
A6: Prevalencia de anemia (%) | B6: Niños de 0 a 59 meses
B7: Mujeres embarazadas
B8: Mujeres en edad reproductiva
A10: Prevalencia de lactancia materna adecuada para la edad | B10: Niños de 0 a 5 meses
B11: Niños de 6 a 23 meses
A13: Mortalidad | B13: Menores de cinco años (muertes por cada 1.000 nacimientos)
B14: Materna (muertes por cada 1.000 nacimientos)

Sheet Variables económicas
A1: Parameter | B1: Value
A2: PIB per cápita | B2: 3000.4442
A3: Crecimiento anual del PIB | B3: 0.03
A4: Participación del trabajo en el PIB | B4: 0.43146
A5: Descuento temporal (costos) | B5: 0.03
A6: Descuento temporal (beneficios) | B6: 0.03
A7: Edad de inicio de la productividad laboral | B7: 18
A8: Edad a la que se acaba la productividad laboral | B8: 65
A9: Participación laboral femenina | B9: 0.73801
A10: Porcentaje de ingresos vitales que realmente se han ganado | B10: 0.9
A11: Reducción total de ingresos vitales en individuos con retraso del crecimiento | B11: 0.66
A12: Disminución de productividad debido a la anemia infantil (%) | B12: =0.025 -> 0.025
A13: Disminución de productividad debido al bajo peso al nacer (%) | B13: =0.075 -> 0.075
A14: Disminución de productividad debido a la anemia materna (%) | B14: 0.00012190323
A15: Porcentaje de embarazos a los cuales se les puede atribuir una pérdida de productividad por anemia materna | B15: 0.5
A16: Aumento de puntuación de CI gracias a la lactancia temprana | B16: 0.8
A17: Aumento de ingresos por punto de CI | B17: 0.010666667
A18: Porcentaje de mortinatos a incluir en la pérdida de productividad | B18: 0.5
A21: Life tables | B21: Age 5 | C21: Age 10 | D21: Age 15 | E21: Age 20 | F21: Age 25 | G21: Age 30 | H21: Age 35 | I21: Age 40 | J21: Age 45 | K21: Age 50 | L21: Age 55 | M21: Age 60 | N21: Age 65 | O21: Age 70
A22: Número de personas vivas restantes (empezando con 100.000 nacimientos) | B22: 95374.525 | C22: 94009.685 | D22: 93793.063 | E22: 93619.88 | F22: 93002.659 | G22: 92072.362 | H22: 90934.834 | I22: 89533.178 | J22: 87597.277 | K22: 84803.134 | L22: 80890.356 | M22: 75378.861 | N22: 67914.972 | O22: 58238.404

Sheet Paquetes de IYCF
A1: Paquete alimentación del lactante y del niño pequeño (IYCF) | B1: Población objetivo | C1: Centro de salud | D1: Comunidad | E1: Medios de comunicación masivos
A2: IYCF 1-alimentación del lactante y del niño pequeño | B2: Mujeres embarazadas | E2: =IF(E$7="","",E$7)
B3: <1 mes | C3: x | E3: =IF(E$7="","",E$7)
B4: 1-5 meses | C4: x | E4: =IF(E$7="","",E$7)
B5: 6-11 meses | C5: x | E5: =IF(E$7="","",E$7)
B6: 12-23 meses | C6: x | E6: =IF(E$7="","",E$7)
B7: Todo
A9: IYCF 2-alimentación del lactante y del niño pequeño | B9: Mujeres embarazadas | E9: =IF(E$7="","",E$7)
B10: <1 mes | D10: x | E10: =IF(E$7="","",E$7)
B11: 1-5 meses | D11: x | E11: =IF(E$7="","",E$7)
B12: 6-11 meses | D12: x | E12: =IF(E$7="","",E$7)
B13: 12-23 meses | D13: x | E13: =IF(E$7="","",E$7)
B14: Todo
A16: IYCF 3-alimentación del lactante y del niño pequeño | B16: Mujeres embarazadas | E16: =IF(E$7="","",E$7)
B17: <1 mes | D17: x | E17: =IF(E$7="","",E$7)
B18: 1-5 meses | D18: x | E18: =IF(E$7="","",E$7)
B19: 6-11 meses | E19: =IF(E$7="","",E$7)
B20: 12-23 meses | E20: =IF(E$7="","",E$7)
B21: Todo

Sheet Tratamiento de la MAS
A1: Field | B1: Por defecto | C1: Extensión | D1: Añadir extensión
A2: Programa | B2: Tratamiento de la MAS | C2: Manejo de la Malnutrición Aguda Moderada (MAM)
A3: Método de entrega | B3: Centro de salud | C3: Basado en la comunidad

Sheet Costo y cobertura del programa
A1: Programa | B1: ="Cobertura de referencia ("&start_year&")" -> Cobertura de referencia (2017) | C1: Cobertura de saturación de la población objetivo | D1: Costo unitario (US$) | E1: Relación costo-cobertura | F1: Aumento máximo anual | G1: Disminución máxima anual
A2: Suplemento energético-proteico equilibrado | B2: 0 | C2: 0.95 | D2: 25 | E2: Lineal (costo marginal constante) [por defecto] | F2: 1 | G2: 1
A3: Suplemento con calcio | B3: 0 | C3: 0.95 | D3: 1 | E3: Lineal (costo marginal constante) [por defecto] | F3: 1 | G3: 1
A4: Transferencias de efectivo | B4: 0 | C4: 0.95 | D4: 90 | E4: Lineal (costo marginal constante) [por defecto] | F4: 1 | G4: 1
A5: Retraso en el pinzamiento del cordón umbilical | B5: 0 | C5: 0.95 | D5: 1 | E5: Lineal (costo marginal constante) [por defecto] | F5: 1 | G5: 1
A6: Planificación familiar | B6: 0 | C6: 0.95 | D6: 0.82 | E6: Lineal (costo marginal constante) [por defecto] | F6: 1 | G6: 1
A7: Enriquecimiento del maíz con hierro y ácido fólico | B7: 0.36 | C7: 0.95 | D7: 0.25 | E7: Lineal (costo marginal constante) [por defecto] | F7: 1 | G7: 1
A8: Enriquecimiento del arroz con hierro y ácido fólico | B8: 0 | C8: 0.95 | D8: 0.75 | E8: Lineal (costo marginal constante) [por defecto] | F8: 1 | G8: 1
A9: Enriquecimiento de la harina de trigo con hierro y ácido fólico | B9: 0 | C9: 0.95 | D9: 0.19 | E9: Lineal (costo marginal constante) [por defecto] | F9: 1 | G9: 1
A10: Suplementación con hierro y ácido fólico (comunidad) | B10: 0 | C10: 0.95 | D10: 0.73 | E10: Lineal (costo marginal constante) [por defecto] | F10: 1 | G10: 1
A11: Suplementación con hierro y ácido fólico (centro de salud) | B11: 0 | C11: 0.95 | D11: 1.78 | E11: Lineal (costo marginal constante) [por defecto] | F11: 1 | G11: 1
A12: Suplementación con hierro y ácido fólico (minorista) | B12: 0 | C12: 0.95 | D12: 0.24 | E12: Lineal (costo marginal constante) [por defecto] | F12: 1 | G12: 1
A13: Suplementación con hierro y ácido fólico (escuela) | B13: 0 | C13: 0.95 | D13: 0.55 | E13: Lineal (costo marginal constante) [por defecto] | F13: 1 | G13: 1
... A39: Suplementación con zinc | B39: 0 | C39: 0.95 | D39: 1 | E39: Lineal (costo marginal constante) [por defecto] | F39: 1 | G39: 1

Sheet Dependencias del programa
A1: Programa | B1: Exclusión de intervención dependiente | C1: Dependencia de otra intervención
A2: Suplementación con hierro y ácido fólico para mujeres embarazadas (comunidad) | B2: Suplementación con micronutrientes múltiples
A3: Suplementación con hierro y ácido fólico para mujeres embarazadas (centro de salud) | B3: Suplementación con micronutrientes múltiples
A4: Suministro público de alimentos complementarios | B4: Suplementos nutricionales a base de lípidos
A5: Micronutrientes en polvo | B5: Suplementos nutricionales a base de lípidos

Sheet Programas de referencia
A1: Programa
A2: Planificación familiar
A3: IPTp-Tratamiento preventivo intermitente de la malaria en el embarazo
A4: Mosquiteros tratados con insecticida de larga duración
A5: WASH: Lavado de manos
A6: WASH: Eliminación higiénica de residuos
A7: WASH: Mejora del saneamiento
A8: WASH: Mejora de la fuente de agua
A9: WASH: Agua corriente o entubada

Sheet Incidencia de las afecciones
A1: Condición | B1: <1 mes | C1: 1-5 meses | D1: 6-11 meses | E1: 12-23 meses | F1: 24-59 meses
A2: Diarrea | B2: ='Entradas de población-año base'!C51 -> 1.66 | C2: ='Entradas de población-año base'!C52 -> 1.66 | D2: ='Entradas de población-año base'!C53 -> 5.64 | E2: ='Entradas de población-año base'!C54 -> 5.43 | F2: ='Entradas de población-año base'!C55 -> 1.91
A3: MAM | B3: =frac_mam_1month * 2.6 -> 0.1404 | C3: =frac_mam_1_5months * 2.6 -> 0.1404 | D3: =frac_mam_6_11months * 2.6 -> 0.14045867 | E3: =frac_mam_12_23months * 2.6 -> 0.11062404 | F3: =frac_mam_24_59months * 2.6 -> 0.058059718
A4: MAS | B4: =frac_sam_1month * 2.6 -> 0.104 | C4: =frac_sam_1_5months * 2.6 -> 0.104 | D4: =frac_sam_6_11months * 2.6 -> 0.040885333 | E4: =frac_sam_12_23months * 2.6 -> 0.026248082 | F4: =frac_sam_24_59months * 2.6 -> 0.019069688

Sheet Población objetivo del programa
A1: Amplio grupo de población | B1: Programa | C1: <1 mes | D1: 1-5 meses | E1: 6-11 meses | F1: 12-23 meses | G1: 24-59 meses | H1: PW: 15-19 años | I1: PW: 20-29 años | J1: PW: 30-39 años | K1: PW: 40-49 años | L1: WRA: 15-19 años (mujeres en edad reproductiva) | M1: WRA: 20-29 años (mujeres en edad reproductiva) | N1: WRA: 30-39 años (mujeres en edad reproductiva) | O1: WRA: 40-49 años (mujeres en edad reproductiva)
A2: Niños | B2: Transferencias de efectivo | C2: 0 | D2: 0 | E2: =food_insecure -> 0.282 | F2: =food_insecure -> 0.282 | G2: 0 | H2: 0 | I2: 0 | J2: 0 | K2: 0 | L2: 0 | M2: 0 | N2: 0 | O2: 0
B3: Retraso en el pinzamiento del cordón umbilical | C3: 1 | D3: 0 | E3: 0 | F3: 0 | G3: 0 | H3: 0 | I3: 0 | J3: 0 | K3: 0 | L3: 0 | M3: 0 | N3: 0 | O3: 0
B4: Método de la madre canguro | C4: 1 | D4: 0 | E4: 0 | F4: 0 | G4: 0 | H4: 0 | I4: 0 | J4: 0 | K4: 0 | L4: 0 | M4: 0 | N4: 0 | O4: 0
B5: Suplementos nutricionales a base de lípidos | C5: 0 | D5: 0 | E5: =food_insecure -> 0.282 | F5: =food_insecure -> 0.282 | G5: 0 | H5: 0 | I5: 0 | J5: 0 | K5: 0 | L5: 0 | M5: 0 | N5: 0 | O5: 0
B6: Micronutrientes en polvo | C6: 0 | D6: 0 | E6: =1 -> 1 | F6: =1 -> 1 | G6: =1 -> 1 | H6: 0 | I6: 0 | J6: 0 | K6: 0 | L6: 0 | M6: 0 | N6: 0 | O6: 0
B7: Sales de rehidratación oral | C7: =diarrhoea_1mo*frac_diarrhea_severe -> 0.332 | D7: =diarrhoea_1_5mo*frac_diarrhea_severe -> 0.332 | E7: =diarrhoea_6_11mo*frac_diarrhea_severe -> 1.128 | F7: =diarrhoea_12_23mo*frac_diarrhea_severe -> 1.086 | G7: =diarrhoea_24_59mo*frac_diarrhea_severe -> 0.382 | H7: 0 | I7: 0 | J7: 0 | K7: 0 | L7: 0 | M7: 0 | N7: 0 | O7: 0
B8: Suministro público de alimentos complementarios | C8: 0 | D8: 0 | E8: =food_insecure -> 0.282 | F8: =food_insecure -> 0.282 | G8: 0 | H8: 0 | I8: 0 | J8: 0 | K8: 0 | L8: 0 | M8: 0 | N8: 0 | O8: 0
B9: Suplementos nutricionales a base de lípidos en pequeñas cantidades | C9: 0 | D9: 0 | E9: =food_insecure -> 0.282 | F9: =food_insecure -> 0.282 | G9: 0 | H9: 0 | I9: 0 | J9: 0 | K9: 0 | L9: 0 | M9: 0 | N9: 0 | O9: 0
B10: Tratamiento de la MAS | C10: 0 | D10: =IF(ISBLANK(comm_deliv), frac_children_health_facility,1) -> 0.37 | E10: =IF(ISBLANK(comm_deliv), frac_children_health_facility,1) -> 0.37 | F10: =IF(ISBLANK(comm_deliv), frac_children_health_facility,1) -> 0.37 | G10: =IF(ISBLANK(comm_deliv), frac_children_health_facility,1) -> 0.37 | H10: 0 | I10: 0 | J10: 0 | K10: 0 | L10: 0 | M10: 0 | N10: 0 | O10: 0
B11: Suplementación con vitamina A | C11: 0 | D11: 0 | E11: 1 | F11: 1 | G11: 1 | H11: 0 | I11: 0 | J11: 0 | K11: 0 | L11: 0 | M11: 0 | N11: 0 | O11: 0
B12: Zinc para el tratamiento + SRO | C12: =diarrhoea_1mo*frac_diarrhea_severe -> 0.332 | D12: =diarrhoea_1_5mo*frac_diarrhea_severe -> 0.332 | E12: =diarrhoea_6_11mo*frac_diarrhea_severe -> 1.128 | F12: =diarrhoea_12_23mo*frac_diarrhea_severe -> 1.086 | G12: =diarrhoea_24_59mo*frac_diarrhea_severe -> 0.382 | H12: 0 | I12: 0 | J12: 0 | K12: 0 | L12: 0 | M12: 0 | N12: 0 | O12: 0
B13: Suplementación con zinc | C13: 0 | D13: 0 | E13: 1 | F13: 1 | G13: 1 | H13: 0 | I13: 0 | J13: 0 | K13: 0 | L13: 0 | M13: 0 | N13: 0 | O13: 0
A15: Mujeres embarazadas | B15: Suplemento energético-proteico equilibrado | C15: 0 | D15: 0 | E15: 0 | F15: 0 | G15: 0 | H15: =food_insecure -> 0.282 | I15: =food_insecure -> 0.282 | J15: =food_insecure -> 0.282 | K15: =food_insecure -> 0.282 | L15: 0 | M15: 0 | N15: 0 | O15: 0
B16: Suplemento con calcio | C16: 0 | D16: 0 | E16: 0 | F16: 0 | G16: 0 | H16: =food_insecure -> 0.282 | I16: =food_insecure -> 0.282 | J16: =food_insecure -> 0.282 | K16: =food_insecure -> 0.282 | L16: 0 | M16: 0 | N16: 0 | O16: 0
B17: Suplementación con hierro y ácido fólico para mujeres embarazadas (comunidad) | C17: 0 | D17: 0 | E17: 0 | F17: 0 | G17: 0 | H17: =1 -> 1 | I17: =1 -> 1 | J17: =1 -> 1 | K17: =1 -> 1 | L17: 0 | M17: 0 | N17: 0 | O17: 0
B18: Suplementación con hierro y ácido fólico para mujeres embarazadas (centro de salud) | C18: 0 | D18: 0 | E18: 0 | F18: 0 | G18: 0 | H18: =frac_PW_health_facility -> 0.51 | I18: =frac_PW_health_facility -> 0.51 | J18: =frac_PW_health_facility -> 0.51 | K18: =frac_PW_health_facility -> 0.51 | L18: 0 | M18: 0 | N18: 0 | O18: 0
B19: IPTp-Tratamiento preventivo intermitente de la malaria en el embarazo | C19: 0 | D19: 0 | E19: 0 | F19: 0 | G19: 0 | H19: =frac_malaria_risk -> 1 | I19: =frac_malaria_risk -> 1 | J19: =frac_malaria_risk -> 1 | K19: =frac_malaria_risk -> 1 | L19: 0 | M19: 0 | N19: 0 | O19: 0
B20: Magnesio para la eclampsia | C20: 0 | D20: 0 | E20: 0 | F20: 0 | G20: 0 | H20: 1 | I20: 1 | J20: 1 | K20: 1 | L20: 0 | M20: 0 | N20: 0 | O20: 0
B21: Magnesio para la preeclampsia | C21: 0 | D21: 0 | E21: 0 | F21: 0 | G21: 0 | H21: 1 | I21: 1 | J21: 1 | K21: 1 | L21: 0 | M21: 0 | N21: 0 | O21: 0
B22: Suplementación con micronutrientes múltiples | C22: 0 | D22: 0 | E22: 0 | F22: 0 | G22: 0 | H22: =1 -> 1 | I22: =1 -> 1 | J22: =1 -> 1 | K22: =1 -> 1 | L22: 0 | M22: 0 | N22: 0 | O22: 0
A24: Mujeres en edad reproductiva no embarazadas | B24: Planificación familiar | C24: 0 | D24: 0 | E24: 0 | F24: 0 | G24: 0 | H24: 0 | I24: 0 | J24: 0 | K24: 0 | L24: =famplan_unmet_need -> 0.221 | M24: =famplan_unmet_need -> 0.221 | N24: =famplan_unmet_need -> 0.221 | O24: =famplan_unmet_need -> 0.221
B25: Suplementación con hierro y ácido fólico (comunidad) | C25: 0 | D25: 0 | E25: 0 | F25: 0 | G25: 0 | H25: 0 | I25: 0 | J25: 0 | K25: 0 | L25: =(1-food_insecure)*(0.49)*(1-school_attendance) + food_insecure*(0.7)*(1-school_attendance) -> 0.4228994 | M25: =(1-food_insecure)*(0.49)+food_insecure*(0.7) -> 0.54922 | N25: =(1-food_insecure)*(0.49)+food_insecure*(0.7) -> 0.54922 | O25: =(1-food_insecure)*(0.49)+food_insecure*(0.7) -> 0.54922
B26: Suplementación con hierro y ácido fólico (centro de salud) | C26: 0 | D26: 0 | E26: 0 | F26: 0 | G26: 0 | H26: 0 | I26: 0 | J26: 0 | K26: 0 | L26: =(1-food_insecure)*(0.21)*(1-school_attendance) + food_insecure*(0.3)*(1-school_attendance) -> 0.1812426 | M26: =(1-food_insecure)*(0.21)+food_insecure*(0.3) -> 0.23538 | N26: =(1-food_insecure)*(0.21)+food_insecure*(0.3) -> 0.23538 | O26: =(1-food_insecure)*(0.21)+food_insecure*(0.3) -> 0.23538
B27: Suplementación con hierro y ácido fólico (minorista) | C27: 0 | D27: 0 | E27: 0 | F27: 0 | G27: 0 | H27: 0 | I27: 0 | J27: 0 | K27: 0 | L27: =(1-food_insecure)*(0.3)*(1-school_attendance) -> 0.165858 | M27: =(1-food_insecure)*(0.3) -> 0.2154 | N27: =(1-food_insecure)*(0.3) -> 0.2154 | O27: =(1-food_insecure)*(0.3) -> 0.2154
B28: Suplementación con hierro y ácido fólico (escuela) | C28: 0 | D28: 0 | E28: 0 | F28: 0 | G28: 0 | H28: 0 | I28: 0 | J28: 0 | K28: 0 | L28: =(1-food_insecure)*1*school_attendance + food_insecure*1*school_attendance -> 0.23 | M28: 0 | N28: 0 | O28: 0
A30: Población general | B30: Enriquecimiento del maíz con hierro y ácido fólico | C30: 0 | D30: 0 | E30: =frac_maize -> 0.8 | F30: =frac_maize -> 0.8 | G30: =frac_maize -> 0.8 | H30: =frac_maize -> 0.8 | I30: =frac_maize -> 0.8 | J30: =frac_maize -> 0.8 | K30: =frac_maize -> 0.8 | L30: =frac_maize -> 0.8 | ... O30: =frac_maize -> 0.8
B31: Enriquecimiento del arroz con hierro y ácido fólico | C31: 0 | D31: 0 | E31: =frac_rice -> 0.1 | F31: =frac_rice -> 0.1 | G31: =frac_rice -> 0.1 | H31: =frac_rice -> 0.1 | I31: =frac_rice -> 0.1 | J31: =frac_rice -> 0.1 | K31: =frac_rice -> 0.1 | L31: =frac_rice -> 0.1 | ... O31: =frac_rice -> 0.1
B32: Enriquecimiento de la harina de trigo con hierro y ácido fólico | C32: 0 | D32: 0 | E32: =frac_wheat -> 0.1 | F32: =frac_wheat -> 0.1 | G32: =frac_wheat -> 0.1 | H32: =frac_wheat -> 0.1 | I32: =frac_wheat -> 0.1 | J32: =frac_wheat -> 0.1 | K32: =frac_wheat -> 0.1 | L32: =frac_wheat -> 0.1 | ... O32: =frac_wheat -> 0.1
B33: Fortificación de la sal con hierro y yodo | C33: 0 | D33: 0 | E33: 1 | F33: 1 | G33: 1 | H33: 1 | I33: 1 | J33: 1 | K33: 1 | L33: 1 | M33: 1 | N33: 1 | O33: 1
B34: Mosquiteros tratados con insecticida de larga duración | C34: =frac_malaria_risk -> 1 | D34: =frac_malaria_risk -> 1 | E34: =frac_malaria_risk -> 1 | F34: =frac_malaria_risk -> 1 | G34: =frac_malaria_risk -> 1 | H34: =frac_malaria_risk -> 1 | I34: =frac_malaria_risk -> 1 | J34: =frac_malaria_risk -> 1 | ... O34: =frac_malaria_risk -> 1
B35: WASH: Lavado de manos | C35: 1 | D35: 1 | E35: 1 | F35: 1 | G35: 1 | H35: 1 | I35: 1 | J35: 1 | K35: 1 | L35: 1 | M35: 1 | N35: 1 | O35: 1
B36: WASH: Eliminación higiénica de residuos | C36: 1 | D36: 1 | E36: 1 | F36: 1 | G36: 1 | H36: 1 | I36: 1 | J36: 1 | K36: 1 | L36: 1 | M36: 1 | N36: 1 | O36: 1
B37: WASH: Mejora del saneamiento | C37: 1 | D37: 1 | E37: 1 | F37: 1 | G37: 1 | H37: 1 | I37: 1 | J37: 1 | K37: 1 | L37: 1 | M37: 1 | N37: 1 | O37: 1
B38: WASH: Mejora de la fuente de agua | C38: 1 | D38: 1 | E38: 1 | F38: 1 | G38: 1 | H38: 1 | I38: 1 | J38: 1 | K38: 1 | L38: 1 | M38: 1 | N38: 1 | O38: 1
B39: WASH: Agua corriente o entubada | C39: 1 | D39: 1 | E39: 1 | F39: 1 | G39: 1 | H39: 1 | I39: 1 | J39: 1 | K39: 1 | L39: 1 | M39: 1 | N39: 1 | O39: 1

Sheet Opciones de la curva de costos
A1: Lineal (costo marginal constante) [por defecto]
A2: Curva con costo marginal creciente
A3: Curva con costo marginal decreciente
A4: En forma de S (costo marginal decreciente y luego creciente)

Sheet Prog. de planificación familiar
A1: Método | B1: Efectividad | C1: Distribución | D1: Costo | E1: Costo proporcional
A2: Preservativo/condón | B2: 0.9 | C2: 0.09 | D2: 0.8 | E2: =C2*D2 -> 0.072
A3: Esterilización masculina | B3: 1 | C3: 0.02 | D3: 1.9 | E3: =C3*D3 -> 0.038
A4: Esterilización femenina | B4: 1 | C4: 0.08 | D4: 2 | E4: =C4*D4 -> 0.16
A5: Inyectable | B5: 1 | C5: 0.18 | D5: 0.7 | E5: =C5*D5 -> 0.126
A6: Implante | B6: 1 | C6: 0.02 | D6: 0.7 | E6: =C6*D6 -> 0.014
A7: Cápsula/píldora | B7: 0.93 | C7: 0.45 | D7: 0.9 | E7: =C7*D7 -> 0.405
A8: Retiro | B8: 0.5 | C8: 0.03 | D8: 0 | E8: =C8*D8 -> 0
A9: Planificación Familiar Natural | B9: 0.5 | C9: 0.11 | D9: 0 | E9: =C9*D9 -> 0
A10: Dispositivo Intrauterino (DIU) | B10: 0.98 | C10: 0.01 | D10: 0.6 | E10: =C10*D10 -> 0.006

Sheet Programas población afectada
A1: Amplio grupo de población | B1: Programa | C1: <1 mes | D1: 1-5 meses | E1: 6-11 meses | F1: 12-23 meses | G1: 24-59 meses | H1: PW: 15-19 años | I1: PW: 20-29 años | J1: PW: 30-39 años | K1: PW: 40-49 años | L1: WRA: 15-19 años (mujeres en edad reproductiva) | M1: WRA: 20-29 años (mujeres en edad reproductiva) | N1: WRA: 30-39 años (mujeres en edad reproductiva) | O1: WRA: 40-49 años (mujeres en edad reproductiva)
A2: Niños | B2: Transferencias de efectivo | C2: 0 | D2: 0 | E2: 1 | F2: 1 | G2: 0 | H2: 0 | I2: 0 | J2: 0 | K2: 0 | L2: 0 | M2: 0 | N2: 0 | O2: 0
B3: Retraso en el pinzamiento del cordón umbilical | C3: 1 | D3: 1 | E3: 0 | F3: 0 | G3: 0 | H3: 0 | I3: 0 | J3: 0 | K3: 0 | L3: 0 | M3: 0 | N3: 0 | O3: 0
B4: IYCF 1-alimentación del lactante y del niño pequeño | C4: 1 | D4: 1 | E4: 1 | F4: 1 | G4: 1 | H4: 0 | I4: 0 | J4: 0 | K4: 0 | L4: 0 | M4: 0 | N4: 0 | O4: 0
B5: IYCF 2-alimentación del lactante y del niño pequeño | C5: 1 | D5: 1 | E5: 1 | F5: 1 | G5: 1 | H5: 0 | I5: 0 | J5: 0 | K5: 0 | L5: 0 | M5: 0 | N5: 0 | O5: 0
B6: IYCF 3-alimentación del lactante y del niño pequeño | C6: 1 | D6: 1 | E6: 1 | F6: 1 | G6: 1 | H6: 0 | I6: 0 | J6: 0 | K6: 0 | L6: 0 | M6: 0 | N6: 0 | O6: 0
B7: Método de la madre canguro | C7: 1 | D7: 1 | E7: 0 | F7: 0 | G7: 0 | H7: 0 | I7: 0 | J7: 0 | K7: 0 | L7: 0 | M7: 0 | N7: 0 | O7: 0
B8: Suplementos nutricionales a base de lípidos | C8: 0 | D8: 0 | E8: 1 | F8: 1 | G8: 0 | H8: 0 | I8: 0 | J8: 0 | K8: 0 | L8: 0 | M8: 0 | N8: 0 | O8: 0
B9: Micronutrientes en polvo | C9: 0 | D9: 0 | E9: 1 | F9: 1 | G9: 1 | H9: 0 | I9: 0 | J9: 0 | K9: 0 | L9: 0 | M9: 0 | N9: 0 | O9: 0
B10: Sales de rehidratación oral | C10: 1 | D10: 1 | E10: 1 | F10: 1 | G10: 1 | H10: 0 | I10: 0 | J10: 0 | K10: 0 | L10: 0 | M10: 0 | N10: 0 | O10: 0
B11: Suministro público de alimentos complementarios | C11: 0 | D11: 0 | E11: 1 | F11: 1 | G11: 0 | H11: 0 | I11: 0 | J11: 0 | K11: 0 | L11: 0 | M11: 0 | N11: 0 | O11: 0
B12: Suplementos nutricionales a base de lípidos en pequeñas cantidades | C12: 0 | D12: 0 | E12: 1 | F12: 1 | G12: 0 | H12: 0 | I12: 0 | J12: 0 | K12: 0 | L12: 0 | M12: 0 | N12: 0 | O12: 0
B13: Tratamiento de la MAS | C13: 0 | D13: 1 | E13: 1 | F13: 1 | G13: 1 | H13: 0 | I13: 0 | J13: 0 | K13: 0 | L13: 0 | M13: 0 | N13: 0 | O13: 0
B14: Suplementación con vitamina A | C14: 0 | D14: 0 | E14: 1 | F14: 1 | G14: 1 | H14: 0 | I14: 0 | J14: 0 | K14: 0 | L14: 0 | M14: 0 | N14: 0 | O14: 0
... B16: Suplementación con zinc | C16: 0 | D16: 0 | E16: 1 | F16: 1 | G16: 1 | H16: 0 | I16: 0 | J16: 0 | K16: 0 | L16: 0 | M16: 0 | N16: 0 | O16: 0
A18: Mujeres embarazadas | B18: Suplemento energético-proteico equilibrado | C18: 0 | D18: 0 | E18: 0 | F18: 0 | G18: 0 | H18: 1 | I18: 1 | J18: 1 | K18: 1 | L18: 0 | M18: 0 | N18: 0 | O18: 0
B19: Suplemento con calcio | C19: 0 | D19: 0 | E19: 0 | F19: 0 | G19: 0 | H19: 1 | I19: 1 | J19: 1 | K19: 1 | L19: 0 | M19: 0 | N19: 0 | O19: 0
B20: Suplementación con hierro y ácido fólico para mujeres embarazadas (comunidad) | C20: 0 | D20: 0 | E20: 0 | F20: 0 | G20: 0 | H20: 1 | I20: 1 | J20: 1 | K20: 1 | L20: 0 | M20: 0 | N20: 0 | O20: 0
B21: Suplementación con hierro y ácido fólico para mujeres embarazadas (centro de salud) | C21: 0 | D21: 0 | E21: 0 | F21: 0 | G21: 0 | H21: 1 | I21: 1 | J21: 1 | K21: 1 | L21: 0 | M21: 0 | N21: 0 | O21: 0
B22: IPTp-Tratamiento preventivo intermitente de la malaria en el embarazo | C22: 0 | D22: 0 | E22: 0 | F22: 0 | G22: 0 | H22: 1 | I22: 1 | J22: 1 | K22: 1 | L22: 0 | M22: 0 | N22: 0 | O22: 0
B23: Magnesio para la eclampsia | C23: 0 | D23: 0 | E23: 0 | F23: 0 | G23: 0 | H23: 1 | I23: 1 | J23: 1 | K23: 1 | L23: 0 | M23: 0 | N23: 0 | O23: 0
B24: Magnesio para la preeclampsia | C24: 0 | D24: 0 | E24: 0 | F24: 0 | G24: 0 | H24: 1 | I24: 1 | J24: 1 | K24: 1 | L24: 0 | M24: 0 | N24: 0 | O24: 0
B25: Suplementación con micronutrientes múltiples | C25: 0 | D25: 0 | E25: 0 | F25: 0 | G25: 0 | H25: 1 | I25: 1 | J25: 1 | K25: 1 | L25: 0 | M25: 0 | N25: 0 | O25: 0
A27: Mujeres en edad reproductiva no embarazadas | B27: Planificación familiar | C27: 0 | D27: 0 | E27: 0 | F27: 0 | G27: 0 | H27: 0 | I27: 0 | J27: 0 | K27: 0 | L27: 1 | M27: 0 | N27: 0 | O27: 0
B28: Suplementación con hierro y ácido fólico (comunidad) | C28: 0 | D28: 0 | E28: 0 | F28: 0 | G28: 0 | H28: 0 | I28: 0 | J28: 0 | K28: 0 | L28: 1 | M28: 1 | N28: 1 | O28: 1
B29: Suplementación con hierro y ácido fólico (centro de salud) | C29: 0 | D29: 0 | E29: 0 | F29: 0 | G29: 0 | H29: 0 | I29: 0 | J29: 0 | K29: 0 | L29: 1 | M29: 1 | N29: 1 | O29: 1
B30: Suplementación con hierro y ácido fólico (minorista) | C30: 0 | D30: 0 | E30: 0 | F30: 0 | G30: 0 | H30: 0 | I30: 0 | J30: 0 | K30: 0 | L30: 1 | M30: 1 | N30: 1 | O30: 1
B31: Suplementación con hierro y ácido fólico (escuela) | C31: 0 | D31: 0 | E31: 0 | F31: 0 | G31: 0 | H31: 0 | I31: 0 | J31: 0 | K31: 0 | L31: 1 | M31: 0 | N31: 0 | O31: 0
A33: Población general | B33: Enriquecimiento del maíz con hierro y ácido fólico | C33: 1 | D33: 0 | E33: 1 | F33: 1 | G33: 1 | H33: 1 | I33: 1 | J33: 1 | K33: 1 | L33: 1 | M33: 1 | N33: 1 | O33: 1
B34: Enriquecimiento del arroz con hierro y ácido fólico | C34: 1 | D34: 0 | E34: 1 | F34: 1 | G34: 1 | H34: 1 | I34: 1 | J34: 1 | K34: 1 | L34: 1 | M34: 1 | N34: 1 | O34: 1
B35: Enriquecimiento de la harina de trigo con hierro y ácido fólico | C35: 1 | D35: 0 | E35: 1 | F35: 1 | G35: 1 | H35: 1 | I35: 1 | J35: 1 | K35: 1 | L35: 1 | M35: 1 | N35: 1 | O35: 1
B36: Fortificación de la sal con hierro y yodo | C36: 1 | D36: 0 | E36: 1 | F36: 1 | G36: 1 | H36: 1 | I36: 1 | J36: 1 | K36: 1 | L36: 1 | M36: 1 | N36: 1 | O36: 1
B37: Mosquiteros tratados con insecticida de larga duración | C37: 1 | D37: 1 | E37: 1 | F37: 1 | G37: 1 | H37: 1 | I37: 1 | J37: 1 | K37: 1 | L37: 1 | M37: 1 | N37: 1 | O37: 1
B38: WASH: Lavado de manos | C38: 1 | D38: 1 | E38: 1 | F38: 1 | G38: 1 | H38: 1 | I38: 1 | J38: 1 | K38: 1 | L38: 1 | M38: 1 | N38: 1 | O38: 1
B39: WASH: Eliminación higiénica de residuos | C39: 1 | D39: 1 | E39: 1 | F39: 1 | G39: 1 | H39: 1 | I39: 1 | J39: 1 | K39: 1 | L39: 1 | M39: 1 | N39: 1 | O39: 1
B40: WASH: Mejora del saneamiento | C40: 1 | D40: 1 | E40: 1 | F40: 1 | G40: 1 | H40: 1 | I40: 1 | J40: 1 | K40: 1 | L40: 1 | M40: 1 | N40: 1 | O40: 1
B41: WASH: Mejora de la fuente de agua | C41: 1 | D41: 1 | E41: 1 | F41: 1 | G41: 1 | H41: 1 | I41: 1 | J41: 1 | K41: 1 | L41: 1 | M41: 1 | N41: 1 | O41: 1
B42: WASH: Agua corriente o entubada | C42: 1 | D42: 1 | E42: 1 | F42: 1 | G42: 1 | H42: 1 | I42: 1 | J42: 1 | K42: 1 | L42: 1 | M42: 1 | N42: 1 | O42: 1

Sheet Riesgos que impacta programa
A1: Programa | B1: Baja talla o retraso en el crecimiento | C1: Anemia | D1: Prevención de la emaciación | E1: Tratamiento de la emaciación | F1: Lactancia materna | G1: Diarrea | H1: Mortalidad | I1: Desenlaces del nacimiento | J1: Espaciamiento entre los nacimientos | K1: Número de nacimiento | L1: Mortinatos
A2: Suplemento energético-proteico equilibrado | I2: x
A3: Suplemento con calcio | H3: x | I3: x
A4: Transferencias de efectivo | B4: x | D4: x
A5: Retraso en el pinzamiento del cordón umbilical | C5: x
A6: Planificación familiar | J6: x | K6: x
A7: Enriquecimiento del maíz con hierro y ácido fólico | C7: x | H7: x
A8: Enriquecimiento del arroz con hierro y ácido fólico | C8: x | H8: x
A9: Enriquecimiento de la harina de trigo con hierro y ácido fólico | C9: x | H9: x
A10: Suplementación con hierro y ácido fólico (comunidad) | C10: x
A11: Suplementación con hierro y ácido fólico (centro de salud) | C11: x
A12: Suplementación con hierro y ácido fólico (minorista) | C12: x
A13: Suplementación con hierro y ácido fólico (escuela) | C13: x
A14: Suplementación con hierro y ácido fólico para mujeres embarazadas (comunidad) | C14: x | I14: x
A15: Suplementación con hierro y ácido fólico para mujeres embarazadas (centro de salud) | C15: x | I15: x
A16: IPTp-Tratamiento preventivo intermitente de la malaria en el embarazo | C16: x | H16: x | I16: x
A17: Fortificación de la sal con hierro y yodo | C17: x
A18: IYCF 1-alimentación del lactante y del niño pequeño | B18: x | F18: x
A19: IYCF 2-alimentación del lactante y del niño pequeño | B19: x | F19: x
A20: IYCF 3-alimentación del lactante y del niño pequeño | B20: x | F20: x
A21: Método de la madre canguro | H21: x | I21: x
A22: Suplementos nutricionales a base de lípidos | B22: x | C22: x | D22: x
A23: Mosquiteros tratados con insecticida de larga duración | C23: x | I23: x
A24: Magnesio para la eclampsia | H24: x
A25: Magnesio para la preeclampsia | H25: x
A26: Micronutrientes en polvo | C26: x
A27: Suplementación con micronutrientes múltiples | C27: x | I27: x | L27: x
A28: Sales de rehidratación oral | H28: x
A29: Suministro público de alimentos complementarios | B29: x | D29: x
A30: Suplementos nutricionales a base de lípidos en pequeñas cantidades | B30: x | C30: x | D30: x
A31: Tratamiento de la MAS | E31: x
A32: Suplementación con vitamina A | G32: x | H32: x
A33: WASH: Lavado de manos | G33: x | H33: x
A34: WASH: Eliminación higiénica de residuos | G34: x | H34: x
A35: WASH: Mejora del saneamiento | G35: x | H35: x
A36: WASH: Mejora de la fuente de agua | G36: x | H36: x
A37: WASH: Agua corriente o entubada | G37: x | H37: x
A38: Zinc para el tratamiento + SRO | H38: x
A39: Suplementación con zinc | B39: x | G39: x | H39: x

Sheet Riegos para la población
A1: Rango de edades | B1: Baja talla o retraso en el crecimiento | C1: Anemia | D1: Prevención de la emaciación | E1: Tratamiento de la emaciación | F1: Lactancia materna | G1: Diarrea | H1: Mortalidad | I1: Desenlaces del nacimiento | J1: Espaciamiento entre los nacimientos | K1: Número de nacimiento | L1: Mortinatos
A2: <1 mes | B2: x | C2: x | D2: x | E2: x | F2: x | G2: x | H2: x
A3: 1-5 meses | B3: x | C3: x | D3: x | E3: x | F3: x | G3: x | H3: x
A4: 6-11 meses | B4: x | C4: x | D4: x | E4: x | F4: x | G4: x | H4: x
A5: 12-23 meses | B5: x | C5: x | D5: x | E5: x | F5: x | G5: x | H5: x
A6: 24-59 meses | B6: x | C6: x | D6: x | E6: x | F6: x | G6: x | H6: x
A7: PW: 15-19 años | C7: x | H7: x | I7: x | L7: x
A8: PW: 20-29 años | C8: x | H8: x | I8: x | L8: x
A9: PW: 30-39 años | C9: x | H9: x | I9: x | L9: x
A10: PW: 40-49 años | C10: x | H10: x | I10: x | L10: x
A11: WRA: 15-19 años (mujeres en edad reproductiva) | C11: x | J11: x | K11: x
A12: WRA: 20-29 años (mujeres en edad reproductiva) | C12: x | K12: x
A13: WRA: 30-39 años (mujeres en edad reproductiva) | C13: x | K13: x
A14: WRA: 40-49 años (mujeres en edad reproductiva) | C14: x | K14: x

Sheet Razón de momios IYCF
A1: Comportamiento | B1: Población objetivo | C1: Método de entrega | D1: <1 mes | E1: 1-5 meses | F1: 6-11 meses | G1: 12-23 meses | H1: 24-59 meses
A2: Razón de momios para lactancia materna adecuada | B2: Mujeres embarazadas | C2: Centro de salud | D2: 1 | E2: 1 | F2: 1 | G2: 1 | H2: 1
C3: Comunidad | D3: 1 | E3: 1 | F3: 1 | G3: 1 | H3: 1
C4: Medios de comunicación masivos | D4: 1 | E4: 1 | F4: 1 | G4: 1 | H4: 1
B5: <1 mes | C5: Centro de salud | D5: 2.17 | E5: 1 | F5: 1 | G5: 1 | H5: 1
C6: Comunidad | D6: 2.17 | E6: 1 | F6: 1 | G6: 1 | H6: 1
C7: Medios de comunicación masivos | D7: 1 | E7: 1 | F7: 1 | G7: 1 | H7: 1
B8: 1-5 meses | C8: Centro de salud | D8: 1 | E8: 2.48 | F8: 1 | G8: 1 | H8: 1
C9: Comunidad | D9: 1 | E9: 2.48 | F9: 1 | G9: 1 | H9: 1
C10: Medios de comunicación masivos | D10: 1 | E10: 1 | F10: 1 | G10: 1 | H10: 1
B11: 6-11 meses | C11: Centro de salud | D11: 1 | E11: 1 | F11: 1.82 | G11: 1 | H11: 1
C12: Comunidad | D12: 1 | E12: 1 | F12: 1.82 | G12: 1 | H12: 1
C13: Medios de comunicación masivos | D13: 1 | E13: 1 | F13: 1 | G13: 1 | H13: 1
B14: 12-23 meses | C14: Centro de salud | D14: 1 | E14: 1 | F14: 1 | G14: 1.82 | H14: 1
C15: Comunidad | D15: 1 | E15: 1 | F15: 1 | G15: 1.82 | H15: 1
C16: Medios de comunicación masivos | D16: 1 | E16: 1 | F16: 1 | G16: 1 | H16: 1
B17: Todo | C17: Medios de comunicación masivos | D17: 1.05 | E17: 1.05 | F17: 1.05 | G17: 1.05 | H17: 1
A19: Razón de momios para baja talla o retraso en el crecimiento | B19: Mujeres embarazadas | C19: Centro de salud | D19: 1 | E19: 1 | F19: 1 | G19: 1 | H19: 1
C20: Comunidad | D20: 1 | E20: 1 | F20: 1 | G20: 1 | H20: 1
C21: Medios de comunicación masivos | D21: 1 | E21: 1 | F21: 1 | G21: 1 | H21: 1
B22: <1 mes | C22: Centro de salud | D22: 1 | E22: 1 | F22: 1 | G22: 1 | H22: 1
C23: Comunidad | D23: 1 | E23: 1 | F23: 1 | G23: 1 | H23: 1
C24: Medios de comunicación masivos | D24: 1 | E24: 1 | F24: 1 | G24: 1 | H24: 1
B25: 1-5 meses | C25: Centro de salud | D25: 1 | E25: 1 | F25: 1 | G25: 1 | H25: 1
C26: Comunidad | D26: 1 | E26: 1 | F26: 1 | G26: 1 | H26: 1
C27: Medios de comunicación masivos | D27: 1 | E27: 1 | F27: 1 | G27: 1 | H27: 1
B28: 6-11 meses | C28: Centro de salud | D28: 1 | E28: 1 | F28: 1 | G28: 1 | H28: 1
C29: Comunidad | D29: 1 | E29: 1 | F29: 1 | G29: 1 | H29: 1
C30: Medios de comunicación masivos | D30: 1 | E30: 1 | F30: 1 | G30: 1 | H30: 1
B31: 12-23 meses | C31: Centro de salud | D31: 1 | E31: 1 | F31: 1 | G31: 1 | H31: 1
C32: Comunidad | D32: 1 | E32: 1 | F32: 1 | G32: 1 | H32: 1
C33: Medios de comunicación masivos | D33: 1 | E33: 1 | F33: 1 | G33: 1 | H33: 1
B34: Todo | C34: Medios de comunicación masivos | D34: 1 | E34: 1 | F34: 1 | G34: 1 | H34: 1
A36: Razón de momios para alimentación complementaria correcta | B36: Mujeres embarazadas | C36: Centro de salud | D36: 1 | E36: 1 | F36: 1 | G36: 1 | H36: 1
C37: Comunidad | D37: 1 | E37: 1 | F37: 1 | G37: 1 | H37: 1
C38: Medios de comunicación masivos | D38: 1 | E38: 1 | F38: 1 | G38: 1 | H38: 1
B39: <1 mes | C39: Centro de salud | D39: 1 | E39: 1 | F39: 1 | G39: 1 | H39: 1
C40: Comunidad | D40: 1 | E40: 1 | F40: 1 | G40: 1 | H40: 1
C41: Medios de comunicación masivos | D41: 1 | E41: 1 | F41: 1 | G41: 1 | H41: 1
B42: 1-5 meses | C42: Centro de salud | D42: 1 | E42: 1 | F42: 1 | G42: 1 | H42: 1
...

Sheet Riesgos desenlace de nacimiento
A1: Factores de riesgo materno que conducen a los resultados del nacimiento
C2: Nacido a término AEG (Adecuado para la edad gestacional) | D2: Nacido a término PEG (pequeño para la edad gestacional) | E2: Prematuro AEG (adecuado para edad gestacional) | F2: Prematuro PEG (pequeño para la edad gestacional)
A3: Riesgo relativo según el espaciamiento de los nacimientos
B4: El primer nacimiento | C4: 1 | D4: 1 | E4: 1 | F4: 1
B5: menos de 18 meses | C5: 1 | D5: 1.41 | E5: 1.49 | F5: 3.03
B6: 18-23 meses | C6: 1 | D6: 1.18 | E6: 1.1 | F6: 1.77
B7: 24 meses o más | C7: 1 | D7: 1 | E7: 1 | F7: 1
A9: Razón de momios para mujeres con anemia materna | C9: 1 | D9: 1.53 | E9: 1.32 | F9: 1.53
A11: Riesgos para los niños que experimentan desenlaces al nacimiento
A12: Razón de momios para las condiciones
B13: Retraso en el crecimiento (score HAZ < -2) | C13: 1 | D13: 5 | E13: 6.4 | F13: 46.5
B14: MAM (puntuación WHZ entre -3 y -2) | C14: 1 | D14: 2.52 | E14: 1.96 | F14: 4.19
B15: MAS (score WHZ < -3) | C15: 1 | D15: 2.52 | E15: 1.96 | F15: 4.19
A17: Riesgos relativos de las causas de muerte neonatal
B18: Diarrea neonatal | C18: 1 | D18: 1 | E18: 1 | F18: 1
B19: Sepsis neonatal | C19: 1 | D19: 2.07 | E19: 3.39 | F19: 11.89
B20: Neumonía neonatal | C20: 1 | D20: 2.07 | E20: 3.39 | F20: 11.89
B21: Asfixia neonatal | C21: 1 | D21: 2.07 | E21: 3.39 | F21: 11.89
B22: Prematuridad neonatal | C22: 1 | D22: 1 | E22: 999.99 | F22: 999.99
B23: Tétanos neonatal | C23: 1 | D23: 1 | E23: 1 | F23: 1
B24: Anomalías congénitas neonatales | C24: 1 | D24: 1 | E24: 1 | F24: 1
B25: Neonatal otros | C25: 1 | D25: 1 | E25: 1 | F25: 1
A27: Límites inferiores
A28: Factores de riesgo materno que conducen a los resultados del nacimiento
C29: Nacido a término AEG (Adecuado para la edad gestacional) | D29: Nacido a término PEG (pequeño para la edad gestacional) | E29: Prematuro AEG (adecuado para edad gestacional) | F29: Prematuro PEG (pequeño para la edad gestacional)
A30: Riesgo relativo según el espaciamiento de los nacimientos-inferior
B31: El primer nacimiento | C31: =IF(C4=1,1,C4*0.9) -> 1 | D31: =IF(D4=1,1,D4*0.9) -> 1 | E31: =IF(E4=1,1,E4*0.9) -> 1 | F31: =IF(F4=1,1,F4*0.9) -> 1
B32: menos de 18 meses | C32: =IF(C5=1,1,C5*0.9) -> 1 | D32: =IF(D5=1,1,D5*0.9) -> 1.269 | E32: =IF(E5=1,1,E5*0.9) -> 1.341 | F32: =IF(F5=1,1,F5*0.9) -> 2.727
B33: 18-23 meses | C33: =IF(C6=1,1,C6*0.9) -> 1 | D33: =IF(D6=1,1,D6*0.9) -> 1.062 | E33: =IF(E6=1,1,E6*0.9) -> 0.99 | F33: =IF(F6=1,1,F6*0.9) -> 1.593
B34: 24 meses o más | C34: =IF(C7=1,1,C7*0.9) -> 1 | D34: =IF(D7=1,1,D7*0.9) -> 1 | E34: =IF(E7=1,1,E7*0.9) -> 1 | F34: =IF(F7=1,1,F7*0.9) -> 1
A36: Razón de momios para mujeres con anemia materna-inferior | C36: =IF(C9=1,1,C9*0.9) -> 1 | D36: =IF(D9=1,1,D9*0.9) -> 1.377 | E36: =IF(E9=1,1,E9*0.9) -> 1.188 | F36: =IF(F9=1,1,F9*0.9) -> 1.377
A38: Riesgos para los niños que experimentan desenlaces al nacimiento
A39: Razón de momios para las condiciones - inferior
B40: Retraso en el crecimiento (score HAZ < -2)-Inferior | C40: =IF(C13=1,1,C13*0.9) -> 1 | D40: =IF(D13=1,1,D13*0.9) -> 4.5 | E40: =IF(E13=1,1,E13*0.9) -> 5.76 | F40: =IF(F13=1,1,F13*0.9) -> 41.85
B41: MAM (puntuación WHZ entre -3 y -2)-inferior | C41: =IF(C14=1,1,C14*0.9) -> 1 | D41: =IF(D14=1,1,D14*0.9) -> 2.268 | E41: =IF(E14=1,1,E14*0.9) -> 1.764 | F41: =IF(F14=1,1,F14*0.9) -> 3.771
B42: MAS (score WHZ < -3)-Inferior | C42: =IF(C15=1,1,C15*0.9) -> 1 | D42: =IF(D15=1,1,D15*0.9) -> 2.268 | E42: =IF(E15=1,1,E15*0.9) -> 1.764 | F42: =IF(F15=1,1,F15*0.9) -> 3.771
A44: Riesgos relativos de las causas de muerte neonatal - inferior
B45: Diarrea neonatal | C45: =IF(C18=1,1,C18*0.9) -> 1 | D45: =IF(D18=1,1,D18*0.9) -> 1 | E45: =IF(E18=1,1,E18*0.9) -> 1 | F45: =IF(F18=1,1,F18*0.9) -> 1
B46: Sepsis neonatal | C46: =IF(C19=1,1,C19*0.9) -> 1 | D46: =IF(D19=1,1,D19*0.9) -> 1.863 | E46: =IF(E19=1,1,E19*0.9) -> 3.051 | F46: =IF(F19=1,1,F19*0.9) -> 10.701
B47: Neumonía neonatal | C47: =IF(C20=1,1,C20*0.9) -> 1 | D47: =IF(D20=1,1,D20*0.9) -> 1.863 | E47: =IF(E20=1,1,E20*0.9) -> 3.051 | F47: =IF(F20=1,1,F20*0.9) -> 10.701
...

Sheet Riesgos relativos
A1: Riesgo relativo de las causas de muerte según la distribución de talla para la edad (retraso en el crecimiento)
A2: Baja talla o retraso en el crecimiento | B2: Causa de muerte | C2: Estado de HAZ (baja talla) | D2: <1 mes | E2: 1-5 meses | F2: 6-11 meses | G2: 12-23 meses | H2: 24-59 meses
B3: Diarrea | C3: Normal | D3: 1 | E3: 1 | F3: 1 | G3: 1 | H3: 1
C4: Leve | D4: 1 | E4: 1.67 | F4: 1.67 | G4: 1.67 | H4: 1.67
C5: Moderado | D5: 1 | E5: 2.38 | F5: 2.38 | G5: 2.38 | H5: 2.38
C6: Alto | D6: 1 | E6: 6.33 | F6: 6.33 | G6: 6.33 | H6: 6.33
B7: Neumonía | C7: Normal | D7: 1 | E7: 1 | F7: 1 | G7: 1 | H7: 1
C8: Leve | D8: 1 | E8: 1.55 | F8: 1.55 | G8: 1.55 | H8: 1.55
C9: Moderado | D9: 1 | E9: 2.18 | F9: 2.18 | G9: 2.18 | H9: 2.18
C10: Alto | D10: 1 | E10: 6.39 | F10: 6.39 | G10: 6.39 | H10: 6.39
B11: Sarampión | C11: Normal | D11: 1 | E11: 1 | F11: 1 | G11: 1 | H11: 1
C12: Leve | D12: 1 | E12: 1 | F12: 1 | G12: 1 | H12: 1
C13: Moderado | D13: 1 | E13: 2.79 | F13: 2.79 | G13: 2.79 | H13: 2.79
C14: Alto | D14: 1 | E14: 6.01 | F14: 6.01 | G14: 6.01 | H14: 6.01
B15: Malaria | C15: Normal | D15: 1 | E15: 1 | F15: 1 | G15: 1 | H15: 1
C16: Leve | D16: 1 | E16: 1 | F16: 1 | G16: 1 | H16: 1
C17: Moderado | D17: 1 | E17: 1 | F17: 1 | G17: 1 | H17: 1
C18: Alto | D18: 1 | E18: 1 | F18: 1 | G18: 1 | H18: 1
B19: Meningitis | C19: Normal | D19: 1 | E19: 1 | F19: 1 | G19: 1 | H19: 1
C20: Leve | D20: 1 | E20: 1 | F20: 1 | G20: 1 | H20: 1
C21: Moderado | D21: 1 | E21: 1.86 | F21: 1.86 | G21: 1.86 | H21: 1.86
C22: Alto | D22: 1 | E22: 3.01 | F22: 3.01 | G22: 3.01 | H22: 3.01
B23: Otro | C23: Normal | D23: 1 | E23: 1 | F23: 1 | G23: 1 | H23: 1
C24: Leve | D24: 1 | E24: 1 | F24: 1 | G24: 1 | H24: 1
C25: Moderado | D25: 1 | E25: 1.86 | F25: 1.86 | G25: 1.86 | H25: 1.86
C26: Alto | D26: 1 | E26: 3.01 | F26: 3.01 | G26: 3.01 | H26: 3.01
A28: Riesgo relativo de las causas de muerte según la distribución del peso para la talla (emaciación)
A29: Emaciación | B29: Causa de muerte | C29: Estado de la peso para la talla (WHZ) | D29: <1 mes | E29: 1-5 meses | F29: 6-11 meses | G29: 12-23 meses | H29: 24-59 meses
B30: Diarrea | C30: Normal | D30: 1 | E30: 1 | F30: 1 | G30: 1 | H30: 1
C31: Leve | D31: 1 | E31: 1.6 | F31: 1.6 | G31: 1.6 | H31: 1.6
C32: MAM | D32: 1 | E32: 3.41 | F32: 3.41 | G32: 3.41 | H32: 3.41
C33: MAS | D33: 1 | E33: 12.33 | F33: 12.33 | G33: 12.33 | H33: 12.33
B34: Neumonía | C34: Normal | D34: 1 | E34: 1 | F34: 1 | G34: 1 | H34: 1
C35: Leve | D35: 1 | E35: 1.92 | F35: 1.92 | G35: 1.92 | H35: 1.92
C36: MAM | D36: 1 | E36: 4.66 | F36: 4.66 | G36: 4.66 | H36: 4.66
C37: MAS | D37: 1 | E37: 9.68 | F37: 9.68 | G37: 9.68 | H37: 9.68
B38: Sarampión | C38: Normal | D38: 1 | E38: 1 | F38: 1 | G38: 1 | H38: 1
C39: Leve | D39: 1 | E39: 1 | F39: 1 | G39: 1 | H39: 1
C40: MAM | D40: 1 | E40: 2.58 | F40: 2.58 | G40: 2.58 | H40: 2.58
C41: MAS | D41: 1 | E41: 9.63 | F41: 9.63 | G41: 9.63 | H41: 9.63
...

Sheet Razón de momios
A1: Razón de momios de baja talla o retraso en el crecimiento
A2: Condición | C2: <1 mes | D2: 1-5 meses | E2: 6-11 meses | F2: 12-23 meses | G2: 24-59 meses
B3: Dada la baja talla previa (HAZ < -2 en la banda de edad anterior) | C3: N/A | D3: 45 | E3: 361.6 | F3: 174.7 | G3: 174.7
B4: Diarrea (por episodio adicional) | C4: 1.025 | D4: 1.025 | E4: 1.025 | F4: 1.025 | G4: 1.025
A5: Por programa
B6: Suministro público de alimentos complementarios | C6: 1 | D6: 1 | E6: 0.89 | F6: 0.89 | G6: 1
B7: Suplementos nutricionales a base de lípidos | C7: 1 | D7: 1 | E7: 0.88 | F7: 0.88 | G7: 1
B8: Transferencias de efectivo | C8: 1 | D8: 1 | E8: 1 | F8: 0.808 | G8: 0.808
B9: Suplementos nutricionales a base de lípidos en pequeñas cantidades | C9: 1 | D9: 1 | E9: 0.88 | F9: 0.88 | G9: 1
B10: Suplementación con zinc | C10: 1 | D10: 1 | E10: 1 | F10: 1 | G10: 1
A12: Razón de momios de lactancia materna adecuada por programa
B13: Método de la madre canguro | C13: 1 | D13: 1.39 | E13: 1 | F13: 1 | G13: 1
A15: Otras razones de momios
A16: Emaciación | B16: Para MAS por episodio adicional de diarrea | C16: 1.024 | D16: 1.024 | E16: 1.024 | F16: 1.024 | G16: 1.024
B17: Para MAM por episodio adicional de diarrea | C17: 1.024 | D17: 1.024 | E17: 1.024 | F17: 1.024 | G17: 1.024
A18: Anemia | B18: Para anemia por episodio adicional de diarrea grave | C18: 1 | D18: 1 | E18: 1 | F18: 1 | G18: 1
A20: Razón de momios para el espaciamiento óptimo de los nacimientos por programa
