Workbook
Name abortion: 'Entradas de población-año base'!$C$38
Name abortion: 'Entradas de población-año base'!$C$41
Name comm_deliv: 'Tratamiento de la MAS'!$D$3
Name diarrhoea_1_5mo: 'Entradas de población-año base'!$C$52
Name diarrhoea_12_23mo: 'Entradas de población-año base'!$C$54
Name diarrhoea_1mo: 'Entradas de población-año base'!$C$51
Name diarrhoea_24_59mo: 'Entradas de población-año base'!$C$55
Name diarrhoea_6_11mo: 'Entradas de población-año base'!$C$53
Name end_year: 'Entradas de población-año base'!$C$4
Name famplan_unmet_need: 'Entradas de población-año base'!$C$13
Name food_insecure: 'Entradas de población-año base'!$C$8
Name frac_children_health_facility: 'Entradas de población-año base'!$C$12
Name frac_diarrhea_severe: 'Entradas de población-año base'!$C$58
Name frac_maize: 'Entradas de población-año base'!$C$19
Name frac_malaria_risk: 'Entradas de población-año base'!$C$9
Name frac_mam_1_5months: 'Distribución estado nutricional'!$D$10
Name frac_mam_12_23months: 'Distribución estado nutricional'!$F$10
Name frac_mam_1month: 'Distribución estado nutricional'!$C$10
Name frac_mam_24_59months: 'Distribución estado nutricional'!$G$10
Name frac_mam_6_11months: 'Distribución estado nutricional'!$E$10
Name frac_MAMtoSAM: 'Entradas de población-año base'!#REF!
Name frac_other_staples: 'Entradas de población-año base'!$C$20
Name frac_PW_health_facility: 'Entradas de población-año base'!$C$11
Name frac_rice: 'Entradas de población-año base'!$C$17
Name frac_sam_1_5months: 'Distribución estado nutricional'!$D$11
Name frac_sam_12_23months: 'Distribución estado nutricional'!$F$11
Name frac_sam_1month: 'Distribución estado nutricional'!$C$11
Name frac_sam_24_59months: 'Distribución estado nutricional'!$G$11
Name frac_sam_6_11months: 'Distribución estado nutricional'!$E$11
Name frac_SAMtoMAM: 'Entradas de población-año base'!#REF!
Name frac_subsistence_farming: 'Entradas de población-año base'!$C$16
Name frac_wheat: 'Entradas de población-año base'!$C$18
Name infant_mortality: 'Entradas de población-año base'!$C$38
Name iron_deficiency_anaemia: 'Entradas de población-año base'!$C$59
Name manage_mam: 'Tratamiento de la MAS'!$D$2
Name maternal_mortality: 'Entradas de población-año base'!$C$40
Name neonatal_mortality: 'Entradas de población-año base'!$C$37
Name Percentage_of_pregnant_women_attending_health_facility: 'Entradas de población-año base'!$C$11
Name preterm_AGA: 'Entradas de población-año base'!$C$46
Name preterm_SGA: 'Entradas de población-año base'!$C$45
Name school_attendance: 'Entradas de población-año base'!$C$10
Name start_year: 'Entradas de población-año base'!$C$3
Name stillbirth: 'Entradas de población-año base'!$C$39
Name stillbirth: 'Entradas de población-año base'!$C$42
Name term_AGA: 'Entradas de población-año base'!$C$48
Name term_SGA: 'Entradas de población-año base'!$C$47
Name U5_mortality: 'Entradas de población-año base'!$C$39

Sheet Entradas de población-año base
A1: Datos del año de referencia | B1: Field | C1: Datos
A2: Años de proyección
B3: Año de referencia (año de inicio de la proyección) | C3: 2024
B4: Año final | C4: 2035
A6: Datos poblacionales
B7: Población infantil menor de 5 años | C7: 3688334
B8: Porcentaje de población con inseguridad alimentaria (pobre por defecto) | C8: 0.679
B9: Porcentaje de población con riesgo de malaria | C9: 0.86
B10: Asistencia a la escuela (porcentaje de mujeres de 15 a 19 años) | C10: 0.1197697
B11: Porcentaje de mujeres embarazadas que acuden a un centro de salud | C11: 1
B12: Porcentaje de niños que acuden a un centro de salud | C12: 1
B13: Necesidad insatisfecha de planificación familiar | C13: 0.825
A15: Alimento
B16: Fracción de agricultura de subsistencia | C16: 0.1
B17: Fracción que consume arroz como principal alimento básico | C17: 0.01
B18: Fracción que consume trigo como principal alimento básico | C18: 0.98
B19: Fracción que consume maíz como principal alimento básico | C19: 0.01
B20: Fracción de otros alimentos básicos como alimento principal | C20: =1-frac_rice-frac_wheat-frac_maize -> 0
A22: Distribución de edad de las mujeres embarazadas
B23: Porcentaje de mujeres embarazadas de 15 a 19 años | C23: 0.1394
B24: Porcentaje de mujeres embarazadas de 20 a 29 años | C24: 0.4439
B25: Porcentaje de mujeres embarazadas de 30 a 39 años | C25: 0.3323
B26: Porcentaje de mujeres embarazadas de 40 a 49 años | C26: 0.0844
A28: Espaciamiento entre los nacimientos
B29: El primer nacimiento | C29: 0.15293756
B30: menos de 18 meses | C30: 0.094746757
B31: 18-23 meses | C31: 0.16092717
B32: 24 meses o más | C32: 0.59138851
B33: Total (debe ser el 100%) | C33: =SUM(C29:C32) -> 1
A35: Mortalidad y factores de riesgo en el año de referencia
A36: Mortalidad
B37: Mortalidad neonatal (por cada 1.000 nacidos vivos) | C37: 32.34702
B38: Mortalidad infantil (por cada 1.000 nacidos vivos) | C38: 66.04942
B39: Mortalidad de menores de 5 años (por cada 1.000 nacidos vivos) | C39: 107.06548
B40: Mortalidad materna (por cada 1.000 nacidos vivos) | C40: 10.63
B41: Fracción de embarazos que terminan en aborto espontáneo | C41: 0.12
B42: Nacidos muertos (por cada 1.000 nacimientos totales) | C42: 25.27843
A44: Distribución del desenlace del nacimiento
B45: Prematuro PEG (pequeño para la edad gestacional) | C45: 0.007928
B46: Prematuro AEG (adecuado para edad gestacional) | C46: 0.0851857
...

Sheet Proyecciones demográficas
A1: año | B1: Número de nacimientos | C1: WRA: 15-19 años (mujeres en edad reproductiva) | D1: WRA: 20-29 años (mujeres en edad reproductiva) | E1: WRA: 30-39 años (mujeres en edad reproductiva) | F1: WRA: 40-49 años (mujeres en edad reproductiva) | G1: Total mujeres en edad reproductiva | H1: Estimación de mujeres embarazadas | I1: mujeres en edad reproductiva no embarazadas
A2: =start_year -> 2024 | B2: 878222 | C2: 1091728.5 | D2: 1690707 | E2: 1124774.5 | F2: 736490 | G2: =C2+D2+E2+F2 -> 4643700 | H2: =(B2 + stillbirth*B2/(1000-stillbirth))/(1-abortion) -> 1023861.1 | I2: =G2-H2 -> 3619838.9
A3: =IF($A$2+ROW(A3)-2<=end_year,A2+1,"") -> 2025 | B3: 907325 | C3: 1120017 | D3: 1746558.5 | E3: 1177105.5 | F3: 762201 | G3: =C3+D3+E3+F3 -> 4805882 | H3: =(B3 + stillbirth*B3/(1000-stillbirth))/(1-abortion) -> 1057790.4 | I3: =G3-H3 -> 3748091.6
A4: =IF($A$2+ROW(A4)-2<=end_year,A3+1,"") -> 2026 | B4: 909765 | C4: 1145637.5 | D4: 1772691 | E4: 1219563 | F4: 780226.5 | G4: =C4+D4+E4+F4 -> 4918118 | H4: =(B4 + stillbirth*B4/(1000-stillbirth))/(1-abortion) -> 1060635.1 | I4: =G4-H4 -> 3857482.9
A5: =IF($A$2+ROW(A5)-2<=end_year,A4+1,"") -> 2027 | B5: 914247 | C5: 1177365.5 | D5: 1805574 | E5: 1270107.5 | F5: 803090.5 | G5: =C5+D5+E5+F5 -> 5056137.5 | H5: =(B5 + stillbirth*B5/(1000-stillbirth))/(1-abortion) -> 1065860.3 | I5: =G5-H5 -> 3990277.2
A6: =IF($A$2+ROW(A6)-2<=end_year,A5+1,"") -> 2028 | B6: 922811 | C6: 1213799 | D6: 1847263 | E6: 1325416 | F6: 832073.5 | G6: =C6+D6+E6+F6 -> 5218551.5 | H6: =(B6 + stillbirth*B6/(1000-stillbirth))/(1-abortion) -> 1075844.5 | I6: =G6-H6 -> 4142707
A7: =IF($A$2+ROW(A7)-2<=end_year,A6+1,"") -> 2029 | B7: 935384 | C7: 1252049 | D7: 1889547.5 | E7: 1380229 | F7: 864586 | G7: =C7+D7+E7+F7 -> 5386411.5 | H7: =(B7 + stillbirth*B7/(1000-stillbirth))/(1-abortion) -> 1090502.6 | I7: =G7-H7 -> 4295908.9
A8: =IF($A$2+ROW(A8)-2<=end_year,A7+1,"") -> 2030 | B8: 945060 | C8: 1290869.5 | D8: 1933829.5 | E8: 1433948 | F8: 899774.5 | G8: =C8+D8+E8+F8 -> 5558421.5 | H8: =(B8 + stillbirth*B8/(1000-stillbirth))/(1-abortion) -> 1101783.2 | I8: =G8-H8 -> 4456638.3
A9: =IF($A$2+ROW(A9)-2<=end_year,A8+1,"") -> 2031 | B9: 957376 | C9: 1328374 | D9: 1981713 | E9: 1487379 | F9: 938839.5 | G9: =C9+D9+E9+F9 -> 5736305.5 | H9: =(B9 + stillbirth*B9/(1000-stillbirth))/(1-abortion) -> 1116141.6 | I9: =G9-H9 -> 4620163.9
A10: =IF($A$2+ROW(A10)-2<=end_year,A9+1,"") -> 2032 | B10: 964929 | C10: 1364159.5 | D10: 2035302 | E10: 1537493 | F10: 983509.5 | G10: =C10+D10+E10+F10 -> 5920464 | H10: =(B10 + stillbirth*B10/(1000-stillbirth))/(1-abortion) -> 1124947.1 | I10: =G10-H10 -> 4795516.9
A11: =IF($A$2+ROW(A11)-2<=end_year,A10+1,"") -> 2033 | B11: 974881 | C11: 1399808.5 | D11: 2093637.5 | E11: 1582289 | F11: 1029758.5 | G11: =C11+D11+E11+F11 -> 6105493.5 | H11: =(B11 + stillbirth*B11/(1000-stillbirth))/(1-abortion) -> 1136549.5 | I11: =G11-H11 -> 4968944
A12: =IF($A$2+ROW(A12)-2<=end_year,A11+1,"") -> 2034 | B12: 984264 | C12: 1436714.5 | D12: 2153666 | E12: 1627353 | F12: 1073131 | G12: =C12+D12+E12+F12 -> 6290864.5 | H12: =(B12 + stillbirth*B12/(1000-stillbirth))/(1-abortion) -> 1147488.5 | I12: =G12-H12 -> 5143376
A13: =IF($A$2+ROW(A13)-2<=end_year,A12+1,"") -> 2035 | B13: 993785 | C13: 1474684.5 | D13: 2214750 | E13: 1674509 | F13: 1117838.5 | G13: =C13+D13+E13+F13 -> 6481782 | H13: =(B13 + stillbirth*B13/(1000-stillbirth))/(1-abortion) -> 1158588.4 | I13: =G13-H13 -> 5323193.6
A14: =IF($A$2+ROW(A14)-2<=end_year,A13+1,"")
A15: =IF($A$2+ROW(A15)-2<=end_year,A14+1,"")
A16: =IF($A$2+ROW(A16)-2<=end_year,A15+1,"")
A17: =IF($A$2+ROW(A17)-2<=end_year,A16+1,"")
A18: =IF($A$2+ROW(A18)-2<=end_year,A17+1,"")
A19: =IF($A$2+ROW(A19)-2<=end_year,A18+1,"")
A20: =IF($A$2+ROW(A20)-2<=end_year,A19+1,"")
A21: =IF($A$2+ROW(A21)-2<=end_year,A20+1,"")
A22: =IF($A$2+ROW(A22)-2<=end_year,A21+1,"")
A23: =IF($A$2+ROW(A23)-2<=end_year,A22+1,"")
A24: =IF($A$2+ROW(A24)-2<=end_year,A23+1,"")
A25: =IF($A$2+ROW(A25)-2<=end_year,A24+1,"")
... A37: =IF($A$2+ROW(A37)-2<=end_year,A36+1,"")
A38: =IF($A$2+ROW(A38)-2<=end_year,A37+1,"") | G38: =C38+D38+E38+F38 -> 0 | H38: =(B38 + stillbirth*B38/(1000-stillbirth))/(1-abortion) -> 0 | I38: =G38-H38 -> 0
A39: =IF($A$2+ROW(A39)-2<=end_year,A38+1,"") | G39: =C39+D39+E39+F39 -> 0 | H39: =(B39 + stillbirth*B39/(1000-stillbirth))/(1-abortion) -> 0 | I39: =G39-H39 -> 0
A40: =IF($A$2+ROW(A40)-2<=end_year,A39+1,"") | G40: =C40+D40+E40+F40 -> 0 | H40: =(B40 + stillbirth*B40/(1000-stillbirth))/(1-abortion) -> 0 | I40: =G40-H40 -> 0

Sheet Causas de muerte
A1: ="Porcentaje de muertes en el año de referencia ("&start_year&") atribuible a la causa" -> Porcentaje de muertes en el año de referencia (2024) atribuible a la causa
A2: Neonatal | B2: Causas | C2: <1 mes
B3: Diarrea neonatal | C3: 0.036768003
B4: Sepsis neonatal | C4: 0.080138679
B5: Neumonía neonatal | C5: 0.13380843
B6: Asfixia neonatal | C6: 0.25636247
B7: Prematuridad neonatal | C7: 0.32692927
B8: Tétanos neonatal | C8: 0.021870639
B9: Anomalías congénitas neonatales | C9: 0.038326146
B10: Neonatal otros | C10: 0.10579637
B11: Total (debe ser el 100%) | C11: =SUM(C3:C10) -> 1
A13: Niños | B13: Causas | C13: 1-5 meses | D13: 6-11 meses | E13: 12-23 meses | F13: 24-59 meses
B14: Diarrea | C14: 0.20961509 | D14: 0.20961509 | E14: 0.20961509 | F14: 0.20961509
B15: Neumonía | C15: 0.3029018 | D15: 0.3029018 | E15: 0.3029018 | F15: 0.3029018
B16: Meningitis | C16: 0.049506531 | D16: 0.049506531 | E16: 0.049506531 | F16: 0.049506531
B17: Sarampión | C17: 0.045077341 | D17: 0.045077341 | E17: 0.045077341 | F17: 0.045077341
B18: Malaria | C18: 0.17951082 | D18: 0.17951082 | E18: 0.17951082 | F18: 0.17951082
B19: Tosferina | C19: 0.01549908 | D19: 0.01549908 | E19: 0.01549908 | F19: 0.01549908
B20: SIDA | C20: 0.0095918804 | D20: 0.0095918804 | E20: 0.0095918804 | F20: 0.0095918804
B21: Lesión | C21: 0.032982816 | D21: 0.032982816 | E21: 0.032982816 | F21: 0.032982816
B22: Otro | C22: 0.15531463 | D22: 0.15531463 | E22: 0.15531463 | F22: 0.15531463
B23: Total (debe ser el 100%) | C23: =SUM(C14:C22) -> 1 | D23: =SUM(D14:D22) -> 1 | E23: =SUM(E14:E22) -> 1 | F23: =SUM(F14:F22) -> 1
A25: Mujeres embarazadas | B25: Causas | C25: Mujeres embarazadas
B26: Hemorragia pre-parto | C26: 0.088804052
B27: Hemorragia intraparto | C27: 0.008650573
B28: Hemorragia posparto | C28: 0.15426393
B29: Trastornos hipertensivos | C29: 0.16852035
B30: Sepsis | C30: 0.10688997
B31: Aborto | C31: 0.10946105
B32: Embolia | C32: 0.018636323
B33: Otras causas directas | C33: 0.08322101
B34: Causas indirectas | C34: 0.26155274
B35: Total (debe ser el 100%) | C35: =SUM(C26:C34) -> 1

Sheet Distribución estado nutricional
A1: ="Porcentaje de población en cada categoría en el año de referencia ("&start_year&")" -> Porcentaje de población en cada categoría en el año de referencia (2024) | B1: Estado | C1: <1 mes | D1: 1-5 meses | E1: 6-11 meses | F1: 12-23 meses | G1: 24-59 meses
A2: Retraso en el crecimiento (Talla para la edad) | B2: Normal (score HAZ > -1) | C2: =IFERROR(1-_xlfn.NORM.DIST(_xlfn.NORM.INV(SUM(C4:C5), 0, 1) + 1, 0, 1, TRUE), "") -> 0.57527705 | D2: =IFERROR(1-_xlfn.NORM.DIST(_xlfn.NORM.INV(SUM(D4:D5), 0, 1) + 1, 0, 1, TRUE), "") -> 0.57527705 | E2: =IFERROR(1-_xlfn.NORM.DIST(_xlfn.NORM.INV(SUM(E4:E5), 0, 1) + 1, 0, 1, TRUE), "") -> 0.38657967 | F2: =IFERROR(1-_xlfn.NORM.DIST(_xlfn.NORM.INV(SUM(F4:F5), 0, 1) + 1, 0, 1, TRUE), "") -> 0.19527089 | G2: =IFERROR(1-_xlfn.NORM.DIST(_xlfn.NORM.INV(SUM(G4:G5), 0, 1) + 1, 0, 1, TRUE), "") -> 0.21072497
B3: Leve (score HAZ entre -2 y -1) | C3: =IFERROR(_xlfn.NORM.DIST(_xlfn.NORM.INV(SUM(C4:C5), 0, 1) + 1, 0, 1, TRUE) - SUM(C4:C5), "") -> 0.30766545 | D3: =IFERROR(_xlfn.NORM.DIST(_xlfn.NORM.INV(SUM(D4:D5), 0, 1) + 1, 0, 1, TRUE) - SUM(D4:D5), "") -> 0.30766545 | E3: =IFERROR(_xlfn.NORM.DIST(_xlfn.NORM.INV(SUM(E4:E5), 0, 1) + 1, 0, 1, TRUE) - SUM(E4:E5), "") -> 0.37511213 | F3: =IFERROR(_xlfn.NORM.DIST(_xlfn.NORM.INV(SUM(F4:F5), 0, 1) + 1, 0, 1, TRUE) - SUM(F4:F5), "") -> 0.36093821 | G3: =IFERROR(_xlfn.NORM.DIST(_xlfn.NORM.INV(SUM(G4:G5), 0, 1) + 1, 0, 1, TRUE) - SUM(G4:G5), "") -> 0.36700583
B4: Moderado (score HAZ entre -3 y -2) | C4: 0.0684786 | D4: 0.0684786 | E4: 0.1344006 | F4: 0.2166221 | G4: 0.210056
B5: Alto (puntuación HAZ < -3) | C5: 0.0485789 | D5: 0.0485789 | E5: 0.1039076 | F5: 0.2271688 | G5: 0.2122132
A8: Emaciación (peso para la talla) | B8: Normal (score WHZ > -1) | C8: =IFERROR(1-_xlfn.NORM.DIST(_xlfn.NORM.INV(SUM(C10:C11), 0, 1) + 1, 0, 1, TRUE), "") -> 0.50361625 | D8: =IFERROR(1-_xlfn.NORM.DIST(_xlfn.NORM.INV(SUM(D10:D11), 0, 1) + 1, 0, 1, TRUE), "") -> 0.50361625 | E8: =IFERROR(1-_xlfn.NORM.DIST(_xlfn.NORM.INV(SUM(E10:E11), 0, 1) + 1, 0, 1, TRUE), "") -> 0.42929326 | F8: =IFERROR(1-_xlfn.NORM.DIST(_xlfn.NORM.INV(SUM(F10:F11), 0, 1) + 1, 0, 1, TRUE), "") -> 0.4504707 | G8: =IFERROR(1-_xlfn.NORM.DIST(_xlfn.NORM.INV(SUM(G10:G11), 0, 1) + 1, 0, 1, TRUE), "") -> 0.58276678
B9: Leve (score WHZ entre -2 y -1) | C9: =IFERROR(_xlfn.NORM.DIST(_xlfn.NORM.INV(SUM(C10:C11), 0, 1) + 1, 0, 1, TRUE) - SUM(C10:C11), "") -> 0.33991195 | D9: =IFERROR(_xlfn.NORM.DIST(_xlfn.NORM.INV(SUM(D10:D11), 0, 1) + 1, 0, 1, TRUE) - SUM(D10:D11), "") -> 0.33991195 | E9: =IFERROR(_xlfn.NORM.DIST(_xlfn.NORM.INV(SUM(E10:E11), 0, 1) + 1, 0, 1, TRUE) - SUM(E10:E11), "") -> 0.36511884 | F9: =IFERROR(_xlfn.NORM.DIST(_xlfn.NORM.INV(SUM(F10:F11), 0, 1) + 1, 0, 1, TRUE) - SUM(F10:F11), "") -> 0.3588859 | G9: =IFERROR(_xlfn.NORM.DIST(_xlfn.NORM.INV(SUM(G10:G11), 0, 1) + 1, 0, 1, TRUE) - SUM(G10:G11), "") -> 0.30389732
B10: MAM (puntuación WHZ entre -3 y -2) | C10: 0.0959345 | D10: 0.0959345 | E10: 0.128469 | F10: 0.1263933 | G10: 0.0806715
B11: MAS (score WHZ < -3) | C11: 0.0605373 | D11: 0.0605373 | E11: 0.0771189 | F11: 0.0642501 | G11: 0.0326644
A13: Anemia | C13: <1 mes | D13: 1-5 meses | E13: 6-11 meses | F13: 12-23 meses | G13: 24-59 meses | H13: PW: 15-19 años | I13: PW: 20-29 años | J13: PW: 30-39 años | K13: PW: 40-49 años | L13: WRA: 15-19 años (mujeres en edad reproductiva) | M13: WRA: 20-29 años (mujeres en edad reproductiva) | N13: WRA: 30-39 años (mujeres en edad reproductiva) | O13: WRA: 40-49 años (mujeres en edad reproductiva)
B14: Prevalencia de anemia | C14: 0.73521599 | D14: 0.72018265 | E14: 0.72018265 | F14: 0.82913691 | G14: 0.82913691 | H14: 0.521 | I14: 0.521 | J14: 0.521 | K14: 0.521 | L14: 0.471 | M14: 0.471 | N14: 0.471 | O14: 0.471
B15: Prevalencia de anemia por deficiencia de hierro | C15: =iron_deficiency_anaemia*C14 -> 0.31991527 | D15: =iron_deficiency_anaemia*D14 -> 0.3133738 | E15: =iron_deficiency_anaemia*E14 -> 0.3133738 | F15: =iron_deficiency_anaemia*F14 -> 0.36078317 | G15: =iron_deficiency_anaemia*G14 -> 0.36078317 | H15: =iron_deficiency_anaemia*H14 -> 0.22670325 | I15: =iron_deficiency_anaemia*I14 -> 0.22670325 | J15: =iron_deficiency_anaemia*J14 -> 0.22670325 | ... O15: =iron_deficiency_anaemia*O14 -> 0.2049467

Sheet Distribución de lactancia
A1: ="Porcentaje de niños en cada categoría en el año de referencia ("&start_year&")" -> Porcentaje de niños en cada categoría en el año de referencia (2024) | B1: Estado | C1: <1 mes | D1: 1-5 meses | E1: 6-11 meses | F1: 12-23 meses | G1: 24-59 meses
A2: Lactancia materna | B2: Exclusivo | C2: 0.2220383 | D2: 0.1640936 | E2: 0 | F2: 0 | G2: 0
B3: Predominante | C3: 0.5179011 | D3: 0.4032494 | E3: 0 | F3: 0 | G3: 0
B4: Parcial | C4: 0.2476181 | D4: 0.4201106 | E4: 0.9684 | F4: 0.727193 | G4: 0
B5: Ninguno | C5: =1-SUM(C2:C4) -> 0.0124425 | D5: =1-SUM(D2:D4) -> 0.0125464 | E5: =1-SUM(E2:E4) -> 0.0316 | F5: =1-SUM(F2:F4) -> 0.272807 | G5: =1-SUM(G2:G4) -> 1

Sheet Tendencias temporales
A1: Riesgo | B1: Población | C1: 2010 | D1: 2011 | E1: 2012 | F1: 2013 | G1: 2014 | H1: 2015 | I1: 2016 | J1: 2017 | K1: 2018
A2: Prevalencia del retraso del crecimiento (%) | B2: Niños de 0 a 59 meses
A4: Prevalencia de emaciación (%) | B4: Niños de 0 a 59 meses
A6: Prevalencia de anemia (%) | B6: Niños de 0 a 59 meses
B7: Mujeres embarazadas
B8: Mujeres en edad reproductiva
A10: Prevalencia de lactancia materna adecuada para la edad | B10: Niños de 0 a 5 meses
B11: Niños de 6 a 23 meses
A13: Mortalidad | B13: Menores de cinco años (muertes por cada 1.000 nacimientos)
B14: Materna (muertes por cada 1.000 nacimientos)

Sheet Variables económicas   
A1: Parameter | B1: Value
A2: PIB per cápita | B2: 716.80438
A3: Crecimiento anual del PIB | B3: 0.03
A4: Participación del trabajo en el PIB | B4: 0.42012
A5: Descuento temporal (costos) | B5: 0.03
A6: Descuento temporal (beneficios) | B6: 0.03
A7: Edad de inicio de la productividad laboral | B7: 18
A8: Edad a la que se acaba la productividad laboral | B8: 65
A9: Participación laboral femenina | B9: 0.48591
A10: Porcentaje de ingresos vitales que realmente se han ganado | B10: 0.9
A11: Reducción total de ingresos vitales en individuos con retraso del crecimiento | B11: 0.66
A12: Disminución de productividad debido a la anemia infantil (%) | B12: 0.025
A13: Disminución de productividad debido al bajo peso al nacer (%) | B13: 0.075
... A18: Porcentaje de mortinatos a incluir en la pérdida de productividad | B18: 0
A21: Life tables | B21: Age 5 | C21: Age 10 | D21: Age 15 | E21: Age 20 | F21: Age 25 | G21: Age 30 | H21: Age 35 | I21: Age 40 | J21: Age 45 | K21: Age 50 | L21: Age 55 | M21: Age 60 | N21: Age 65 | O21: Age 70
A22: Número de personas vivas restantes (empezando con 100.000 nacimientos) | B22: 88505.869 | C22: 87162.077 | D22: 86236.433 | E22: 85581.111 | F22: 84708.149 | G22: 83616.63 | H22: 82211.269 | I22: 80347.488 | J22: 77800.512 | K22: 74536.829 | L22: 70063.978 | M22: 64300.853 | N22: 56534.872 | O22: 47041.989

Sheet Paquetes de IYCF
A1: Paquete alimentación del lactante y del niño pequeño (IYCF) | B1: Población objetivo | C1: Centro de salud | D1: Comunidad | E1: Medios de comunicación masivos
A2: IYCF 1-alimentación del lactante y del niño pequeño | B2: Mujeres embarazadas | E2: =IF(E$7="","",E$7)
B3: <1 mes | D3: x | E3: =IF(E$7="","",E$7)
B4: 1-5 meses | D4: x | E4: =IF(E$7="","",E$7)
B5: 6-11 meses | D5: x | E5: =IF(E$7="","",E$7)
B6: 12-23 meses | D6: x | E6: =IF(E$7="","",E$7)
B7: Todo
A9: IYCF 2-alimentación del lactante y del niño pequeño | B9: Mujeres embarazadas | E9: =IF(E$7="","",E$7)
B10: <1 mes | E10: =IF(E$7="","",E$7)
B11: 1-5 meses | E11: =IF(E$7="","",E$7)
B12: 6-11 meses | D12: x | E12: =IF(E$7="","",E$7)
B13: 12-23 meses | D13: x | E13: =IF(E$7="","",E$7)
B14: Todo
A16: IYCF 3-alimentación del lactante y del niño pequeño | B16: Mujeres embarazadas | D16: x | E16: =IF(E$7="","",E$7)
B17: <1 mes | D17: x | E17: =IF(E$7="","",E$7)
B18: 1-5 meses | D18: x | E18: =IF(E$7="","",E$7)
B19: 6-11 meses | D19: x | E19: =IF(E$7="","",E$7)
B20: 12-23 meses | D20: x | E20: =IF(E$7="","",E$7)
B21: Todo

Sheet Tratamiento de la MAS
A1: Field | B1: Por defecto | C1: Extensión | D1: Añadir extensión
A2: Programa | B2: Tratamiento de la MAS | C2: Manejo de la Malnutrición Aguda Moderada (MAM)
A3: Método de entrega | B3: Centro de salud | C3: Basado en la comunidad

Sheet Costo y cobertura del programa
A1: Programa | B1: ="Cobertura de referencia ("&start_year&")" -> Cobertura de referencia (2024) | C1: Cobertura de saturación de la población objetivo | D1: Costo unitario (US$) | E1: Relación costo-cobertura | F1: Aumento máximo anual | G1: Disminución máxima anual
A2: Suplemento energético-proteico equilibrado | B2: 0 | C2: 0.95 | D2: 18.025736 | E2: Lineal (costo marginal constante) [por defecto] | F2: 1 | G2: 1
A3: Suplemento con calcio | B3: 0 | C3: 0.95 | D3: 18.025736 | E3: Lineal (costo marginal constante) [por defecto] | F3: 1 | G3: 1
A4: Transferencias de efectivo | B4: 0 | C4: 0.95 | D4: 4.1560553 | E4: Lineal (costo marginal constante) [por defecto] | F4: 1 | G4: 1
A5: Retraso en el pinzamiento del cordón umbilical | B5: 0 | C5: 0.95 | D5: 0.11773528 | E5: Lineal (costo marginal constante) [por defecto] | F5: 1 | G5: 1
A6: Planificación familiar | B6: 0 | C6: 0.95 | D6: 99.99 | E6: Lineal (costo marginal constante) [por defecto] | F6: 1 | G6: 1
A7: Enriquecimiento del maíz con hierro y ácido fólico | B7: 0 | C7: 0.95 | D7: 0.21395532 | E7: Lineal (costo marginal constante) [por defecto] | F7: 1 | G7: 1
A8: Enriquecimiento del arroz con hierro y ácido fólico | B8: 0.5 | C8: 0.95 | D8: 0.788482 | E8: Lineal (costo marginal constante) [por defecto] | F8: 1 | G8: 1
A9: Enriquecimiento de la harina de trigo con hierro y ácido fólico | B9: 0.5 | C9: 0.95 | D9: 0.23003335 | E9: Lineal (costo marginal constante) [por defecto] | F9: 1 | G9: 1
A10: Suplementación con hierro y ácido fólico (comunidad) | B10: 0.1104295 | C10: 0.95 | D10: 15.044942 | E10: Lineal (costo marginal constante) [por defecto] | F10: 1 | G10: 1
A11: Suplementación con hierro y ácido fólico (centro de salud) | B11: 0 | C11: 0.95 | D11: 15.044942 | E11: Lineal (costo marginal constante) [por defecto] | F11: 1 | G11: 1
A12: Suplementación con hierro y ácido fólico (minorista) | B12: 0 | C12: 0.95 | D12: 15.044942 | E12: Lineal (costo marginal constante) [por defecto] | F12: 1 | G12: 1
A13: Suplementación con hierro y ácido fólico (escuela) | B13: 0 | C13: 0.95 | D13: 15.044942 | E13: Lineal (costo marginal constante) [por defecto] | F13: 1 | G13: 1
... A39: Suplementación con zinc | B39: 0 | C39: 0.95 | D39: 3.4125 | E39: Lineal (costo marginal constante) [por defecto] | F39: 1 | G39: 1

Sheet Dependencias del programa
A1: Programa | B1: Exclusión de intervención dependiente | C1: Dependencia de otra intervención
A2: Suplementación con hierro y ácido fólico para mujeres embarazadas (comunidad) | B2: Suplementación con micronutrientes múltiples
A3: Suplementación con hierro y ácido fólico para mujeres embarazadas (centro de salud) | B3: Suplementación con micronutrientes múltiples
A4: Suministro público de alimentos complementarios | B4: Suplementos nutricionales a base de lípidos
A5: Suministro público de alimentos complementarios | B5: Suplementos nutricionales a base de lípidos en pequeñas cantidades
A6: Micronutrientes en polvo | B6: Suplementos nutricionales a base de lípidos en pequeñas cantidades
A7: Suplementación con zinc | B7: Suplementos nutricionales a base de lípidos en pequeñas cantidades

Sheet Programas de referencia
A1: Programa
A2: Planificación familiar
A3: IPTp-Tratamiento preventivo intermitente de la malaria en el embarazo
A4: Mosquiteros tratados con insecticida de larga duración
A5: WASH: Lavado de manos
A6: WASH: Eliminación higiénica de residuos
A7: WASH: Mejora del saneamiento
A8: WASH: Mejora de la fuente de agua
A9: WASH: Agua corriente o entubada
A10: Tratamiento de la MAS

Sheet Incidencia de las afecciones
A1: Condición | B1: <1 mes | C1: 1-5 meses | D1: 6-11 meses | E1: 12-23 meses | F1: 24-59 meses
A2: Diarrea | B2: ='Entradas de población-año base'!C51 -> 5.408 | C2: ='Entradas de población-año base'!C52 -> 5.408 | D2: ='Entradas de población-año base'!C53 -> 9.23 | E2: ='Entradas de población-año base'!C54 -> 8.684 | F2: ='Entradas de población-año base'!C55 -> 4.3766667
A3: MAM | B3: =frac_mam_1month * 2.6 -> 0.2494297 | C3: =frac_mam_1_5months * 2.6 -> 0.2494297 | D3: =frac_mam_6_11months * 2.6 -> 0.3340194 | E3: =frac_mam_12_23months * 2.6 -> 0.32862258 | F3: =frac_mam_24_59months * 2.6 -> 0.2097459
A4: MAS | B4: =frac_sam_1month * 2.6 -> 0.15739698 | C4: =frac_sam_1_5months * 2.6 -> 0.15739698 | D4: =frac_sam_6_11months * 2.6 -> 0.20050914 | E4: =frac_sam_12_23months * 2.6 -> 0.16705026 | F4: =frac_sam_24_59months * 2.6 -> 0.08492744

Sheet Población objetivo del programa
A1: Amplio grupo de población | B1: Programa | C1: <1 mes | D1: 1-5 meses | E1: 6-11 meses | F1: 12-23 meses | G1: 24-59 meses | H1: PW: 15-19 años | I1: PW: 20-29 años | J1: PW: 30-39 años | K1: PW: 40-49 años | L1: WRA: 15-19 años (mujeres en edad reproductiva) | M1: WRA: 20-29 años (mujeres en edad reproductiva) | N1: WRA: 30-39 años (mujeres en edad reproductiva) | O1: WRA: 40-49 años (mujeres en edad reproductiva)
A2: Niños | B2: Transferencias de efectivo | C2: 0 | D2: 0 | E2: =food_insecure -> 0.679 | F2: =food_insecure -> 0.679 | G2: 0 | H2: 0 | I2: 0 | J2: 0 | K2: 0 | L2: 0 | M2: 0 | N2: 0 | O2: 0
B3: Retraso en el pinzamiento del cordón umbilical | C3: 1 | D3: 0 | E3: 0 | F3: 0 | G3: 0 | H3: 0 | I3: 0 | J3: 0 | K3: 0 | L3: 0 | M3: 0 | N3: 0 | O3: 0
B4: Método de la madre canguro | C4: 1 | D4: 0 | E4: 0 | F4: 0 | G4: 0 | H4: 0 | I4: 0 | J4: 0 | K4: 0 | L4: 0 | M4: 0 | N4: 0 | O4: 0
B5: Suplementos nutricionales a base de lípidos | C5: 0 | D5: 0 | E5: =food_insecure -> 0.679 | F5: =food_insecure -> 0.679 | G5: 0 | H5: 0 | I5: 0 | J5: 0 | K5: 0 | L5: 0 | M5: 0 | N5: 0 | O5: 0
B6: Micronutrientes en polvo | C6: 0 | D6: 0 | E6: =1 -> 1 | F6: =1 -> 1 | G6: =1 -> 1 | H6: 0 | I6: 0 | J6: 0 | K6: 0 | L6: 0 | M6: 0 | N6: 0 | O6: 0
B7: Sales de rehidratación oral | C7: =diarrhoea_1mo*frac_diarrhea_severe -> 0.11799273 | D7: =diarrhoea_1_5mo*frac_diarrhea_severe -> 0.11799273 | E7: =diarrhoea_6_11mo*frac_diarrhea_severe -> 0.20138182 | F7: =diarrhoea_12_23mo*frac_diarrhea_severe -> 0.18946909 | G7: =diarrhoea_24_59mo*frac_diarrhea_severe -> 0.095490909 | H7: 0 | I7: 0 | J7: 0 | K7: 0 | L7: 0 | M7: 0 | N7: 0 | O7: 0
B8: Suministro público de alimentos complementarios | C8: 0 | D8: 0 | E8: =food_insecure -> 0.679 | F8: =food_insecure -> 0.679 | G8: 0 | H8: 0 | I8: 0 | J8: 0 | K8: 0 | L8: 0 | M8: 0 | N8: 0 | O8: 0
B9: Suplementos nutricionales a base de lípidos en pequeñas cantidades | C9: 0 | D9: 0 | E9: =food_insecure -> 0.679 | F9: =food_insecure -> 0.679 | G9: 0 | H9: 0 | I9: 0 | J9: 0 | K9: 0 | L9: 0 | M9: 0 | N9: 0 | O9: 0
B10: Tratamiento de la MAS | C10: 0 | D10: =IF(ISBLANK(comm_deliv), frac_children_health_facility,1) -> 1 | E10: =IF(ISBLANK(comm_deliv), frac_children_health_facility,1) -> 1 | F10: =IF(ISBLANK(comm_deliv), frac_children_health_facility,1) -> 1 | G10: =IF(ISBLANK(comm_deliv), frac_children_health_facility,1) -> 1 | H10: 0 | I10: 0 | J10: 0 | K10: 0 | L10: 0 | M10: 0 | N10: 0 | O10: 0
B11: Suplementación con vitamina A | C11: 0 | D11: 0 | E11: 1 | F11: 1 | G11: 1 | H11: 0 | I11: 0 | J11: 0 | K11: 0 | L11: 0 | M11: 0 | N11: 0 | O11: 0
B12: Zinc para el tratamiento + SRO | C12: =diarrhoea_1mo*frac_diarrhea_severe -> 0.11799273 | D12: =diarrhoea_1_5mo*frac_diarrhea_severe -> 0.11799273 | E12: =diarrhoea_6_11mo*frac_diarrhea_severe -> 0.20138182 | F12: =diarrhoea_12_23mo*frac_diarrhea_severe -> 0.18946909 | G12: =diarrhoea_24_59mo*frac_diarrhea_severe -> 0.095490909 | H12: 0 | I12: 0 | J12: 0 | K12: 0 | L12: 0 | M12: 0 | N12: 0 | O12: 0
B13: Suplementación con zinc | C13: 0 | D13: 0 | E13: 1 | F13: 1 | G13: 1 | H13: 0 | I13: 0 | J13: 0 | K13: 0 | L13: 0 | M13: 0 | N13: 0 | O13: 0
A15: Mujeres embarazadas | B15: Suplemento energético-proteico equilibrado | C15: 0 | D15: 0 | E15: 0 | F15: 0 | G15: 0 | H15: =food_insecure -> 0.679 | I15: =food_insecure -> 0.679 | J15: =food_insecure -> 0.679 | K15: =food_insecure -> 0.679 | L15: 0 | M15: 0 | N15: 0 | O15: 0
B16: Suplemento con calcio | C16: 0 | D16: 0 | E16: 0 | F16: 0 | G16: 0 | H16: =food_insecure -> 0.679 | I16: =food_insecure -> 0.679 | J16: =food_insecure -> 0.679 | K16: =food_insecure -> 0.679 | L16: 0 | M16: 0 | N16: 0 | O16: 0
B17: Suplementación con hierro y ácido fólico para mujeres embarazadas (comunidad) | C17: 0 | D17: 0 | E17: 0 | F17: 0 | G17: 0 | H17: =1 -> 1 | I17: =1 -> 1 | J17: =1 -> 1 | K17: =1 -> 1 | L17: 0 | M17: 0 | N17: 0 | O17: 0
B18: Suplementación con hierro y ácido fólico para mujeres embarazadas (centro de salud) | C18: 0 | D18: 0 | E18: 0 | F18: 0 | G18: 0 | H18: =frac_PW_health_facility -> 1 | I18: =frac_PW_health_facility -> 1 | J18: =frac_PW_health_facility -> 1 | K18: =frac_PW_health_facility -> 1 | L18: 0 | M18: 0 | N18: 0 | O18: 0
B19: IPTp-Tratamiento preventivo intermitente de la malaria en el embarazo | C19: 0 | D19: 0 | E19: 0 | F19: 0 | G19: 0 | H19: =frac_malaria_risk -> 0.86 | I19: =frac_malaria_risk -> 0.86 | J19: =frac_malaria_risk -> 0.86 | K19: =frac_malaria_risk -> 0.86 | L19: 0 | M19: 0 | N19: 0 | O19: 0
B20: Magnesio para la eclampsia | C20: 0 | D20: 0 | E20: 0 | F20: 0 | G20: 0 | H20: 1 | I20: 1 | J20: 1 | K20: 1 | L20: 0 | M20: 0 | N20: 0 | O20: 0
B21: Magnesio para la preeclampsia | C21: 0 | D21: 0 | E21: 0 | F21: 0 | G21: 0 | H21: 1 | I21: 1 | J21: 1 | K21: 1 | L21: 0 | M21: 0 | N21: 0 | O21: 0
B22: Suplementación con micronutrientes múltiples | C22: 0 | D22: 0 | E22: 0 | F22: 0 | G22: 0 | H22: =1 -> 1 | I22: =1 -> 1 | J22: =1 -> 1 | K22: =1 -> 1 | L22: 0 | M22: 0 | N22: 0 | O22: 0
A24: Mujeres en edad reproductiva no embarazadas | B24: Planificación familiar | C24: 0 | D24: 0 | E24: 0 | F24: 0 | G24: 0 | H24: 0 | I24: 0 | J24: 0 | K24: 0 | L24: =famplan_unmet_need -> 0.825 | M24: =famplan_unmet_need -> 0.825 | N24: =famplan_unmet_need -> 0.825 | O24: =famplan_unmet_need -> 0.825
B25: Suplementación con hierro y ácido fólico (comunidad) | C25: 0 | D25: 0 | E25: 0 | F25: 0 | G25: 0 | H25: 0 | I25: 0 | J25: 0 | K25: 0 | L25: =(1-food_insecure)*(0.49)*(1-school_attendance) + food_insecure*(0.7)*(1-school_attendance) -> 0.55682489 | M25: =(1-food_insecure)*(0.49)+food_insecure*(0.7) -> 0.63259 | N25: =(1-food_insecure)*(0.49)+food_insecure*(0.7) -> 0.63259 | O25: =(1-food_insecure)*(0.49)+food_insecure*(0.7) -> 0.63259
B26: Suplementación con hierro y ácido fólico (centro de salud) | C26: 0 | D26: 0 | E26: 0 | F26: 0 | G26: 0 | H26: 0 | I26: 0 | J26: 0 | K26: 0 | L26: =(1-food_insecure)*(0.21)*(1-school_attendance) + food_insecure*(0.3)*(1-school_attendance) -> 0.23863924 | M26: =(1-food_insecure)*(0.21)+food_insecure*(0.3) -> 0.27111 | N26: =(1-food_insecure)*(0.21)+food_insecure*(0.3) -> 0.27111 | O26: =(1-food_insecure)*(0.21)+food_insecure*(0.3) -> 0.27111
B27: Suplementación con hierro y ácido fólico (minorista) | C27: 0 | D27: 0 | E27: 0 | F27: 0 | G27: 0 | H27: 0 | I27: 0 | J27: 0 | K27: 0 | L27: =(1-food_insecure)*(0.3)*(1-school_attendance) -> 0.084766178 | M27: =(1-food_insecure)*(0.3) -> 0.0963 | N27: =(1-food_insecure)*(0.3) -> 0.0963 | O27: =(1-food_insecure)*(0.3) -> 0.0963
B28: Suplementación con hierro y ácido fólico (escuela) | C28: 0 | D28: 0 | E28: 0 | F28: 0 | G28: 0 | H28: 0 | I28: 0 | J28: 0 | K28: 0 | L28: =(1-food_insecure)*1*school_attendance + food_insecure*1*school_attendance -> 0.1197697 | M28: 0 | N28: 0 | O28: 0
A30: Población general | B30: Enriquecimiento del maíz con hierro y ácido fólico | C30: 0 | D30: 0 | E30: =frac_maize -> 0.01 | F30: =frac_maize -> 0.01 | G30: =frac_maize -> 0.01 | H30: =frac_maize -> 0.01 | I30: =frac_maize -> 0.01 | J30: =frac_maize -> 0.01 | K30: =frac_maize -> 0.01 | L30: =frac_maize -> 0.01 | ... O30: =frac_maize -> 0.01
B31: Enriquecimiento del arroz con hierro y ácido fólico | C31: 0 | D31: 0 | E31: =frac_rice -> 0.01 | F31: =frac_rice -> 0.01 | G31: =frac_rice -> 0.01 | H31: =frac_rice -> 0.01 | I31: =frac_rice -> 0.01 | J31: =frac_rice -> 0.01 | K31: =frac_rice -> 0.01 | L31: =frac_rice -> 0.01 | ... O31: =frac_rice -> 0.01
B32: Enriquecimiento de la harina de trigo con hierro y ácido fólico | C32: 0 | D32: 0 | E32: =frac_wheat -> 0.98 | F32: =frac_wheat -> 0.98 | G32: =frac_wheat -> 0.98 | H32: =frac_wheat -> 0.98 | I32: =frac_wheat -> 0.98 | J32: =frac_wheat -> 0.98 | K32: =frac_wheat -> 0.98 | L32: =frac_wheat -> 0.98 | ... O32: =frac_wheat -> 0.98
B33: Fortificación de la sal con hierro y yodo | C33: 0 | D33: 0 | E33: 1 | F33: 1 | G33: 1 | H33: 1 | I33: 1 | J33: 1 | K33: 1 | L33: 1 | M33: 1 | N33: 1 | O33: 1
B34: Mosquiteros tratados con insecticida de larga duración | C34: =frac_malaria_risk -> 0.86 | D34: =frac_malaria_risk -> 0.86 | E34: =frac_malaria_risk -> 0.86 | F34: =frac_malaria_risk -> 0.86 | G34: =frac_malaria_risk -> 0.86 | H34: =frac_malaria_risk -> 0.86 | I34: =frac_malaria_risk -> 0.86 | J34: =frac_malaria_risk -> 0.86 | ... O34: =frac_malaria_risk -> 0.86
B35: WASH: Lavado de manos | C35: 1 | D35: 1 | E35: 1 | F35: 1 | G35: 1 | H35: 1 | I35: 1 | J35: 1 | K35: 1 | L35: 1 | M35: 1 | N35: 1 | O35: 1
B36: WASH: Eliminación higiénica de residuos | C36: 1 | D36: 1 | E36: 1 | F36: 1 | G36: 1 | H36: 1 | I36: 1 | J36: 1 | K36: 1 | L36: 1 | M36: 1 | N36: 1 | O36: 1
B37: WASH: Mejora del saneamiento | C37: 1 | D37: 1 | E37: 1 | F37: 1 | G37: 1 | H37: 1 | I37: 1 | J37: 1 | K37: 1 | L37: 1 | M37: 1 | N37: 1 | O37: 1
B38: WASH: Mejora de la fuente de agua | C38: 1 | D38: 1 | E38: 1 | F38: 1 | G38: 1 | H38: 1 | I38: 1 | J38: 1 | K38: 1 | L38: 1 | M38: 1 | N38: 1 | O38: 1
B39: WASH: Agua corriente o entubada | C39: 1 | D39: 1 | E39: 1 | F39: 1 | G39: 1 | H39: 1 | I39: 1 | J39: 1 | K39: 1 | L39: 1 | M39: 1 | N39: 1 | O39: 1

Sheet Opciones de la curva de costos
A1: Lineal (costo marginal constante) [por defecto]
A2: Curva con costo marginal creciente
A3: Curva con costo marginal decreciente
A4: En forma de S (costo marginal decreciente y luego creciente)

Sheet Prog. de planificación familiar
A1: Método | B1: Efectividad | C1: Distribución | D1: Costo | E1: Costo proporcional
A2: Preservativo/condón | B2: 0.9 | C2: 0.09 | D2: 0.8 | E2: =C2*D2 -> 0.072
A3: Esterilización masculina | B3: 1 | C3: 0.02 | D3: 1.9 | E3: =C3*D3 -> 0.038
A4: Esterilización femenina | B4: 1 | C4: 0.08 | D4: 2 | E4: =C4*D4 -> 0.16
A5: Inyectable | B5: 1 | C5: 0.18 | D5: 0.7 | E5: =C5*D5 -> 0.126
A6: Implante | B6: 1 | C6: 0.02 | D6: 0.7 | E6: =C6*D6 -> 0.014
A7: Cápsula/píldora | B7: 0.93 | C7: 0.45 | D7: 0.9 | E7: =C7*D7 -> 0.405
A8: Retiro | B8: 0.5 | C8: 0.03 | D8: 0 | E8: =C8*D8 -> 0
A9: Planificación Familiar Natural | B9: 0.5 | C9: 0.11 | D9: 0 | E9: =C9*D9 -> 0
A10: Dispositivo Intrauterino (DIU) | B10: 0.98 | C10: 0.01 | D10: 0.6 | E10: =C10*D10 -> 0.006

Sheet Programas población afectada
A1: Amplio grupo de población | B1: Programa | C1: <1 mes | D1: 1-5 meses | E1: 6-11 meses | F1: 12-23 meses | G1: 24-59 meses | H1: PW: 15-19 años | I1: PW: 20-29 años | J1: PW: 30-39 años | K1: PW: 40-49 años | L1: WRA: 15-19 años (mujeres en edad reproductiva) | M1: WRA: 20-29 años (mujeres en edad reproductiva) | N1: WRA: 30-39 años (mujeres en edad reproductiva) | O1: WRA: 40-49 años (mujeres en edad reproductiva)
A2: Niños | B2: Transferencias de efectivo | C2: 0 | D2: 0 | E2: 1 | F2: 1 | G2: 0 | H2: 0 | I2: 0 | J2: 0 | K2: 0 | L2: 0 | M2: 0 | N2: 0 | O2: 0
B3: Retraso en el pinzamiento del cordón umbilical | C3: 1 | D3: 1 | E3: 0 | F3: 0 | G3: 0 | H3: 0 | I3: 0 | J3: 0 | K3: 0 | L3: 0 | M3: 0 | N3: 0 | O3: 0
B4: IYCF 1-alimentación del lactante y del niño pequeño | C4: 1 | D4: 1 | E4: 1 | F4: 1 | G4: 1 | H4: 0 | I4: 0 | J4: 0 | K4: 0 | L4: 0 | M4: 0 | N4: 0 | O4: 0
B5: IYCF 2-alimentación del lactante y del niño pequeño | C5: 1 | D5: 1 | E5: 1 | F5: 1 | G5: 1 | H5: 0 | I5: 0 | J5: 0 | K5: 0 | L5: 0 | M5: 0 | N5: 0 | O5: 0
B6: IYCF 3-alimentación del lactante y del niño pequeño | C6: 1 | D6: 1 | E6: 1 | F6: 1 | G6: 1 | H6: 0 | I6: 0 | J6: 0 | K6: 0 | L6: 0 | M6: 0 | N6: 0 | O6: 0
B7: Método de la madre canguro | C7: 1 | D7: 1 | E7: 0 | F7: 0 | G7: 0 | H7: 0 | I7: 0 | J7: 0 | K7: 0 | L7: 0 | M7: 0 | N7: 0 | O7: 0
B8: Suplementos nutricionales a base de lípidos | C8: 0 | D8: 0 | E8: 1 | F8: 1 | G8: 0 | H8: 0 | I8: 0 | J8: 0 | K8: 0 | L8: 0 | M8: 0 | N8: 0 | O8: 0
B9: Micronutrientes en polvo | C9: 0 | D9: 0 | E9: 1 | F9: 1 | G9: 1 | H9: 0 | I9: 0 | J9: 0 | K9: 0 | L9: 0 | M9: 0 | N9: 0 | O9: 0
B10: Sales de rehidratación oral | C10: 1 | D10: 1 | E10: 1 | F10: 1 | G10: 1 | H10: 0 | I10: 0 | J10: 0 | K10: 0 | L10: 0 | M10: 0 | N10: 0 | O10: 0
B11: Suministro público de alimentos complementarios | C11: 0 | D11: 0 | E11: 1 | F11: 1 | G11: 0 | H11: 0 | I11: 0 | J11: 0 | K11: 0 | L11: 0 | M11: 0 | N11: 0 | O11: 0
B12: Suplementos nutricionales a base de lípidos en pequeñas cantidades | C12: 0 | D12: 0 | E12: 1 | F12: 1 | G12: 0 | H12: 0 | I12: 0 | J12: 0 | K12: 0 | L12: 0 | M12: 0 | N12: 0 | O12: 0
B13: Tratamiento de la MAS | C13: 0 | D13: 1 | E13: 1 | F13: 1 | G13: 1 | H13: 0 | I13: 0 | J13: 0 | K13: 0 | L13: 0 | M13: 0 | N13: 0 | O13: 0
B14: Suplementación con vitamina A | C14: 0 | D14: 0 | E14: 1 | F14: 1 | G14: 1 | H14: 0 | I14: 0 | J14: 0 | K14: 0 | L14: 0 | M14: 0 | N14: 0 | O14: 0
... B16: Suplementación con zinc | C16: 0 | D16: 0 | E16: 1 | F16: 1 | G16: 1 | H16: 0 | I16: 0 | J16: 0 | K16: 0 | L16: 0 | M16: 0 | N16: 0 | O16: 0
A18: Mujeres embarazadas | B18: Suplemento energético-proteico equilibrado | C18: 0 | D18: 0 | E18: 0 | F18: 0 | G18: 0 | H18: 1 | I18: 1 | J18: 1 | K18: 1 | L18: 0 | M18: 0 | N18: 0 | O18: 0
B19: Suplemento con calcio | C19: 0 | D19: 0 | E19: 0 | F19: 0 | G19: 0 | H19: 1 | I19: 1 | J19: 1 | K19: 1 | L19: 0 | M19: 0 | N19: 0 | O19: 0
B20: Suplementación con hierro y ácido fólico para mujeres embarazadas (comunidad) | C20: 0 | D20: 0 | E20: 0 | F20: 0 | G20: 0 | H20: 1 | I20: 1 | J20: 1 | K20: 1 | L20: 0 | M20: 0 | N20: 0 | O20: 0
B21: Suplementación con hierro y ácido fólico para mujeres embarazadas (centro de salud) | C21: 0 | D21: 0 | E21: 0 | F21: 0 | G21: 0 | H21: 1 | I21: 1 | J21: 1 | K21: 1 | L21: 0 | M21: 0 | N21: 0 | O21: 0
B22: IPTp-Tratamiento preventivo intermitente de la malaria en el embarazo | C22: 0 | D22: 0 | E22: 0 | F22: 0 | G22: 0 | H22: 1 | I22: 1 | J22: 1 | K22: 1 | L22: 0 | M22: 0 | N22: 0 | O22: 0
B23: Magnesio para la eclampsia | C23: 0 | D23: 0 | E23: 0 | F23: 0 | G23: 0 | H23: 1 | I23: 1 | J23: 1 | K23: 1 | L23: 0 | M23: 0 | N23: 0 | O23: 0
B24: Magnesio para la preeclampsia | C24: 0 | D24: 0 | E24: 0 | F24: 0 | G24: 0 | H24: 1 | I24: 1 | J24: 1 | K24: 1 | L24: 0 | M24: 0 | N24: 0 | O24: 0
B25: Suplementación con micronutrientes múltiples | C25: 0 | D25: 0 | E25: 0 | F25: 0 | G25: 0 | H25: 1 | I25: 1 | J25: 1 | K25: 1 | L25: 0 | M25: 0 | N25: 0 | O25: 0
A27: Mujeres en edad reproductiva no embarazadas | B27: Planificación familiar | C27: 0 | D27: 0 | E27: 0 | F27: 0 | G27: 0 | H27: 0 | I27: 0 | J27: 0 | K27: 0 | L27: 1 | M27: 0 | N27: 0 | O27: 0
B28: Suplementación con hierro y ácido fólico (comunidad) | C28: 0 | D28: 0 | E28: 0 | F28: 0 | G28: 0 | H28: 0 | I28: 0 | J28: 0 | K28: 0 | L28: 1 | M28: 1 | N28: 1 | O28: 1
B29: Suplementación con hierro y ácido fólico (centro de salud) | C29: 0 | D29: 0 | E29: 0 | F29: 0 | G29: 0 | H29: 0 | I29: 0 | J29: 0 | K29: 0 | L29: 1 | M29: 1 | N29: 1 | O29: 1
B30: Suplementación con hierro y ácido fólico (minorista) | C30: 0 | D30: 0 | E30: 0 | F30: 0 | G30: 0 | H30: 0 | I30: 0 | J30: 0 | K30: 0 | L30: 1 | M30: 1 | N30: 1 | O30: 1
B31: Suplementación con hierro y ácido fólico (escuela) | C31: 0 | D31: 0 | E31: 0 | F31: 0 | G31: 0 | H31: 0 | I31: 0 | J31: 0 | K31: 0 | L31: 1 | M31: 0 | N31: 0 | O31: 0
A33: Población general | B33: Enriquecimiento del maíz con hierro y ácido fólico | C33: 1 | D33: 0 | E33: 1 | F33: 1 | G33: 1 | H33: 1 | I33: 1 | J33: 1 | K33: 1 | L33: 1 | M33: 1 | N33: 1 | O33: 1
B34: Enriquecimiento del arroz con hierro y ácido fólico | C34: 1 | D34: 0 | E34: 1 | F34: 1 | G34: 1 | H34: 1 | I34: 1 | J34: 1 | K34: 1 | L34: 1 | M34: 1 | N34: 1 | O34: 1
B35: Enriquecimiento de la harina de trigo con hierro y ácido fólico | C35: 1 | D35: 0 | E35: 1 | F35: 1 | G35: 1 | H35: 1 | I35: 1 | J35: 1 | K35: 1 | L35: 1 | M35: 1 | N35: 1 | O35: 1
B36: Fortificación de la sal con hierro y yodo | C36: 1 | D36: 0 | E36: 1 | F36: 1 | G36: 1 | H36: 1 | I36: 1 | J36: 1 | K36: 1 | L36: 1 | M36: 1 | N36: 1 | O36: 1
B37: Mosquiteros tratados con insecticida de larga duración | C37: 1 | D37: 1 | E37: 1 | F37: 1 | G37: 1 | H37: 1 | I37: 1 | J37: 1 | K37: 1 | L37: 1 | M37: 1 | N37: 1 | O37: 1
B38: WASH: Lavado de manos | C38: 1 | D38: 1 | E38: 1 | F38: 1 | G38: 1 | H38: 1 | I38: 1 | J38: 1 | K38: 1 | L38: 1 | M38: 1 | N38: 1 | O38: 1
B39: WASH: Eliminación higiénica de residuos | C39: 1 | D39: 1 | E39: 1 | F39: 1 | G39: 1 | H39: 1 | I39: 1 | J39: 1 | K39: 1 | L39: 1 | M39: 1 | N39: 1 | O39: 1
B40: WASH: Mejora del saneamiento | C40: 1 | D40: 1 | E40: 1 | F40: 1 | G40: 1 | H40: 1 | I40: 1 | J40: 1 | K40: 1 | L40: 1 | M40: 1 | N40: 1 | O40: 1
B41: WASH: Mejora de la fuente de agua | C41: 1 | D41: 1 | E41: 1 | F41: 1 | G41: 1 | H41: 1 | I41: 1 | J41: 1 | K41: 1 | L41: 1 | M41: 1 | N41: 1 | O41: 1
B42: WASH: Agua corriente o entubada | C42: 1 | D42: 1 | E42: 1 | F42: 1 | G42: 1 | H42: 1 | I42: 1 | J42: 1 | K42: 1 | L42: 1 | M42: 1 | N42: 1 | O42: 1

Sheet Riesgos que impacta programa
A1: Programa | B1: Baja talla o retraso en el crecimiento | C1: Anemia | D1: Prevención de la emaciación | E1: Tratamiento de la emaciación | F1: Lactancia materna | G1: Diarrea | H1: Mortalidad | I1: Desenlaces del nacimiento | J1: Espaciamiento entre los nacimientos | K1: Número de nacimiento | L1: Mortinatos
A2: Suplemento energético-proteico equilibrado | I2: x
A3: Suplemento con calcio | H3: x | I3: x
A4: Transferencias de efectivo | B4: x | D4: x
A5: Retraso en el pinzamiento del cordón umbilical | C5: x
A6: Planificación familiar | J6: x | K6: x
A7: Enriquecimiento del maíz con hierro y ácido fólico | C7: x | H7: x
A8: Enriquecimiento del arroz con hierro y ácido fólico | C8: x | H8: x
A9: Enriquecimiento de la harina de trigo con hierro y ácido fólico | C9: x | H9: x
A10: Suplementación con hierro y ácido fólico (comunidad) | C10: x
A11: Suplementación con hierro y ácido fólico (centro de salud) | C11: x
A12: Suplementación con hierro y ácido fólico (minorista) | C12: x
A13: Suplementación con hierro y ácido fólico (escuela) | C13: x
A14: Suplementación con hierro y ácido fólico para mujeres embarazadas (comunidad) | C14: x | I14: x
A15: Suplementación con hierro y ácido fólico para mujeres embarazadas (centro de salud) | C15: x | I15: x
A16: IPTp-Tratamiento preventivo intermitente de la malaria en el embarazo | C16: x | H16: x | I16: x
A17: Fortificación de la sal con hierro y yodo | C17: x
A18: IYCF 1-alimentación del lactante y del niño pequeño | B18: x | F18: x
A19: IYCF 2-alimentación del lactante y del niño pequeño | B19: x | F19: x
A20: IYCF 3-alimentación del lactante y del niño pequeño | B20: x | F20: x
A21: Método de la madre canguro | H21: x | I21: x
A22: Suplementos nutricionales a base de lípidos | B22: x | C22: x | D22: x
A23: Mosquiteros tratados con insecticida de larga duración | C23: x | I23: x
A24: Magnesio para la eclampsia | H24: x
A25: Magnesio para la preeclampsia | H25: x
A26: Micronutrientes en polvo | C26: x
A27: Suplementación con micronutrientes múltiples | C27: x | I27: x | L27: x
A28: Sales de rehidratación oral | H28: x
A29: Suministro público de alimentos complementarios | B29: x | D29: x
A30: Suplementos nutricionales a base de lípidos en pequeñas cantidades | B30: x | C30: x | D30: x
A31: Tratamiento de la MAS | E31: x
A32: Suplementación con vitamina A | G32: x | H32: x
A33: WASH: Lavado de manos | G33: x | H33: x
A34: WASH: Eliminación higiénica de residuos | G34: x | H34: x
A35: WASH: Mejora del saneamiento | G35: x | H35: x
A36: WASH: Mejora de la fuente de agua | G36: x | H36: x
A37: WASH: Agua corriente o entubada | G37: x | H37: x
A38: Zinc para el tratamiento + SRO | H38: x
A39: Suplementación con zinc | B39: x | G39: x | H39: x

Sheet Riegos para la población
A1: Rango de edades | B1: Baja talla o retraso en el crecimiento | C1: Anemia | D1: Prevención de la emaciación | E1: Tratamiento de la emaciación | F1: Lactancia materna | G1: Diarrea | H1: Mortalidad | I1: Desenlaces del nacimiento | J1: Espaciamiento entre los nacimientos | K1: Número de nacimiento | L1: Mortinatos
A2: <1 mes | B2: x | C2: x | D2: x | E2: x | F2: x | G2: x | H2: x
A3: 1-5 meses | B3: x | C3: x | D3: x | E3: x | F3: x | G3: x | H3: x
A4: 6-11 meses | B4: x | C4: x | D4: x | E4: x | F4: x | G4: x | H4: x
A5: 12-23 meses | B5: x | C5: x | D5: x | E5: x | F5: x | G5: x | H5: x
A6: 24-59 meses | B6: x | C6: x | D6: x | E6: x | F6: x | G6: x | H6: x
A7: PW: 15-19 años | C7: x | H7: x | I7: x | L7: x
A8: PW: 20-29 años | C8: x | H8: x | I8: x | L8: x
A9: PW: 30-39 años | C9: x | H9: x | I9: x | L9: x
A10: PW: 40-49 años | C10: x | H10: x | I10: x | L10: x
A11: WRA: 15-19 años (mujeres en edad reproductiva) | C11: x | J11: x | K11: x
A12: WRA: 20-29 años (mujeres en edad reproductiva) | C12: x | K12: x
A13: WRA: 30-39 años (mujeres en edad reproductiva) | C13: x | K13: x
A14: WRA: 40-49 años (mujeres en edad reproductiva) | C14: x | K14: x

Sheet Razón de momios IYCF
A1: Comportamiento | B1: Población objetivo | C1: Método de entrega | D1: <1 mes | E1: 1-5 meses | F1: 6-11 meses | G1: 12-23 meses | H1: 24-59 meses
A2: Razón de momios para lactancia materna adecuada | B2: Mujeres embarazadas | C2: Centro de salud | D2: 1 | E2: 1 | F2: 1 | G2: 1 | H2: 1
C3: Comunidad | D3: 1 | E3: 1 | F3: 1 | G3: 1 | H3: 1
C4: Medios de comunicación masivos | D4: 1 | E4: 1 | F4: 1 | G4: 1 | H4: 1
B5: <1 mes | C5: Centro de salud | D5: 2.17 | E5: 1 | F5: 1 | G5: 1 | H5: 1
C6: Comunidad | D6: 2.17 | E6: 1 | F6: 1 | G6: 1 | H6: 1
C7: Medios de comunicación masivos | D7: 1 | E7: 1 | F7: 1 | G7: 1 | H7: 1
B8: 1-5 meses | C8: Centro de salud | D8: 1 | E8: 2.48 | F8: 1 | G8: 1 | H8: 1
C9: Comunidad | D9: 1 | E9: 2.48 | F9: 1 | G9: 1 | H9: 1
C10: Medios de comunicación masivos | D10: 1 | E10: 1 | F10: 1 | G10: 1 | H10: 1
B11: 6-11 meses | C11: Centro de salud | D11: 1 | E11: 1 | F11: 1.82 | G11: 1 | H11: 1
C12: Comunidad | D12: 1 | E12: 1 | F12: 1.82 | G12: 1 | H12: 1
C13: Medios de comunicación masivos | D13: 1 | E13: 1 | F13: 1 | G13: 1 | H13: 1
B14: 12-23 meses | C14: Centro de salud | D14: 1 | E14: 1 | F14: 1 | G14: 1.82 | H14: 1
C15: Comunidad | D15: 1 | E15: 1 | F15: 1 | G15: 1.82 | H15: 1
C16: Medios de comunicación masivos | D16: 1 | E16: 1 | F16: 1 | G16: 1 | H16: 1
B17: Todo | C17: Medios de comunicación masivos | D17: 1.05 | E17: 1.05 | F17: 1.05 | G17: 1.05 | H17: 1
A19: Razón de momios para baja talla o retraso en el crecimiento | B19: Mujeres embarazadas | C19: Centro de salud | D19: 1 | E19: 1 | F19: 1 | G19: 1 | H19: 1
C20: Comunidad | D20: 1 | E20: 1 | F20: 1 | G20: 1 | H20: 1
C21: Medios de comunicación masivos | D21: 1 | E21: 1 | F21: 1 | G21: 1 | H21: 1
B22: <1 mes | C22: Centro de salud | D22: 1 | E22: 1 | F22: 1 | G22: 1 | H22: 1
C23: Comunidad | D23: 1 | E23: 1 | F23: 1 | G23: 1 | H23: 1
C24: Medios de comunicación masivos | D24: 1 | E24: 1 | F24: 1 | G24: 1 | H24: 1
B25: 1-5 meses | C25: Centro de salud | D25: 1 | E25: 1 | F25: 1 | G25: 1 | H25: 1
C26: Comunidad | D26: 1 | E26: 1 | F26: 1 | G26: 1 | H26: 1
C27: Medios de comunicación masivos | D27: 1 | E27: 1 | F27: 1 | G27: 1 | H27: 1
B28: 6-11 meses | C28: Centro de salud | D28: 1 | E28: 1 | F28: 1 | G28: 1 | H28: 1
C29: Comunidad | D29: 1 | E29: 1 | F29: 1 | G29: 1 | H29: 1
C30: Medios de comunicación masivos | D30: 1 | E30: 1 | F30: 1 | G30: 1 | H30: 1
B31: 12-23 meses | C31: Centro de salud | D31: 1 | E31: 1 | F31: 1 | G31: 1 | H31: 1
C32: Comunidad | D32: 1 | E32: 1 | F32: 1 | G32: 1 | H32: 1
C33: Medios de comunicación masivos | D33: 1 | E33: 1 | F33: 1 | G33: 1 | H33: 1
B34: Todo | C34: Medios de comunicación masivos | D34: 1 | E34: 1 | F34: 1 | G34: 1 | H34: 1
A36: Razón de momios para alimentación complementaria correcta | B36: Mujeres embarazadas | C36: Centro de salud | D36: 1 | E36: 1 | F36: 1 | G36: 1 | H36: 1
C37: Comunidad | D37: 1 | E37: 1 | F37: 1 | G37: 1 | H37: 1
C38: Medios de comunicación masivos | D38: 1 | E38: 1 | F38: 1 | G38: 1 | H38: 1
B39: <1 mes | C39: Centro de salud | D39: 1 | E39: 1 | F39: 1 | G39: 1 | H39: 1
C40: Comunidad | D40: 1 | E40: 1 | F40: 1 | G40: 1 | H40: 1
C41: Medios de comunicación masivos | D41: 1 | E41: 1 | F41: 1 | G41: 1 | H41: 1
B42: 1-5 meses | C42: Centro de salud | D42: 1 | E42: 1 | F42: 1 | G42: 1 | H42: 1
...

Sheet Razón de momios
A1: Razón de momios de baja talla o retraso en el crecimiento
A2: Condición | C2: <1 mes | D2: 1-5 meses | E2: 6-11 meses | F2: 12-23 meses | G2: 24-59 meses
B3: Dada la baja talla previa (HAZ < -2 en la banda de edad anterior) | C3: N/A | D3: 45 | E3: 361.6 | F3: 174.7 | G3: 174.7
B4: Diarrea (por episodio adicional) | C4: 1.025 | D4: 1.025 | E4: 1.025 | F4: 1.025 | G4: 1.025
A5: Por programa
B6: Suministro público de alimentos complementarios | C6: 1 | D6: 1 | E6: 0.89 | F6: 0.89 | G6: 1
B7: Suplementos nutricionales a base de lípidos | C7: 1 | D7: 1 | E7: 0.88 | F7: 0.88 | G7: 1
B8: Transferencias de efectivo | C8: 1 | D8: 1 | E8: 1 | F8: 0.808 | G8: 0.808
B9: Suplementos nutricionales a base de lípidos en pequeñas cantidades | C9: 1 | D9: 1 | E9: 0.88 | F9: 0.88 | G9: 1
B10: Suplementación con zinc | C10: 1 | D10: 1 | E10: 1 | F10: 1 | G10: 1
A12: Razón de momios de lactancia materna adecuada por programa
B13: Método de la madre canguro | C13: 1 | D13: 1.39 | E13: 1 | F13: 1 | G13: 1
A15: Otras razones de momios
A16: Emaciación | B16: Para MAS por episodio adicional de diarrea | C16: 1.024 | D16: 1.024 | E16: 1.024 | F16: 1.024 | G16: 1.024
B17: Para MAM por episodio adicional de diarrea | C17: 1.024 | D17: 1.024 | E17: 1.024 | F17: 1.024 | G17: 1.024
A18: Anemia | B18: Para anemia por episodio adicional de diarrea grave | C18: 1 | D18: 1 | E18: 1 | F18: 1 | G18: 1
A20: Razón de momios para el espaciamiento óptimo de los nacimientos por programa
C21: WRA: 15-19 años (mujeres en edad reproductiva) | D21: WRA: 20-29 años (mujeres en edad reproductiva) | E21: WRA: 30-39 años (mujeres en edad reproductiva) | F21: WRA: 40-49 años (mujeres en edad reproductiva)
B22: Planificación familiar | C22: 1.52 | D22: 1 | E22: 1 | F22: 1
A24: Límites inferiores
A25: Razón de momios de baja talla o retraso en el crecimiento
A26: Condición | C26: <1 mes | D26: 1-5 meses | E26: 6-11 meses | F26: 12-23 meses | G26: 24-59 meses
B27: Dada a baja talla previa (HAZ < -2 en la banda de edad anterior) - inferior | C27: N/A | D27: =D3*0.9 -> 40.5 | E27: =E3*0.9 -> 325.44 | F27: =F3*0.9 -> 157.23 | G27: =G3*0.9 -> 157.23
B28: Diarrea (por episodio adicional) - inferior | C28: 1.014 | D28: 1.014 | E28: 1.014 | F28: 1.014 | G28: 1.014
A29: Por programa - inferior
B30: Suministro público de alimentos complementarios - inferior | C30: =IF(C6=1,1,C6*0.9) -> 1 | D30: =IF(D6=1,1,D6*0.9) -> 1 | E30: =E6*0.9 -> 0.801 | F30: =F6*0.9 -> 0.801 | G30: =IF(G6=1,1,G6*0.9) -> 1
B31: Suplementos nutricionales a base de lípidos: más bajos | C31: =IF(C7=1,1,C7*0.9) -> 1 | D31: =IF(D7=1,1,D7*0.9) -> 1 | E31: 0.85 | F31: 0.85 | G31: =IF(G7=1,1,G7*0.9) -> 1
B32: Cash transfers - lower | C32: =IF(C8=1,1,C8*0.9) -> 1 | D32: =IF(D8=1,1,D8*0.9) -> 1 | E32: 1 | F32: 0.395 | G32: 0.395
B33: Suplementos nutricionales a base de lípidos en pequeñas cantidades: lower | C33: =IF(C9=1,1,C9*0.9) -> 1 | D33: =IF(D9=1,1,D9*0.9) -> 1 | E33: 0.85 | F33: 0.85 | G33: =IF(G9=1,1,G9*0.9) -> 1
B34: Suplementación con zinc - inferior | C34: =IF(C10=1,1,C10*0.9) -> 1 | D34: =IF(D10=1,1,D10*0.9) -> 1 | E34: =IF(E10=1,1,E10*0.9) -> 1 | F34: =IF(F10=1,1,F10*0.9) -> 1 | G34: =IF(G10=1,1,G10*0.9) -> 1
A36: Razón de momios de lactancia materna adecuada por programa - inferior
B37: Método madre canguro - inferior | C37: 1 | D37: 1.11 | E37: 1 | F37: 1 | G37: 1
A39: Otras razones de momios
A40: Emaciación | B40: Para MAS por episodio adicional de diarrea - inferior | C40: 1.016 | D40: 1.016 | E40: 1.016 | F40: 1.016 | G40: 1.016
B41: Para MAM por episodio adicional de diarrea - inferior | C41: 1.016 | D41: 1.016 | E41: 1.016 | F41: 1.016 | G41: 1.016
A42: Anemia | B42: Para anemia por episodio adicional de diarrea grave - inferior | C42: =IF(C18=1,1,C18*0.9) -> 1 | D42: =IF(D18=1,1,D18*0.9) -> 1 | E42: =IF(E18=1,1,E18*0.9) -> 1 | F42: =IF(F18=1,1,F18*0.9) -> 1 | G42: =IF(G18=1,1,G18*0.9) -> 1
A44: Razón de momios para el espaciamiento óptimo de los nacimientos por programa - inferior
C45: WRA: 15-19 años (mujeres en edad reproductiva) | D45: WRA: 20-29 años (mujeres en edad reproductiva) | E45: WRA: 30-39 años (mujeres en edad reproductiva) | F45: WRA: 40-49 años (mujeres en edad reproductiva)
B46: Planificación familiar - más baja | C46: =C22*0.9 -> 1.368 | D46: 1 | E46: 1 | F46: 1
A48: Límites superiores
...

Sheet Resultados de nacimiento- prog
A1: Programa | C1: Prematuro PEG (pequeño para la edad gestacional) | D1: Nacido a término PEG (pequeño para la edad gestacional) | E1: Prematuro AEG (adecuado para edad gestacional) | F1: Nacido a término AEG (Adecuado para la edad gestacional)
A2: Suplemento energético-proteico equilibrado | B2: efectividad | C2: 0.29 | D2: 0.29 | E2: 0 | F2: 0
B3: fracción afectada | C3: 1 | D3: 1 | E3: 1 | F3: 1
A4: Suplemento con calcio | B4: efectividad | C4: =1-0.76 -> 0.24 | D4: 0 | E4: =1-0.76 -> 0.24 | F4: 0
B5: fracción afectada | C5: 1 | D5: 1 | E5: 1 | F5: 1
A6: Suplementación con hierro y ácido fólico para mujeres embarazadas (comunidad) | B6: efectividad | C6: 0.61 | D6: 0.61 | E6: 0 | F6: 0
B7: fracción afectada | C7: 1 | D7: 1 | E7: 1 | F7: 1
A8: Suplementación con hierro y ácido fólico para mujeres embarazadas (centro de salud) | B8: efectividad | C8: 0.61 | D8: 0.61 | E8: 0 | F8: 0
B9: fracción afectada | C9: 1 | D9: 1 | E9: 1 | F9: 1
A10: IPTp-Tratamiento preventivo intermitente de la malaria en el embarazo | B10: efectividad | C10: 0.35 | D10: 0.35 | E10: 0 | F10: 0
B11: fracción afectada | C11: 1 | D11: 1 | E11: 0 | F11: 0
A12: Mosquiteros tratados con insecticida de larga duración | B12: efectividad | C12: 0.35 | D12: 0.35 | E12: 0 | F12: 0
B13: fracción afectada | C13: 1 | D13: 1 | E13: 0 | F13: 0
A14: Suplementación con micronutrientes múltiples | B14: efectividad | C14: =1-0.9*0.39 -> 0.649 | D14: =1-0.9*0.39 -> 0.649 | E14: 0 | F14: 0
B15: fracción afectada | C15: 1 | D15: 1 | E15: 1 | F15: 1
A17: Límites inferiores
A18: Programa | C18: Prematuro PEG (pequeño para la edad gestacional) | D18: Nacido a término PEG (pequeño para la edad gestacional) | E18: Prematuro AEG (adecuado para edad gestacional) | F18: Nacido a término AEG (Adecuado para la edad gestacional)
A19: Suplemento energético-proteico equilibrado | B19: efectividad | C19: =1-0.94 -> 0.06 | D19: =1-0.94 -> 0.06 | E19: =E2*0.9 -> 0 | F19: =F2*0.9 -> 0
B20: fracción afectada | C20: 1 | D20: 1 | E20: 1 | F20: 1
A21: Suplemento con calcio | B21: efectividad | C21: =1-0.97 -> 0.03 | D21: 0 | E21: =1-0.97 -> 0.03 | F21: 0
B22: fracción afectada | C22: 1 | D22: 1 | E22: 1 | F22: 1
A23: Suplementación con hierro y ácido fólico para mujeres embarazadas (comunidad) | B23: efectividad | C23: =1-0.86 -> 0.14 | D23: =1-0.86 -> 0.14 | E23: =E6*0.9 -> 0 | F23: =F6*0.9 -> 0
B24: fracción afectada | C24: 1 | D24: 1 | E24: 1 | F24: 1
A25: Suplementación con hierro y ácido fólico para mujeres embarazadas (centro de salud) | B25: efectividad | C25: =1-0.86 -> 0.14 | D25: =1-0.86 -> 0.14 | E25: =E8*0.9 -> 0 | F25: =F8*0.9 -> 0
B26: fracción afectada | C26: 1 | D26: 1 | E26: 1 | F26: 1
A27: IPTp-Tratamiento preventivo intermitente de la malaria en el embarazo | B27: efectividad | C27: =1-0.77 -> 0.23 | D27: =1-0.77 -> 0.23 | E27: =E12*0.9 -> 0 | F27: =F12*0.9 -> 0
B28: fracción afectada | C28: 1 | D28: 1 | E28: 1 | F28: 1
A29: Mosquiteros tratados con insecticida de larga duración | B29: efectividad | C29: =1-0.77 -> 0.23 | D29: =1-0.77 -> 0.23 | E29: =E12*0.9 -> 0 | F29: =F12*0.9 -> 0
B30: fracción afectada | C30: 1 | D30: 1 | E30: 1 | F30: 1
A31: Suplementación con micronutrientes múltiples | B31: efectividad | C31: =1-0.96*0.86 -> 0.1744 | D31: =1-0.96*0.86 -> 0.1744 | E31: =E14*0.9 -> 0 | F31: =F14*0.9 -> 0
B32: fracción afectada | C32: 1 | D32: 1 | E32: 1 | F32: 1
A34: Límites superiores
A35: Programa | C35: Prematuro PEG (pequeño para la edad gestacional) | D35: Nacido a término PEG (pequeño para la edad gestacional) | E35: Prematuro AEG (adecuado para edad gestacional) | F35: Nacido a término AEG (Adecuado para la edad gestacional)
A36: Suplemento energético-proteico equilibrado | B36: efectividad | C36: =1-0.54 -> 0.46 | D36: =1-0.54 -> 0.46 | E36: =E2*1.1 -> 0 | F36: =F2*1.1 -> 0
B37: fracción afectada | C37: 1 | D37: 1 | E37: 1 | F37: 1
A38: Suplemento con calcio | B38: efectividad | C38: =1-0.6 -> 0.4 | D38: 0 | E38: =1-0.6 -> 0.4 | F38: 0
B39: fracción afectada | C39: 1 | D39: 1 | E39: 1 | F39: 1
A40: Suplementación con hierro y ácido fólico para mujeres embarazadas (comunidad) | B40: efectividad | C40: =1-0.17 -> 0.83 | D40: =1-0.17 -> 0.83 | E40: =E6*1.1 -> 0 | F40: =F6*1.1 -> 0
B41: fracción afectada | C41: 1 | D41: 1 | E41: 1 | F41: 1
A42: Suplementación con hierro y ácido fólico para mujeres embarazadas (centro de salud) | B42: efectividad | C42: =1-0.17 -> 0.83 | D42: =1-0.17 -> 0.83 | E42: =E8*1.1 -> 0 | F42: =F8*1.1 -> 0
...

Sheet Riesgos desenlace de nacimiento
A1: Factores de riesgo materno que conducen a los resultados del nacimiento
C2: Nacido a término AEG (Adecuado para la edad gestacional) | D2: Nacido a término PEG (pequeño para la edad gestacional) | E2: Prematuro AEG (adecuado para edad gestacional) | F2: Prematuro PEG (pequeño para la edad gestacional)
A3: Riesgo relativo según el espaciamiento de los nacimientos
B4: El primer nacimiento | C4: 1 | D4: 1 | E4: 1 | F4: 1
B5: menos de 18 meses | C5: 1 | D5: 1.41 | E5: 1.49 | F5: 3.03
B6: 18-23 meses | C6: 1 | D6: 1.18 | E6: 1.1 | F6: 1.77
B7: 24 meses o más | C7: 1 | D7: 1 | E7: 1 | F7: 1
A9: Razón de momios para mujeres con anemia materna | C9: 1 | D9: 1.53 | E9: 1.32 | F9: 1.53
A11: Riesgos para los niños que experimentan desenlaces al nacimiento
A12: Razón de momios para las condiciones
B13: Retraso en el crecimiento (score HAZ < -2) | C13: 1 | D13: 5 | E13: 6.4 | F13: 46.5
B14: MAM (puntuación WHZ entre -3 y -2) | C14: 1 | D14: 2.52 | E14: 1.96 | F14: 4.19
B15: MAS (score WHZ < -3) | C15: 1 | D15: 2.52 | E15: 1.96 | F15: 4.19
A17: Riesgos relativos de las causas de muerte neonatal
B18: Diarrea neonatal | C18: 1 | D18: 1 | E18: 1 | F18: 1
B19: Sepsis neonatal | C19: 1 | D19: 2.07 | E19: 3.39 | F19: 11.89
B20: Neumonía neonatal | C20: 1 | D20: 2.07 | E20: 3.39 | F20: 11.89
B21: Asfixia neonatal | C21: 1 | D21: 2.07 | E21: 3.39 | F21: 11.89
B22: Prematuridad neonatal | C22: 1 | D22: 1 | E22: 999.99 | F22: 999.99
B23: Tétanos neonatal | C23: 1 | D23: 1 | E23: 1 | F23: 1
B24: Anomalías congénitas neonatales | C24: 1 | D24: 1 | E24: 1 | F24: 1
B25: Neonatal otros | C25: 1 | D25: 1 | E25: 1 | F25: 1
A27: Límites inferiores
A28: Factores de riesgo materno que conducen a los resultados del nacimiento
C29: Nacido a término AEG (Adecuado para la edad gestacional) | D29: Nacido a término PEG (pequeño para la edad gestacional) | E29: Prematuro AEG (adecuado para edad gestacional) | F29: Prematuro PEG (pequeño para la edad gestacional)
A30: Riesgo relativo según el espaciamiento de los nacimientos-inferior
B31: El primer nacimiento | C31: =IF(C4=1,1,C4*0.9) -> 1 | D31: =IF(D4=1,1,D4*0.9) -> 1 | E31: =IF(E4=1,1,E4*0.9) -> 1 | F31: =IF(F4=1,1,F4*0.9) -> 1
